Workbook

Sheet IK
A1: KETERSEDIAAN PANGAN | D1: Bulan : | E1: 45413 | F1: pilih dulu
A3: NO. | B3: PROVINSI | C3: KABUPATEN/KOTA | D3: LUAS TANAM PADI | J3: LUAS PUSO PADI | P3: LUAS TANAM PADI | T3: LUAS PUSO PADI | X3: KOMPOSIT
D4: Bulan berjalan di 5 tahun sebelum | I4: Bulan Berjalan | J4: Bulan berjalan di 5 tahun sebelum | O4: Bulan Berjalan | P4: Rata-Rata 5 th | Q4: Hasil | T4: Rata-Rata 5 th | U4: Hasil
D5: 2018 | E5: 2019 | F5: 2020 | G5: 2021 | H5: 2022 | J5: 2018 | K5: 2019 | L5: 2020 | M5: 2021 | N5: 2022 | P5: Rata-Rata 5 th | Q5: Value | R5: Bobot | S5: Status | T5: Rata-Rata 5 th | U5: Value | V5: Bobot | W5: Status | X5: Value | Y5: Status | Z5: Indeks
P6: =IF(ISERROR(AVERAGE(D6:H6)),0,AVERAGE(D6:H6)) -> 0 | Q6: =IF(ISERROR(((I6-P6)/P6)*100),0,((I6-P6)/P6)*100) -> 0 | R6: =IF(Q6="","",IF(Q6>=5,3,IF(Q6<-5,1,2))) -> 2 | S6: =IF(R6="","",IF(R6=3,"AMAN",IF(R6=1,"RENTAN","WASPADA"))) -> WASPADA | T6: =(IF(ISERROR(AVERAGE(J6:N6)),0,AVERAGE(J6:N6)))+0.00001 -> 1e-05 | U6: =(IF(ISERROR(((O6-T6)/T6)*100),0,((O6-T6)/T6)*100))+0.00001 -> -99.99999 | V6: =IF(U6="","",IF(U6<-5,3,IF(U6>=5,1,IF(U6=0,3,2)))) -> 3 | W6: =IF(V6="","",IF(V6=3,"AMAN",IF(V6=1,"RENTAN","WASPADA"))) -> AMAN | X6: =R6+V6 -> 5 | Y6: =IF(X6="","",IF(X6<=3,"RENTAN",IF(X6>5,"AMAN","WASPADA"))) -> WASPADA | Z6: =IF(Y6="","",IF(Y6="AMAN","3",IF(Y6="RENTAN","1","2"))) -> 2
P7: =IF(ISERROR(AVERAGE(D7:H7)),0,AVERAGE(D7:H7)) -> 0 | Q7: =IF(ISERROR(((I7-P7)/P7)*100),0,((I7-P7)/P7)*100) -> 0 | R7: =IF(Q7="","",IF(Q7>=5,3,IF(Q7<-5,1,2))) -> 2 | S7: =IF(R7="","",IF(R7=3,"AMAN",IF(R7=1,"RENTAN","WASPADA"))) -> WASPADA | T7: =(IF(ISERROR(AVERAGE(J7:N7)),0,AVERAGE(J7:N7)))+0.00001 -> 1e-05 | U7: =(IF(ISERROR(((O7-T7)/T7)*100),0,((O7-T7)/T7)*100))+0.00001 -> -99.99999 | V7: =IF(U7="","",IF(U7<-5,3,IF(U7>=5,1,IF(U7=0,3,2)))) -> 3 | W7: =IF(V7="","",IF(V7=3,"AMAN",IF(V7=1,"RENTAN","WASPADA"))) -> AMAN | X7: =R7+V7 -> 5 | Y7: =IF(X7="","",IF(X7<=3,"RENTAN",IF(X7>5,"AMAN","WASPADA"))) -> WASPADA | Z7: =IF(Y7="","",IF(Y7="AMAN","3",IF(Y7="RENTAN","1","2"))) -> 2
P8: =IF(ISERROR(AVERAGE(D8:H8)),0,AVERAGE(D8:H8)) -> 0 | Q8: =IF(ISERROR(((I8-P8)/P8)*100),0,((I8-P8)/P8)*100) -> 0 | R8: =IF(Q8="","",IF(Q8>=5,3,IF(Q8<-5,1,2))) -> 2 | S8: =IF(R8="","",IF(R8=3,"AMAN",IF(R8=1,"RENTAN","WASPADA"))) -> WASPADA | T8: =(IF(ISERROR(AVERAGE(J8:N8)),0,AVERAGE(J8:N8)))+0.00001 -> 1e-05 | U8: =(IF(ISERROR(((O8-T8)/T8)*100),0,((O8-T8)/T8)*100))+0.00001 -> -99.99999 | V8: =IF(U8="","",IF(U8<-5,3,IF(U8>=5,1,IF(U8=0,3,2)))) -> 3 | W8: =IF(V8="","",IF(V8=3,"AMAN",IF(V8=1,"RENTAN","WASPADA"))) -> AMAN | X8: =R8+V8 -> 5 | Y8: =IF(X8="","",IF(X8<=3,"RENTAN",IF(X8>5,"AMAN","WASPADA"))) -> WASPADA | Z8: =IF(Y8="","",IF(Y8="AMAN","3",IF(Y8="RENTAN","1","2"))) -> 2
P9: =IF(ISERROR(AVERAGE(D9:H9)),0,AVERAGE(D9:H9)) -> 0 | Q9: =IF(ISERROR(((I9-P9)/P9)*100),0,((I9-P9)/P9)*100) -> 0 | R9: =IF(Q9="","",IF(Q9>=5,3,IF(Q9<-5,1,2))) -> 2 | S9: =IF(R9="","",IF(R9=3,"AMAN",IF(R9=1,"RENTAN","WASPADA"))) -> WASPADA | T9: =(IF(ISERROR(AVERAGE(J9:N9)),0,AVERAGE(J9:N9)))+0.00001 -> 1e-05 | U9: =(IF(ISERROR(((O9-T9)/T9)*100),0,((O9-T9)/T9)*100))+0.00001 -> -99.99999 | V9: =IF(U9="","",IF(U9<-5,3,IF(U9>=5,1,IF(U9=0,3,2)))) -> 3 | W9: =IF(V9="","",IF(V9=3,"AMAN",IF(V9=1,"RENTAN","WASPADA"))) -> AMAN | X9: =R9+V9 -> 5 | Y9: =IF(X9="","",IF(X9<=3,"RENTAN",IF(X9>5,"AMAN","WASPADA"))) -> WASPADA | Z9: =IF(Y9="","",IF(Y9="AMAN","3",IF(Y9="RENTAN","1","2"))) -> 2
P10: =IF(ISERROR(AVERAGE(D10:H10)),0,AVERAGE(D10:H10)) -> 0 | Q10: =IF(ISERROR(((I10-P10)/P10)*100),0,((I10-P10)/P10)*100) -> 0 | R10: =IF(Q10="","",IF(Q10>=5,3,IF(Q10<-5,1,2))) -> 2 | S10: =IF(R10="","",IF(R10=3,"AMAN",IF(R10=1,"RENTAN","WASPADA"))) -> WASPADA | T10: =(IF(ISERROR(AVERAGE(J10:N10)),0,AVERAGE(J10:N10)))+0.00001 -> 1e-05 | U10: =(IF(ISERROR(((O10-T10)/T10)*100),0,((O10-T10)/T10)*100))+0.00001 -> -99.99999 | V10: =IF(U10="","",IF(U10<-5,3,IF(U10>=5,1,IF(U10=0,3,2)))) -> 3 | W10: =IF(V10="","",IF(V10=3,"AMAN",IF(V10=1,"RENTAN","WASPADA"))) -> AMAN | X10: =R10+V10 -> 5 | Y10: =IF(X10="","",IF(X10<=3,"RENTAN",IF(X10>5,"AMAN","WASPADA"))) -> WASPADA | Z10: =IF(Y10="","",IF(Y10="AMAN","3",IF(Y10="RENTAN","1","2"))) -> 2
P11: =IF(ISERROR(AVERAGE(D11:H11)),0,AVERAGE(D11:H11)) -> 0 | Q11: =IF(ISERROR(((I11-P11)/P11)*100),0,((I11-P11)/P11)*100) -> 0 | R11: =IF(Q11="","",IF(Q11>=5,3,IF(Q11<-5,1,2))) -> 2 | S11: =IF(R11="","",IF(R11=3,"AMAN",IF(R11=1,"RENTAN","WASPADA"))) -> WASPADA | T11: =(IF(ISERROR(AVERAGE(J11:N11)),0,AVERAGE(J11:N11)))+0.00001 -> 1e-05 | U11: =(IF(ISERROR(((O11-T11)/T11)*100),0,((O11-T11)/T11)*100))+0.00001 -> -99.99999 | V11: =IF(U11="","",IF(U11<-5,3,IF(U11>=5,1,IF(U11=0,3,2)))) -> 3 | W11: =IF(V11="","",IF(V11=3,"AMAN",IF(V11=1,"RENTAN","WASPADA"))) -> AMAN | X11: =R11+V11 -> 5 | Y11: =IF(X11="","",IF(X11<=3,"RENTAN",IF(X11>5,"AMAN","WASPADA"))) -> WASPADA | Z11: =IF(Y11="","",IF(Y11="AMAN","3",IF(Y11="RENTAN","1","2"))) -> 2
P12: =IF(ISERROR(AVERAGE(D12:H12)),0,AVERAGE(D12:H12)) -> 0 | Q12: =IF(ISERROR(((I12-P12)/P12)*100),0,((I12-P12)/P12)*100) -> 0 | R12: =IF(Q12="","",IF(Q12>=5,3,IF(Q12<-5,1,2))) -> 2 | S12: =IF(R12="","",IF(R12=3,"AMAN",IF(R12=1,"RENTAN","WASPADA"))) -> WASPADA | T12: =(IF(ISERROR(AVERAGE(J12:N12)),0,AVERAGE(J12:N12)))+0.00001 -> 1e-05 | U12: =(IF(ISERROR(((O12-T12)/T12)*100),0,((O12-T12)/T12)*100))+0.00001 -> -99.99999 | V12: =IF(U12="","",IF(U12<-5,3,IF(U12>=5,1,IF(U12=0,3,2)))) -> 3 | W12: =IF(V12="","",IF(V12=3,"AMAN",IF(V12=1,"RENTAN","WASPADA"))) -> AMAN | X12: =R12+V12 -> 5 | Y12: =IF(X12="","",IF(X12<=3,"RENTAN",IF(X12>5,"AMAN","WASPADA"))) -> WASPADA | Z12: =IF(Y12="","",IF(Y12="AMAN","3",IF(Y12="RENTAN","1","2"))) -> 2
P13: =IF(ISERROR(AVERAGE(D13:H13)),0,AVERAGE(D13:H13)) -> 0 | Q13: =IF(ISERROR(((I13-P13)/P13)*100),0,((I13-P13)/P13)*100) -> 0 | R13: =IF(Q13="","",IF(Q13>=5,3,IF(Q13<-5,1,2))) -> 2 | S13: =IF(R13="","",IF(R13=3,"AMAN",IF(R13=1,"RENTAN","WASPADA"))) -> WASPADA | T13: =(IF(ISERROR(AVERAGE(J13:N13)),0,AVERAGE(J13:N13)))+0.00001 -> 1e-05 | U13: =(IF(ISERROR(((O13-T13)/T13)*100),0,((O13-T13)/T13)*100))+0.00001 -> -99.99999 | V13: =IF(U13="","",IF(U13<-5,3,IF(U13>=5,1,IF(U13=0,3,2)))) -> 3 | W13: =IF(V13="","",IF(V13=3,"AMAN",IF(V13=1,"RENTAN","WASPADA"))) -> AMAN | X13: =R13+V13 -> 5 | Y13: =IF(X13="","",IF(X13<=3,"RENTAN",IF(X13>5,"AMAN","WASPADA"))) -> WASPADA | Z13: =IF(Y13="","",IF(Y13="AMAN","3",IF(Y13="RENTAN","1","2"))) -> 2
P14: =IF(ISERROR(AVERAGE(D14:H14)),0,AVERAGE(D14:H14)) -> 0 | Q14: =IF(ISERROR(((I14-P14)/P14)*100),0,((I14-P14)/P14)*100) -> 0 | R14: =IF(Q14="","",IF(Q14>=5,3,IF(Q14<-5,1,2))) -> 2 | S14: =IF(R14="","",IF(R14=3,"AMAN",IF(R14=1,"RENTAN","WASPADA"))) -> WASPADA | T14: =(IF(ISERROR(AVERAGE(J14:N14)),0,AVERAGE(J14:N14)))+0.00001 -> 1e-05 | U14: =(IF(ISERROR(((O14-T14)/T14)*100),0,((O14-T14)/T14)*100))+0.00001 -> -99.99999 | V14: =IF(U14="","",IF(U14<-5,3,IF(U14>=5,1,IF(U14=0,3,2)))) -> 3 | W14: =IF(V14="","",IF(V14=3,"AMAN",IF(V14=1,"RENTAN","WASPADA"))) -> AMAN | X14: =R14+V14 -> 5 | Y14: =IF(X14="","",IF(X14<=3,"RENTAN",IF(X14>5,"AMAN","WASPADA"))) -> WASPADA | Z14: =IF(Y14="","",IF(Y14="AMAN","3",IF(Y14="RENTAN","1","2"))) -> 2
P15: =IF(ISERROR(AVERAGE(D15:H15)),0,AVERAGE(D15:H15)) -> 0 | Q15: =IF(ISERROR(((I15-P15)/P15)*100),0,((I15-P15)/P15)*100) -> 0 | R15: =IF(Q15="","",IF(Q15>=5,3,IF(Q15<-5,1,2))) -> 2 | S15: =IF(R15="","",IF(R15=3,"AMAN",IF(R15=1,"RENTAN","WASPADA"))) -> WASPADA | T15: =(IF(ISERROR(AVERAGE(J15:N15)),0,AVERAGE(J15:N15)))+0.00001 -> 1e-05 | U15: =(IF(ISERROR(((O15-T15)/T15)*100),0,((O15-T15)/T15)*100))+0.00001 -> -99.99999 | V15: =IF(U15="","",IF(U15<-5,3,IF(U15>=5,1,IF(U15=0,3,2)))) -> 3 | W15: =IF(V15="","",IF(V15=3,"AMAN",IF(V15=1,"RENTAN","WASPADA"))) -> AMAN | X15: =R15+V15 -> 5 | Y15: =IF(X15="","",IF(X15<=3,"RENTAN",IF(X15>5,"AMAN","WASPADA"))) -> WASPADA | Z15: =IF(Y15="","",IF(Y15="AMAN","3",IF(Y15="RENTAN","1","2"))) -> 2
P16: =IF(ISERROR(AVERAGE(D16:H16)),0,AVERAGE(D16:H16)) -> 0 | Q16: =IF(ISERROR(((I16-P16)/P16)*100),0,((I16-P16)/P16)*100) -> 0 | R16: =IF(Q16="","",IF(Q16>=5,3,IF(Q16<-5,1,2))) -> 2 | S16: =IF(R16="","",IF(R16=3,"AMAN",IF(R16=1,"RENTAN","WASPADA"))) -> WASPADA | T16: =(IF(ISERROR(AVERAGE(J16:N16)),0,AVERAGE(J16:N16)))+0.00001 -> 1e-05 | U16: =(IF(ISERROR(((O16-T16)/T16)*100),0,((O16-T16)/T16)*100))+0.00001 -> -99.99999 | V16: =IF(U16="","",IF(U16<-5,3,IF(U16>=5,1,IF(U16=0,3,2)))) -> 3 | W16: =IF(V16="","",IF(V16=3,"AMAN",IF(V16=1,"RENTAN","WASPADA"))) -> AMAN | X16: =R16+V16 -> 5 | Y16: =IF(X16="","",IF(X16<=3,"RENTAN",IF(X16>5,"AMAN","WASPADA"))) -> WASPADA | Z16: =IF(Y16="","",IF(Y16="AMAN","3",IF(Y16="RENTAN","1","2"))) -> 2
P17: =IF(ISERROR(AVERAGE(D17:H17)),0,AVERAGE(D17:H17)) -> 0 | Q17: =IF(ISERROR(((I17-P17)/P17)*100),0,((I17-P17)/P17)*100) -> 0 | R17: =IF(Q17="","",IF(Q17>=5,3,IF(Q17<-5,1,2))) -> 2 | S17: =IF(R17="","",IF(R17=3,"AMAN",IF(R17=1,"RENTAN","WASPADA"))) -> WASPADA | T17: =(IF(ISERROR(AVERAGE(J17:N17)),0,AVERAGE(J17:N17)))+0.00001 -> 1e-05 | U17: =(IF(ISERROR(((O17-T17)/T17)*100),0,((O17-T17)/T17)*100))+0.00001 -> -99.99999 | V17: =IF(U17="","",IF(U17<-5,3,IF(U17>=5,1,IF(U17=0,3,2)))) -> 3 | W17: =IF(V17="","",IF(V17=3,"AMAN",IF(V17=1,"RENTAN","WASPADA"))) -> AMAN | X17: =R17+V17 -> 5 | Y17: =IF(X17="","",IF(X17<=3,"RENTAN",IF(X17>5,"AMAN","WASPADA"))) -> WASPADA | Z17: =IF(Y17="","",IF(Y17="AMAN","3",IF(Y17="RENTAN","1","2"))) -> 2
... P38: =IF(ISERROR(AVERAGE(D38:H38)),0,AVERAGE(D38:H38)) -> 0 | Q38: =IF(ISERROR(((I38-P38)/P38)*100),0,((I38-P38)/P38)*100) -> 0 | R38: =IF(Q38="","",IF(Q38>=5,3,IF(Q38<-5,1,2))) -> 2 | S38: =IF(R38="","",IF(R38=3,"AMAN",IF(R38=1,"RENTAN","WASPADA"))) -> WASPADA | T38: =(IF(ISERROR(AVERAGE(J38:N38)),0,AVERAGE(J38:N38)))+0.00001 -> 1e-05 | U38: =(IF(ISERROR(((O38-T38)/T38)*100),0,((O38-T38)/T38)*100))+0.00001 -> -99.99999 | V38: =IF(U38="","",IF(U38<-5,3,IF(U38>=5,1,IF(U38=0,3,2)))) -> 3 | W38: =IF(V38="","",IF(V38=3,"AMAN",IF(V38=1,"RENTAN","WASPADA"))) -> AMAN | X38: =R38+V38 -> 5 | Y38: =IF(X38="","",IF(X38<=3,"RENTAN",IF(X38>5,"AMAN","WASPADA"))) -> WASPADA | Z38: =IF(Y38="","",IF(Y38="AMAN","3",IF(Y38="RENTAN","1","2"))) -> 2
A39: =B3&""&B6 -> PROVINSI | D39: =SUM(D6:D38) -> 0 | E39: =SUM(E6:E38) -> 0 | F39: =SUM(F6:F38) -> 0 | G39: =SUM(G6:G38) -> 0 | H39: =SUM(H6:H38) -> 0 | I39: =SUM(I6:I38) -> 0 | J39: =SUM(J6:J38) -> 0 | K39: =SUM(K6:K38) -> 0 | ... O39: =SUM(O6:O38) -> 0 | P39: =IF(ISERROR(AVERAGE(D39:H39)),0,AVERAGE(D39:H39)) -> 0 | Q39: =IF(ISERROR(((I39-P39)/P39)*100),0,((I39-P39)/P39)*100) -> 0 | R39: =IF(Q39="","",IF(Q39>=5,3,IF(Q39<-5,1,2))) -> 2 | S39: =IF(R39="","",IF(R39=3,"AMAN",IF(R39=1,"RENTAN","WASPADA"))) -> WASPADA | T39: =(IF(ISERROR(AVERAGE(J39:N39)),0,AVERAGE(J39:N39)))+0.00001 -> 1e-05 | U39: =(IF(ISERROR(((O39-T39)/T39)*100),0,((O39-T39)/T39)*100))+0.00001 -> -99.99999 | V39: =IF(U39="","",IF(U39<-5,3,IF(U39>=5,1,IF(U39=0,3,2)))) -> 3 | W39: =IF(V39="","",IF(V39=3,"AMAN",IF(V39=1,"RENTAN","WASPADA"))) -> AMAN | X39: =R39+V39 -> 5 | Y39: =IF(X39="","",IF(X39<=3,"RENTAN",IF(X39>5,"AMAN","WASPADA"))) -> WASPADA | Z39: =IF(Y39="","",IF(Y39="AMAN","3",IF(Y39="RENTAN","1","2"))) -> 2

Sheet IA
A1: AKSES PANGAN
A3: NO. | B3: KOTA | C3: KECAMATAN | D3: HARGA BERAS 3 Bulan Sebelum | G3: Bulan Berjalan | H3: HARGA JAGUNG 3 Bulan Sebelum | K3: Bulan Berjalan | L3: HARGA GULA PASIR 3 Bulan Sebelum | O3: Bulan Berjalan | P3: HARGA MINYAK GORENG 3 Bulan Sebelum | S3: Bulan Berjalan | T3: HARGA DAGING AYAM 3 Bulan Sebelum | W3: Bulan Berjalan | X3: HARGA TELUR AYAM 3 Bulan Sebelum | AA3: Bulan Berjalan | AB3: BERAS | AE3: JAGUNG | AH3: GULA PASIR | AK3: MINYAK GORENG | AN3: DAGING AYAM | AQ3: TELUR AYAM | AT3: BOBOT
AB4: Rata-rata 3 bulan | AC4: Value | AD4: Bobot | AE4: Rata-rata 3 bulan | AF4: Value | AG4: Bobot | AH4: Rata-rata 3 bulan | AI4: Value | AJ4: Bobot | AK4: Rata-rata 3 bulan | AL4: Value | AM4: Bobot | AN4: Rata-rata 3 bulan | AO4: Value | AP4: Bobot | AQ4: Rata-rata 3 bulan | AR4: Value | AS4: Bobot
D5: =IK!$E$1-85 -> 45328 | E5: =IK!$E$1-55 -> 45358 | F5: =IK!$E$1-25 -> 45388 | G5: =IK!$E$1 -> 45413 | H5: =D5 -> 45328 | I5: =E5 -> 45358 | J5: =F5 -> 45388 | K5: =G5 -> 45413 | L5: =H5 -> 45328 | M5: =I5 -> 45358 | N5: =J5 -> 45388 | O5: =K5 -> 45413 | ... AA5: =W5 -> 45413 | AT5: VALUE | AU5: STATUS | AV5: INDEKS
A6: 1 | B6: CILEGON | C6: CIWANDAN | D6: 12000 | E6: 13000 | F6: 11560 | G6: 12000 | H6: 9000 | I6: 9000 | J6: 9000 | K6: 9000 | L6: 13550 | M6: 14000 | N6: 14000 | O6: 14000 | P6: 15000 | Q6: 16230 | R6: 16000 | S6: 15950 | T6: 39100 | U6: 40000 | V6: 40000 | W6: 39850 | X6: 27700 | Y6: 28000 | Z6: 27375 | AA6: 30300 | AB6: =IF(ISERROR(AVERAGE(D6:F6)),0,AVERAGE(D6:F6)) -> 12186.667 | AC6: =IF(ISERROR(((G6-AB6)/AB6)*100),0,((G6-AB6)/AB6)*100) -> -1.5317287 | AD6: =IF(AC6="","",IF(AC6>10,1,IF(AC6<5,3,2))) -> 3 | AE6: =IF(ISERROR(AVERAGE(H6:J6)),0,AVERAGE(H6:J6)) -> 9000 | AF6: =IF(ISERROR(((K6-AE6)/AE6)*100),0,((K6-AE6)/AE6)*100) -> 0 | AG6: =IF(AF6="","",IF(AF6>15,1,IF(AF6<5,3,2))) -> 3 | AH6: =IF(ISERROR(AVERAGE(L6:N6)),0,AVERAGE(L6:N6)) -> 13850 | AI6: =IF(ISERROR(((O6-AH6)/AH6)*100),0,((O6-AH6)/AH6)*100) -> 1.0830325 | AJ6: =IF(AI6="","",IF(AI6>15,1,IF(AI6<5,3,2))) -> 3 | AK6: =IF(ISERROR(AVERAGE(P6:R6)),0,AVERAGE(P6:R6)) -> 15743.333 | AL6: =IF(ISERROR(((S6-AK6)/AK6)*100),0,((S6-AK6)/AK6)*100) -> 1.312725 | AM6: =IF(AL6="","",IF(AL6>15,1,IF(AL6<5,3,2))) -> 3 | AN6: =IF(ISERROR(AVERAGE(T6:V6)),0,AVERAGE(T6:V6)) -> 39700 | AO6: =IF(ISERROR(((W6-AN6)/AN6)*100),0,((W6-AN6)/AN6)*100) -> 0.37783375 | AP6: =IF(AO6="","",IF(AO6>15,1,IF(AO6<5,3,2))) -> 3 | AQ6: =IF(ISERROR(AVERAGE(X6:Z6)),0,AVERAGE(X6:Z6)) -> 27691.667 | AR6: =IF(ISERROR(((AA6-AQ6)/AQ6)*100),0,((AA6-AQ6)/AQ6)*100) -> 9.4191995 | AS6: =IF(AR6="","",IF(AR6>15,1,IF(AR6<5,3,2))) -> 2 | AT6: =IF(ISERROR(AD6+AG6+AJ6+AM6+AP6+AS6),"",AD6+AG6+AJ6+AM6+AP6+AS6) -> 17 | AU6: =IF(AT6="","",IF(AT6<=9,"RENTAN",IF(AT6>13,"AMAN","WASPADA"))) -> AMAN | AV6: =IF(AU6="","",IF(AU6="AMAN","3",IF(AU6="RENTAN","1","2"))) -> 3
C7: CITANGKIL | D7: 12000 | E7: 13000 | F7: 11560 | G7: 12000 | H7: 9000 | I7: 9000 | J7: 9000 | K7: 9000 | L7: 13550 | M7: 14000 | N7: 14000 | O7: 14000 | P7: 15000 | Q7: 16230 | R7: 16000 | S7: 15950 | T7: 39100 | U7: 40000 | V7: 40000 | W7: 39850 | X7: 27700 | Y7: 28000 | Z7: 27375 | AA7: 30300 | AB7: =IF(ISERROR(AVERAGE(D7:F7)),0,AVERAGE(D7:F7)) -> 12186.667 | AC7: =IF(ISERROR(((G7-AB7)/AB7)*100),0,((G7-AB7)/AB7)*100) -> -1.5317287 | AD7: =IF(AC7="","",IF(AC7>10,1,IF(AC7<5,3,2))) -> 3 | AE7: =IF(ISERROR(AVERAGE(H7:J7)),0,AVERAGE(H7:J7)) -> 9000 | AF7: =IF(ISERROR(((K7-AE7)/AE7)*100),0,((K7-AE7)/AE7)*100) -> 0 | AG7: =IF(AF7="","",IF(AF7>15,1,IF(AF7<5,3,2))) -> 3 | AH7: =IF(ISERROR(AVERAGE(L7:N7)),0,AVERAGE(L7:N7)) -> 13850 | AI7: =IF(ISERROR(((O7-AH7)/AH7)*100),0,((O7-AH7)/AH7)*100) -> 1.0830325 | AJ7: =IF(AI7="","",IF(AI7>15,1,IF(AI7<5,3,2))) -> 3 | AK7: =IF(ISERROR(AVERAGE(P7:R7)),0,AVERAGE(P7:R7)) -> 15743.333 | AL7: =IF(ISERROR(((S7-AK7)/AK7)*100),0,((S7-AK7)/AK7)*100) -> 1.312725 | AM7: =IF(AL7="","",IF(AL7>15,1,IF(AL7<5,3,2))) -> 3 | AN7: =IF(ISERROR(AVERAGE(T7:V7)),0,AVERAGE(T7:V7)) -> 39700 | AO7: =IF(ISERROR(((W7-AN7)/AN7)*100),0,((W7-AN7)/AN7)*100) -> 0.37783375 | AP7: =IF(AO7="","",IF(AO7>15,1,IF(AO7<5,3,2))) -> 3 | AQ7: =IF(ISERROR(AVERAGE(X7:Z7)),0,AVERAGE(X7:Z7)) -> 27691.667 | AR7: =IF(ISERROR(((AA7-AQ7)/AQ7)*100),0,((AA7-AQ7)/AQ7)*100) -> 9.4191995 | AS7: =IF(AR7="","",IF(AR7>15,1,IF(AR7<5,3,2))) -> 2 | AT7: =IF(ISERROR(AD7+AG7+AJ7+AM7+AP7+AS7),"",AD7+AG7+AJ7+AM7+AP7+AS7) -> 17 | AU7: =IF(AT7="","",IF(AT7<=9,"RENTAN",IF(AT7>13,"AMAN","WASPADA"))) -> AMAN | AV7: =IF(AU7="","",IF(AU7="AMAN","3",IF(AU7="RENTAN","1","2"))) -> 3
C8: PULOMERAK | D8: 12000 | E8: 13000 | F8: 11560 | G8: 12000 | H8: 9000 | I8: 9000 | J8: 9000 | K8: 9000 | L8: 13550 | M8: 14000 | N8: 14000 | O8: 14000 | P8: 15000 | Q8: 16230 | R8: 16000 | S8: 15950 | T8: 39100 | U8: 40000 | V8: 40000 | W8: 39850 | X8: 27700 | Y8: 28000 | Z8: 27375 | AA8: 30300 | AB8: =IF(ISERROR(AVERAGE(D8:F8)),0,AVERAGE(D8:F8)) -> 12186.667 | AC8: =IF(ISERROR(((G8-AB8)/AB8)*100),0,((G8-AB8)/AB8)*100) -> -1.5317287 | AD8: =IF(AC8="","",IF(AC8>10,1,IF(AC8<5,3,2))) -> 3 | AE8: =IF(ISERROR(AVERAGE(H8:J8)),0,AVERAGE(H8:J8)) -> 9000 | AF8: =IF(ISERROR(((K8-AE8)/AE8)*100),0,((K8-AE8)/AE8)*100) -> 0 | AG8: =IF(AF8="","",IF(AF8>15,1,IF(AF8<5,3,2))) -> 3 | AH8: =IF(ISERROR(AVERAGE(L8:N8)),0,AVERAGE(L8:N8)) -> 13850 | AI8: =IF(ISERROR(((O8-AH8)/AH8)*100),0,((O8-AH8)/AH8)*100) -> 1.0830325 | AJ8: =IF(AI8="","",IF(AI8>15,1,IF(AI8<5,3,2))) -> 3 | AK8: =IF(ISERROR(AVERAGE(P8:R8)),0,AVERAGE(P8:R8)) -> 15743.333 | AL8: =IF(ISERROR(((S8-AK8)/AK8)*100),0,((S8-AK8)/AK8)*100) -> 1.312725 | AM8: =IF(AL8="","",IF(AL8>15,1,IF(AL8<5,3,2))) -> 3 | AN8: =IF(ISERROR(AVERAGE(T8:V8)),0,AVERAGE(T8:V8)) -> 39700 | AO8: =IF(ISERROR(((W8-AN8)/AN8)*100),0,((W8-AN8)/AN8)*100) -> 0.37783375 | AP8: =IF(AO8="","",IF(AO8>15,1,IF(AO8<5,3,2))) -> 3 | AQ8: =IF(ISERROR(AVERAGE(X8:Z8)),0,AVERAGE(X8:Z8)) -> 27691.667 | AR8: =IF(ISERROR(((AA8-AQ8)/AQ8)*100),0,((AA8-AQ8)/AQ8)*100) -> 9.4191995 | AS8: =IF(AR8="","",IF(AR8>15,1,IF(AR8<5,3,2))) -> 2 | AT8: =IF(ISERROR(AD8+AG8+AJ8+AM8+AP8+AS8),"",AD8+AG8+AJ8+AM8+AP8+AS8) -> 17 | AU8: =IF(AT8="","",IF(AT8<=9,"RENTAN",IF(AT8>13,"AMAN","WASPADA"))) -> AMAN | AV8: =IF(AU8="","",IF(AU8="AMAN","3",IF(AU8="RENTAN","1","2"))) -> 3
C9: PURWAKARTA | D9: 12000 | E9: 13000 | F9: 11560 | G9: 12000 | H9: 9000 | I9: 9000 | J9: 9000 | K9: 9000 | L9: 13550 | M9: 14000 | N9: 14000 | O9: 14000 | P9: 15000 | Q9: 16230 | R9: 16000 | S9: 15950 | T9: 39100 | U9: 40000 | V9: 40000 | W9: 39850 | X9: 27700 | Y9: 28000 | Z9: 27375 | AA9: 30300 | AB9: =IF(ISERROR(AVERAGE(D9:F9)),0,AVERAGE(D9:F9)) -> 12186.667 | AC9: =IF(ISERROR(((G9-AB9)/AB9)*100),0,((G9-AB9)/AB9)*100) -> -1.5317287 | AD9: =IF(AC9="","",IF(AC9>10,1,IF(AC9<5,3,2))) -> 3 | AE9: =IF(ISERROR(AVERAGE(H9:J9)),0,AVERAGE(H9:J9)) -> 9000 | AF9: =IF(ISERROR(((K9-AE9)/AE9)*100),0,((K9-AE9)/AE9)*100) -> 0 | AG9: =IF(AF9="","",IF(AF9>15,1,IF(AF9<5,3,2))) -> 3 | AH9: =IF(ISERROR(AVERAGE(L9:N9)),0,AVERAGE(L9:N9)) -> 13850 | AI9: =IF(ISERROR(((O9-AH9)/AH9)*100),0,((O9-AH9)/AH9)*100) -> 1.0830325 | AJ9: =IF(AI9="","",IF(AI9>15,1,IF(AI9<5,3,2))) -> 3 | AK9: =IF(ISERROR(AVERAGE(P9:R9)),0,AVERAGE(P9:R9)) -> 15743.333 | AL9: =IF(ISERROR(((S9-AK9)/AK9)*100),0,((S9-AK9)/AK9)*100) -> 1.312725 | AM9: =IF(AL9="","",IF(AL9>15,1,IF(AL9<5,3,2))) -> 3 | AN9: =IF(ISERROR(AVERAGE(T9:V9)),0,AVERAGE(T9:V9)) -> 39700 | AO9: =IF(ISERROR(((W9-AN9)/AN9)*100),0,((W9-AN9)/AN9)*100) -> 0.37783375 | AP9: =IF(AO9="","",IF(AO9>15,1,IF(AO9<5,3,2))) -> 3 | AQ9: =IF(ISERROR(AVERAGE(X9:Z9)),0,AVERAGE(X9:Z9)) -> 27691.667 | AR9: =IF(ISERROR(((AA9-AQ9)/AQ9)*100),0,((AA9-AQ9)/AQ9)*100) -> 9.4191995 | AS9: =IF(AR9="","",IF(AR9>15,1,IF(AR9<5,3,2))) -> 2 | AT9: =IF(ISERROR(AD9+AG9+AJ9+AM9+AP9+AS9),"",AD9+AG9+AJ9+AM9+AP9+AS9) -> 17 | AU9: =IF(AT9="","",IF(AT9<=9,"RENTAN",IF(AT9>13,"AMAN","WASPADA"))) -> AMAN | AV9: =IF(AU9="","",IF(AU9="AMAN","3",IF(AU9="RENTAN","1","2"))) -> 3
C10: GROGOL | D10: 12000 | E10: 13000 | F10: 11560 | G10: 12000 | H10: 9000 | I10: 9000 | J10: 9000 | K10: 9000 | L10: 13550 | M10: 14000 | N10: 14000 | O10: 14000 | P10: 15000 | Q10: 16230 | R10: 16000 | S10: 15950 | T10: 39100 | U10: 40000 | V10: 40000 | W10: 39850 | X10: 27700 | Y10: 28000 | Z10: 27375 | AA10: 30300 | AB10: =IF(ISERROR(AVERAGE(D10:F10)),0,AVERAGE(D10:F10)) -> 12186.667 | AC10: =IF(ISERROR(((G10-AB10)/AB10)*100),0,((G10-AB10)/AB10)*100) -> -1.5317287 | AD10: =IF(AC10="","",IF(AC10>10,1,IF(AC10<5,3,2))) -> 3 | AE10: =IF(ISERROR(AVERAGE(H10:J10)),0,AVERAGE(H10:J10)) -> 9000 | AF10: =IF(ISERROR(((K10-AE10)/AE10)*100),0,((K10-AE10)/AE10)*100) -> 0 | AG10: =IF(AF10="","",IF(AF10>15,1,IF(AF10<5,3,2))) -> 3 | AH10: =IF(ISERROR(AVERAGE(L10:N10)),0,AVERAGE(L10:N10)) -> 13850 | AI10: =IF(ISERROR(((O10-AH10)/AH10)*100),0,((O10-AH10)/AH10)*100) -> 1.0830325 | AJ10: =IF(AI10="","",IF(AI10>15,1,IF(AI10<5,3,2))) -> 3 | AK10: =IF(ISERROR(AVERAGE(P10:R10)),0,AVERAGE(P10:R10)) -> 15743.333 | AL10: =IF(ISERROR(((S10-AK10)/AK10)*100),0,((S10-AK10)/AK10)*100) -> 1.312725 | AM10: =IF(AL10="","",IF(AL10>15,1,IF(AL10<5,3,2))) -> 3 | AN10: =IF(ISERROR(AVERAGE(T10:V10)),0,AVERAGE(T10:V10)) -> 39700 | AO10: =IF(ISERROR(((W10-AN10)/AN10)*100),0,((W10-AN10)/AN10)*100) -> 0.37783375 | AP10: =IF(AO10="","",IF(AO10>15,1,IF(AO10<5,3,2))) -> 3 | AQ10: =IF(ISERROR(AVERAGE(X10:Z10)),0,AVERAGE(X10:Z10)) -> 27691.667 | AR10: =IF(ISERROR(((AA10-AQ10)/AQ10)*100),0,((AA10-AQ10)/AQ10)*100) -> 9.4191995 | AS10: =IF(AR10="","",IF(AR10>15,1,IF(AR10<5,3,2))) -> 2 | AT10: =IF(ISERROR(AD10+AG10+AJ10+AM10+AP10+AS10),"",AD10+AG10+AJ10+AM10+AP10+AS10) -> 17 | AU10: =IF(AT10="","",IF(AT10<=9,"RENTAN",IF(AT10>13,"AMAN","WASPADA"))) -> AMAN | AV10: =IF(AU10="","",IF(AU10="AMAN","3",IF(AU10="RENTAN","1","2"))) -> 3
C11: CILEGON | D11: 12000 | E11: 13000 | F11: 11560 | G11: 12000 | H11: 9000 | I11: 9000 | J11: 9000 | K11: 9000 | L11: 13550 | M11: 14000 | N11: 14000 | O11: 14000 | P11: 15000 | Q11: 16230 | R11: 16000 | S11: 15950 | T11: 39100 | U11: 40000 | V11: 40000 | W11: 39850 | X11: 27700 | Y11: 28000 | Z11: 27375 | AA11: 30300 | AB11: =IF(ISERROR(AVERAGE(D11:F11)),0,AVERAGE(D11:F11)) -> 12186.667 | AC11: =IF(ISERROR(((G11-AB11)/AB11)*100),0,((G11-AB11)/AB11)*100) -> -1.5317287 | AD11: =IF(AC11="","",IF(AC11>10,1,IF(AC11<5,3,2))) -> 3 | AE11: =IF(ISERROR(AVERAGE(H11:J11)),0,AVERAGE(H11:J11)) -> 9000 | AF11: =IF(ISERROR(((K11-AE11)/AE11)*100),0,((K11-AE11)/AE11)*100) -> 0 | AG11: =IF(AF11="","",IF(AF11>15,1,IF(AF11<5,3,2))) -> 3 | AH11: =IF(ISERROR(AVERAGE(L11:N11)),0,AVERAGE(L11:N11)) -> 13850 | AI11: =IF(ISERROR(((O11-AH11)/AH11)*100),0,((O11-AH11)/AH11)*100) -> 1.0830325 | AJ11: =IF(AI11="","",IF(AI11>15,1,IF(AI11<5,3,2))) -> 3 | AK11: =IF(ISERROR(AVERAGE(P11:R11)),0,AVERAGE(P11:R11)) -> 15743.333 | AL11: =IF(ISERROR(((S11-AK11)/AK11)*100),0,((S11-AK11)/AK11)*100) -> 1.312725 | AM11: =IF(AL11="","",IF(AL11>15,1,IF(AL11<5,3,2))) -> 3 | AN11: =IF(ISERROR(AVERAGE(T11:V11)),0,AVERAGE(T11:V11)) -> 39700 | AO11: =IF(ISERROR(((W11-AN11)/AN11)*100),0,((W11-AN11)/AN11)*100) -> 0.37783375 | AP11: =IF(AO11="","",IF(AO11>15,1,IF(AO11<5,3,2))) -> 3 | AQ11: =IF(ISERROR(AVERAGE(X11:Z11)),0,AVERAGE(X11:Z11)) -> 27691.667 | AR11: =IF(ISERROR(((AA11-AQ11)/AQ11)*100),0,((AA11-AQ11)/AQ11)*100) -> 9.4191995 | AS11: =IF(AR11="","",IF(AR11>15,1,IF(AR11<5,3,2))) -> 2 | AT11: =IF(ISERROR(AD11+AG11+AJ11+AM11+AP11+AS11),"",AD11+AG11+AJ11+AM11+AP11+AS11) -> 17 | AU11: =IF(AT11="","",IF(AT11<=9,"RENTAN",IF(AT11>13,"AMAN","WASPADA"))) -> AMAN | AV11: =IF(AU11="","",IF(AU11="AMAN","3",IF(AU11="RENTAN","1","2"))) -> 3
C12: JOMBANG | D12: 12000 | E12: 13000 | F12: 11560 | G12: 12000 | H12: 9000 | I12: 9000 | J12: 9000 | K12: 9000 | L12: 13550 | M12: 14000 | N12: 14000 | O12: 14000 | P12: 15000 | Q12: 16230 | R12: 16000 | S12: 15950 | T12: 39100 | U12: 40000 | V12: 40000 | W12: 39850 | X12: 27700 | Y12: 28000 | Z12: 27375 | AA12: 30300 | AB12: =IF(ISERROR(AVERAGE(D12:F12)),0,AVERAGE(D12:F12)) -> 12186.667 | AC12: =IF(ISERROR(((G12-AB12)/AB12)*100),0,((G12-AB12)/AB12)*100) -> -1.5317287 | AD12: =IF(AC12="","",IF(AC12>10,1,IF(AC12<5,3,2))) -> 3 | AE12: =IF(ISERROR(AVERAGE(H12:J12)),0,AVERAGE(H12:J12)) -> 9000 | AF12: =IF(ISERROR(((K12-AE12)/AE12)*100),0,((K12-AE12)/AE12)*100) -> 0 | AG12: =IF(AF12="","",IF(AF12>15,1,IF(AF12<5,3,2))) -> 3 | AH12: =IF(ISERROR(AVERAGE(L12:N12)),0,AVERAGE(L12:N12)) -> 13850 | AI12: =IF(ISERROR(((O12-AH12)/AH12)*100),0,((O12-AH12)/AH12)*100) -> 1.0830325 | AJ12: =IF(AI12="","",IF(AI12>15,1,IF(AI12<5,3,2))) -> 3 | AK12: =IF(ISERROR(AVERAGE(P12:R12)),0,AVERAGE(P12:R12)) -> 15743.333 | AL12: =IF(ISERROR(((S12-AK12)/AK12)*100),0,((S12-AK12)/AK12)*100) -> 1.312725 | AM12: =IF(AL12="","",IF(AL12>15,1,IF(AL12<5,3,2))) -> 3 | AN12: =IF(ISERROR(AVERAGE(T12:V12)),0,AVERAGE(T12:V12)) -> 39700 | AO12: =IF(ISERROR(((W12-AN12)/AN12)*100),0,((W12-AN12)/AN12)*100) -> 0.37783375 | AP12: =IF(AO12="","",IF(AO12>15,1,IF(AO12<5,3,2))) -> 3 | AQ12: =IF(ISERROR(AVERAGE(X12:Z12)),0,AVERAGE(X12:Z12)) -> 27691.667 | AR12: =IF(ISERROR(((AA12-AQ12)/AQ12)*100),0,((AA12-AQ12)/AQ12)*100) -> 9.4191995 | AS12: =IF(AR12="","",IF(AR12>15,1,IF(AR12<5,3,2))) -> 2 | AT12: =IF(ISERROR(AD12+AG12+AJ12+AM12+AP12+AS12),"",AD12+AG12+AJ12+AM12+AP12+AS12) -> 17 | AU12: =IF(AT12="","",IF(AT12<=9,"RENTAN",IF(AT12>13,"AMAN","WASPADA"))) -> AMAN | AV12: =IF(AU12="","",IF(AU12="AMAN","3",IF(AU12="RENTAN","1","2"))) -> 3
C13: CIBEBER | D13: 12000 | E13: 13000 | F13: 11560 | G13: 12000 | H13: 9000 | I13: 9000 | J13: 9000 | K13: 9000 | L13: 13550 | M13: 14000 | N13: 14000 | O13: 14000 | P13: 15000 | Q13: 16230 | R13: 16000 | S13: 15950 | T13: 39100 | U13: 40000 | V13: 40000 | W13: 39850 | X13: 27700 | Y13: 28000 | Z13: 27375 | AA13: 30300 | AB13: =IF(ISERROR(AVERAGE(D13:F13)),0,AVERAGE(D13:F13)) -> 12186.667 | AC13: =IF(ISERROR(((G13-AB13)/AB13)*100),0,((G13-AB13)/AB13)*100) -> -1.5317287 | AD13: =IF(AC13="","",IF(AC13>10,1,IF(AC13<5,3,2))) -> 3 | AE13: =IF(ISERROR(AVERAGE(H13:J13)),0,AVERAGE(H13:J13)) -> 9000 | AF13: =IF(ISERROR(((K13-AE13)/AE13)*100),0,((K13-AE13)/AE13)*100) -> 0 | AG13: =IF(AF13="","",IF(AF13>15,1,IF(AF13<5,3,2))) -> 3 | AH13: =IF(ISERROR(AVERAGE(L13:N13)),0,AVERAGE(L13:N13)) -> 13850 | AI13: =IF(ISERROR(((O13-AH13)/AH13)*100),0,((O13-AH13)/AH13)*100) -> 1.0830325 | AJ13: =IF(AI13="","",IF(AI13>15,1,IF(AI13<5,3,2))) -> 3 | AK13: =IF(ISERROR(AVERAGE(P13:R13)),0,AVERAGE(P13:R13)) -> 15743.333 | AL13: =IF(ISERROR(((S13-AK13)/AK13)*100),0,((S13-AK13)/AK13)*100) -> 1.312725 | AM13: =IF(AL13="","",IF(AL13>15,1,IF(AL13<5,3,2))) -> 3 | AN13: =IF(ISERROR(AVERAGE(T13:V13)),0,AVERAGE(T13:V13)) -> 39700 | AO13: =IF(ISERROR(((W13-AN13)/AN13)*100),0,((W13-AN13)/AN13)*100) -> 0.37783375 | AP13: =IF(AO13="","",IF(AO13>15,1,IF(AO13<5,3,2))) -> 3 | AQ13: =IF(ISERROR(AVERAGE(X13:Z13)),0,AVERAGE(X13:Z13)) -> 27691.667 | AR13: =IF(ISERROR(((AA13-AQ13)/AQ13)*100),0,((AA13-AQ13)/AQ13)*100) -> 9.4191995 | AS13: =IF(AR13="","",IF(AR13>15,1,IF(AR13<5,3,2))) -> 2 | AT13: =IF(ISERROR(AD13+AG13+AJ13+AM13+AP13+AS13),"",AD13+AG13+AJ13+AM13+AP13+AS13) -> 17 | AU13: =IF(AT13="","",IF(AT13<=9,"RENTAN",IF(AT13>13,"AMAN","WASPADA"))) -> AMAN | AV13: =IF(AU13="","",IF(AU13="AMAN","3",IF(AU13="RENTAN","1","2"))) -> 3
A14: =B3&" "&B6 -> KOTA CILEGON | D14: =AVERAGE(D6:D13) -> 12000 | E14: =AVERAGE(E6:E13) -> 13000 | F14: =AVERAGE(F6:F13) -> 11560 | G14: =AVERAGE(G6:G13) -> 12000 | H14: =AVERAGE(H6:H13) -> 9000 | I14: =AVERAGE(I6:I13) -> 9000 | J14: =AVERAGE(J6:J13) -> 9000 | K14: =AVERAGE(K6:K13) -> 9000 | ... AA14: =AVERAGE(AA6:AA13) -> 30300 | AB14: =IF(ISERROR(AVERAGE(D14:F14)),0,AVERAGE(D14:F14)) -> 12186.667 | AC14: =IF(ISERROR(((G14-AB14)/AB14)*100),0,((G14-AB14)/AB14)*100) -> -1.5317287 | AD14: =IF(AC14="","",IF(AC14>10,1,IF(AC14<5,3,2))) -> 3 | AE14: =IF(ISERROR(AVERAGE(H14:J14)),0,AVERAGE(H14:J14)) -> 9000 | AF14: =IF(ISERROR(((K14-AE14)/AE14)*100),0,((K14-AE14)/AE14)*100) -> 0 | AG14: =IF(AF14="","",IF(AF14>15,1,IF(AF14<5,3,2))) -> 3 | AH14: =IF(ISERROR(AVERAGE(L14:N14)),0,AVERAGE(L14:N14)) -> 13850 | AI14: =IF(ISERROR(((O14-AH14)/AH14)*100),0,((O14-AH14)/AH14)*100) -> 1.0830325 | AJ14: =IF(AI14="","",IF(AI14>15,1,IF(AI14<5,3,2))) -> 3 | AK14: =IF(ISERROR(AVERAGE(P14:R14)),0,AVERAGE(P14:R14)) -> 15743.333 | AL14: =IF(ISERROR(((S14-AK14)/AK14)*100),0,((S14-AK14)/AK14)*100) -> 1.312725 | AM14: =IF(AL14="","",IF(AL14>15,1,IF(AL14<5,3,2))) -> 3 | AN14: =IF(ISERROR(AVERAGE(T14:V14)),0,AVERAGE(T14:V14)) -> 39700 | AO14: =IF(ISERROR(((W14-AN14)/AN14)*100),0,((W14-AN14)/AN14)*100) -> 0.37783375 | AP14: =IF(AO14="","",IF(AO14>15,1,IF(AO14<5,3,2))) -> 3 | AQ14: =IF(ISERROR(AVERAGE(X14:Z14)),0,AVERAGE(X14:Z14)) -> 27691.667 | AR14: =IF(ISERROR(((AA14-AQ14)/AQ14)*100),0,((AA14-AQ14)/AQ14)*100) -> 9.4191995 | AS14: =IF(AR14="","",IF(AR14>15,1,IF(AR14<5,3,2))) -> 2 | AT14: =IF(ISERROR(AD14+AG14+AJ14+AM14+AP14+AS14),"",AD14+AG14+AJ14+AM14+AP14+AS14) -> 17 | AU14: =IF(AT14="","",IF(AT14<=9,"RENTAN",IF(AT14>13,"AMAN","WASPADA"))) -> AMAN | AV14: =IF(AU14="","",IF(AU14="AMAN","3",IF(AU14="RENTAN","1","2"))) -> 3

Sheet IP
A1: PEMANFAATAN PANGAN
A4: NO. | B4: KOTA | C4: KECAMATAN | D4: BB Sangat Kurang | E4: BB Kurang | F4: BB Normal | G4: Risiko BB Lebih | H4: BB Sangat Kurang + BB Kurang | I4: TOTAL BB/U | J4: HASIL
J5: VALUE | K5: BOBOT | L5: STATUS
A6: 1 | B6: CILEGON | C6: CIWANDAN | D6: 32 | E6: 117 | F6: 3608 | G6: 204 | H6: =D6+E6 -> 149 | I6: =SUM(D6:G6) -> 3961 | J6: =IF(ISERROR((H6/I6)*100),0,((H6/I6)*100)) -> 3.7616763 | K6: =IF(J6="","",IF(J6<10,3,IF(J6>15,1,2))) -> 3 | L6: =IF(K6="","",IF(K6=3,"AMAN",IF(K6=1,"RENTAN","WASPADA"))) -> AMAN
C7: CITANGKIL | D7: 37 | E7: 182 | F7: 4649 | G7: 298 | H7: =D7+E7 -> 219 | I7: =SUM(D7:G7) -> 5166 | J7: =IF(ISERROR((H7/I7)*100),0,((H7/I7)*100)) -> 4.2392567 | K7: =IF(J7="","",IF(J7<10,3,IF(J7>15,1,2))) -> 3 | L7: =IF(K7="","",IF(K7=3,"AMAN",IF(K7=1,"RENTAN","WASPADA"))) -> AMAN
C8: PULOMERAK | D8: 32 | E8: 166 | F8: 3232 | G8: 193 | H8: =D8+E8 -> 198 | I8: =SUM(D8:G8) -> 3623 | J8: =IF(ISERROR((H8/I8)*100),0,((H8/I8)*100)) -> 5.4650842 | K8: =IF(J8="","",IF(J8<10,3,IF(J8>15,1,2))) -> 3 | L8: =IF(K8="","",IF(K8=3,"AMAN",IF(K8=1,"RENTAN","WASPADA"))) -> AMAN
C9: PURWAKARTA | D9: 10 | E9: 62 | F9: 2534 | G9: 137 | H9: =D9+E9 -> 72 | I9: =SUM(D9:G9) -> 2743 | J9: =IF(ISERROR((H9/I9)*100),0,((H9/I9)*100)) -> 2.6248633 | K9: =IF(J9="","",IF(J9<10,3,IF(J9>15,1,2))) -> 3 | L9: =IF(K9="","",IF(K9=3,"AMAN",IF(K9=1,"RENTAN","WASPADA"))) -> AMAN
C10: GROGOL | D10: 33 | E10: 198 | F10: 2412 | G10: 33 | H10: =D10+E10 -> 231 | I10: =SUM(D10:G10) -> 2676 | J10: =IF(ISERROR((H10/I10)*100),0,((H10/I10)*100)) -> 8.632287 | K10: =IF(J10="","",IF(J10<10,3,IF(J10>15,1,2))) -> 3 | L10: =IF(K10="","",IF(K10=3,"AMAN",IF(K10=1,"RENTAN","WASPADA"))) -> AMAN
C11: CILEGON | D11: 25 | E11: 109 | F11: 2476 | G11: 117 | H11: =D11+E11 -> 134 | I11: =SUM(D11:G11) -> 2727 | J11: =IF(ISERROR((H11/I11)*100),0,((H11/I11)*100)) -> 4.9138247 | K11: =IF(J11="","",IF(J11<10,3,IF(J11>15,1,2))) -> 3 | L11: =IF(K11="","",IF(K11=3,"AMAN",IF(K11=1,"RENTAN","WASPADA"))) -> AMAN
C12: JOMBANG | D12: 23 | E12: 117 | F12: 4432 | G12: 125 | H12: =D12+E12 -> 140 | I12: =SUM(D12:G12) -> 4697 | J12: =IF(ISERROR((H12/I12)*100),0,((H12/I12)*100)) -> 2.9806259 | K12: =IF(J12="","",IF(J12<10,3,IF(J12>15,1,2))) -> 3 | L12: =IF(K12="","",IF(K12=3,"AMAN",IF(K12=1,"RENTAN","WASPADA"))) -> AMAN
C13: CIBEBER | D13: 38 | E13: 149 | F13: 3533 | G13: 71 | H13: =D13+E13 -> 187 | I13: =SUM(D13:G13) -> 3791 | J13: =IF(ISERROR((H13/I13)*100),0,((H13/I13)*100)) -> 4.9327354 | K13: =IF(J13="","",IF(J13<10,3,IF(J13>15,1,2))) -> 3 | L13: =IF(K13="","",IF(K13=3,"AMAN",IF(K13=1,"RENTAN","WASPADA"))) -> AMAN
A14: =B4&" "&B6 -> KOTA CILEGON | D14: =SUM(D6:D13) -> 230 | E14: =SUM(E6:E13) -> 1100 | F14: =SUM(F6:F13) -> 26876 | G14: =SUM(G6:G13) -> 1178 | H14: =D14+E14 -> 1330 | I14: =SUM(D14:G14) -> 29384 | J14: =IF(ISERROR((H14/I14)*100),0,((H14/I14)*100)) -> 4.5262728 | K14: =IF(J14="","",IF(J14<10,3,IF(J14>15,1,2))) -> 3 | L14: =IF(K14="","",IF(K14=3,"AMAN",IF(K14=1,"RENTAN","WASPADA"))) -> AMAN

Sheet IKB
A1: INDEKS KOMPOSIT KETAHANAN PANGAN BULANAN
A2: =SUM(IK!E1) -> 45413
A5: NO | B5: KOTA | C5: KECAMATAN | D5: IK | E5: IA | F5: IP | G5: SKOR KOMPOSIT BULANAN | H5: KETERANGAN KOMPOSIT BULANAN | I5: INDEKS KOMPOSIT BULANAN (IKB)
A6: 1 | B6: CILEGON | C6: CIWANDAN | D6: =IK!Z6 -> 2 | E6: =IA!AV6 -> 3 | F6: =IP!K6 -> 3 | G6: =IF(ISERROR(D6+E6+F6),"",D6+E6+F6) -> 8 | H6: =IF(G6="","",IF(G6<=5,"RENTAN",IF(G6>7,"AMAN","WASPADA"))) -> AMAN | I6: =IF(H6="","",IF(H6="aman","3",IF(H6="rentan","1","2"))) -> 3
C7: CITANGKIL | D7: =IK!Z7 -> 2 | E7: =IA!AV7 -> 3 | F7: =IP!K7 -> 3 | G7: =IF(ISERROR(D7+E7+F7),"",D7+E7+F7) -> 8 | H7: =IF(G7="","",IF(G7<=5,"RENTAN",IF(G7>7,"AMAN","WASPADA"))) -> AMAN | I7: =IF(H7="","",IF(H7="aman","3",IF(H7="rentan","1","2"))) -> 3
C8: PULOMERAK | D8: =IK!Z8 -> 2 | E8: =IA!AV8 -> 3 | F8: =IP!K8 -> 3 | G8: =IF(ISERROR(D8+E8+F8),"",D8+E8+F8) -> 8 | H8: =IF(G8="","",IF(G8<=5,"RENTAN",IF(G8>7,"AMAN","WASPADA"))) -> AMAN | I8: =IF(H8="","",IF(H8="aman","3",IF(H8="rentan","1","2"))) -> 3
C9: PURWAKARTA | D9: =IK!Z9 -> 2 | E9: =IA!AV9 -> 3 | F9: =IP!K9 -> 3 | G9: =IF(ISERROR(D9+E9+F9),"",D9+E9+F9) -> 8 | H9: =IF(G9="","",IF(G9<=5,"RENTAN",IF(G9>7,"AMAN","WASPADA"))) -> AMAN | I9: =IF(H9="","",IF(H9="aman","3",IF(H9="rentan","1","2"))) -> 3
C10: GROGOL | D10: =IK!Z10 -> 2 | E10: =IA!AV10 -> 3 | F10: =IP!K10 -> 3 | G10: =IF(ISERROR(D10+E10+F10),"",D10+E10+F10) -> 8 | H10: =IF(G10="","",IF(G10<=5,"RENTAN",IF(G10>7,"AMAN","WASPADA"))) -> AMAN | I10: =IF(H10="","",IF(H10="aman","3",IF(H10="rentan","1","2"))) -> 3
C11: CILEGON | D11: =IK!Z11 -> 2 | E11: =IA!AV11 -> 3 | F11: =IP!K11 -> 3 | G11: =IF(ISERROR(D11+E11+F11),"",D11+E11+F11) -> 8 | H11: =IF(G11="","",IF(G11<=5,"RENTAN",IF(G11>7,"AMAN","WASPADA"))) -> AMAN | I11: =IF(H11="","",IF(H11="aman","3",IF(H11="rentan","1","2"))) -> 3
C12: JOMBANG | D12: =IK!Z12 -> 2 | E12: =IA!AV12 -> 3 | F12: =IP!K12 -> 3 | G12: =IF(ISERROR(D12+E12+F12),"",D12+E12+F12) -> 8 | H12: =IF(G12="","",IF(G12<=5,"RENTAN",IF(G12>7,"AMAN","WASPADA"))) -> AMAN | I12: =IF(H12="","",IF(H12="aman","3",IF(H12="rentan","1","2"))) -> 3
C13: CIBEBER | D13: =IK!Z13 -> 2 | E13: =IA!AV13 -> 3 | F13: =IP!K13 -> 3 | G13: =IF(ISERROR(D13+E13+F13),"",D13+E13+F13) -> 8 | H13: =IF(G13="","",IF(G13<=5,"RENTAN",IF(G13>7,"AMAN","WASPADA"))) -> AMAN | I13: =IF(H13="","",IF(H13="aman","3",IF(H13="rentan","1","2"))) -> 3
A14: =B5&" "&B6 -> KOTA CILEGON | D14: =IK!Z39 -> 2 | E14: =IA!AV14 -> 3 | F14: =IP!K14 -> 3 | G14: =IF(ISERROR(D14+E14+F14),"",D14+E14+F14) -> 8 | H14: =IF(G14="","",IF(G14<=5,"RENTAN",IF(G14>7,"AMAN","WASPADA"))) -> AMAN | I14: =IF(H14="","",IF(H14="aman","3",IF(H14="rentan","1","2"))) -> 3

Sheet Sheet1
B1: 45292
B2: 45323
B3: 45352
B4: 45383
B5: 45413
B6: 45444
B7: 45474
B8: 45505
B9: 45536
B10: 45566
B11: 45597
B12: 45627

Sheet Sheet2
A1: KETERSEDIAAN PANGAN
A2: NO. | B2: PROVINSI | C2: KABUPATEN/KOTA | D2: JULI | G2: AGUSTUS | J2: SEPTEMBER | M2: OKTOBER | P2: NOVEMBER | S2: DESEMBER
D3: % REAL | E3: LUAS | F3: HASIL 100% | G3: % REAL | H3: LUAS | I3: HASIL 100% | J3: % REAL | K3: LUAS | L3: HASIL 100% | M3: % REAL | N3: LUAS | O3: HASIL 100% | P3: % REAL | Q3: LUAS | R3: HASIL 100% | S3: % REAL | T3: LUAS | U3: HASIL 100%
A4: 1 | B4: Aceh | C4: 1101000 Simeulue | E4: =IK!I6 -> 0 | F4: =E4/D4 -> #DIV/0! | I4: =H4/G4 -> #DIV/0! | L4: =K4/J4 -> #DIV/0! | O4: =N4/M4 -> #DIV/0! | R4: =Q4/P4 -> #DIV/0! | U4: =T4/S4 -> #DIV/0!
A5: 2 | B5: Aceh | C5: 1102000 Aceh Singkil | E5: =IK!I7 -> 0 | F5: =E5/D5 -> #DIV/0! | I5: =H5/G5 -> #DIV/0! | L5: =K5/J5 -> #DIV/0! | O5: =N5/M5 -> #DIV/0! | R5: =Q5/P5 -> #DIV/0! | U5: =T5/S5 -> #DIV/0!
A6: 3 | B6: Aceh | C6: 1103000 Aceh Selatan | E6: =IK!I8 -> 0 | F6: =E6/D6 -> #DIV/0! | I6: =H6/G6 -> #DIV/0! | L6: =K6/J6 -> #DIV/0! | O6: =N6/M6 -> #DIV/0! | R6: =Q6/P6 -> #DIV/0! | U6: =T6/S6 -> #DIV/0!
A7: 4 | B7: Aceh | C7: 1104000 Aceh Tenggara | E7: =IK!I9 -> 0 | F7: =E7/D7 -> #DIV/0! | I7: =H7/G7 -> #DIV/0! | L7: =K7/J7 -> #DIV/0! | O7: =N7/M7 -> #DIV/0! | R7: =Q7/P7 -> #DIV/0! | U7: =T7/S7 -> #DIV/0!
A8: 5 | B8: Aceh | C8: 1105000 Aceh Timur | E8: =IK!I10 -> 0 | F8: =E8/D8 -> #DIV/0! | I8: =H8/G8 -> #DIV/0! | L8: =K8/J8 -> #DIV/0! | O8: =N8/M8 -> #DIV/0! | R8: =Q8/P8 -> #DIV/0! | U8: =T8/S8 -> #DIV/0!
A9: 6 | B9: Aceh | C9: 1106000 Aceh Tengah | E9: =IK!I11 -> 0 | F9: =E9/D9 -> #DIV/0! | I9: =H9/G9 -> #DIV/0! | L9: =K9/J9 -> #DIV/0! | O9: =N9/M9 -> #DIV/0! | R9: =Q9/P9 -> #DIV/0! | U9: =T9/S9 -> #DIV/0!
A10: 7 | B10: Aceh | C10: 1107000 Aceh Barat | E10: =IK!I12 -> 0 | F10: =E10/D10 -> #DIV/0! | I10: =H10/G10 -> #DIV/0! | L10: =K10/J10 -> #DIV/0! | O10: =N10/M10 -> #DIV/0! | R10: =Q10/P10 -> #DIV/0! | U10: =T10/S10 -> #DIV/0!
A11: 8 | B11: Aceh | C11: 1108000 Aceh Besar | E11: =IK!I13 -> 0 | F11: =E11/D11 -> #DIV/0! | I11: =H11/G11 -> #DIV/0! | L11: =K11/J11 -> #DIV/0! | O11: =N11/M11 -> #DIV/0! | R11: =Q11/P11 -> #DIV/0! | U11: =T11/S11 -> #DIV/0!
A12: 9 | B12: Aceh | C12: 1109000 Pidie | E12: =IK!I14 -> 0 | F12: =E12/D12 -> #DIV/0! | I12: =H12/G12 -> #DIV/0! | L12: =K12/J12 -> #DIV/0! | O12: =N12/M12 -> #DIV/0! | R12: =Q12/P12 -> #DIV/0! | U12: =T12/S12 -> #DIV/0!
A13: 10 | B13: Aceh | C13: 1110000 Bireuen | E13: =IK!I15 -> 0 | F13: =E13/D13 -> #DIV/0! | I13: =H13/G13 -> #DIV/0! | L13: =K13/J13 -> #DIV/0! | O13: =N13/M13 -> #DIV/0! | R13: =Q13/P13 -> #DIV/0! | U13: =T13/S13 -> #DIV/0!
A14: 11 | B14: Aceh | C14: 1111000 Aceh Utara | E14: =IK!I16 -> 0 | F14: =E14/D14 -> #DIV/0! | I14: =H14/G14 -> #DIV/0! | L14: =K14/J14 -> #DIV/0! | O14: =N14/M14 -> #DIV/0! | R14: =Q14/P14 -> #DIV/0! | U14: =T14/S14 -> #DIV/0!
A15: 12 | B15: Aceh | C15: 1112000 Aceh Barat Daya | E15: =IK!I17 -> 0 | F15: =E15/D15 -> #DIV/0! | I15: =H15/G15 -> #DIV/0! | L15: =K15/J15 -> #DIV/0! | O15: =N15/M15 -> #DIV/0! | R15: =Q15/P15 -> #DIV/0! | U15: =T15/S15 -> #DIV/0!
... A26: 23 | B26: Aceh | C26: 1175000 Subulussalam | E26: =IK!I28 -> 0 | F26: =E26/D26 -> #DIV/0! | I26: =H26/G26 -> #DIV/0! | L26: =K26/J26 -> #DIV/0! | O26: =N26/M26 -> #DIV/0! | R26: =Q26/P26 -> #DIV/0! | U26: =T26/S26 -> #DIV/0!
B27: Aceh | E27: =IK!I29 -> 0 | F27: =E27/D27 -> #DIV/0! | I27: =H27/G27 -> #DIV/0! | L27: =K27/J27 -> #DIV/0! | O27: =N27/M27 -> #DIV/0! | R27: =Q27/P27 -> #DIV/0! | U27: =T27/S27 -> #DIV/0!
A28: 24 | B28: Sumatera Utara | C28: 1201000 Nias | E28: =IK!I30 -> 0 | F28: =E28/D28 -> #DIV/0! | I28: =H28/G28 -> #DIV/0! | L28: =K28/J28 -> #DIV/0! | O28: =N28/M28 -> #DIV/0! | R28: =Q28/P28 -> #DIV/0! | U28: =T28/S28 -> #DIV/0!
A29: 25 | B29: Sumatera Utara | C29: 1202000 Mandailing Natal | E29: =IK!I31 -> 0 | F29: =E29/D29 -> #DIV/0! | I29: =H29/G29 -> #DIV/0! | L29: =K29/J29 -> #DIV/0! | O29: =N29/M29 -> #DIV/0! | R29: =Q29/P29 -> #DIV/0! | U29: =T29/S29 -> #DIV/0!
A30: 26 | B30: Sumatera Utara | C30: 1203000 Tapanuli Selatan | E30: =IK!I32 -> 0 | F30: =E30/D30 -> #DIV/0! | I30: =H30/G30 -> #DIV/0! | L30: =K30/J30 -> #DIV/0! | O30: =N30/M30 -> #DIV/0! | R30: =Q30/P30 -> #DIV/0! | U30: =T30/S30 -> #DIV/0!
A31: 27 | B31: Sumatera Utara | C31: 1204000 Tapanuli Tengah | E31: =IK!I33 -> 0 | F31: =E31/D31 -> #DIV/0! | I31: =H31/G31 -> #DIV/0! | L31: =K31/J31 -> #DIV/0! | O31: =N31/M31 -> #DIV/0! | R31: =Q31/P31 -> #DIV/0! | U31: =T31/S31 -> #DIV/0!
A32: 28 | B32: Sumatera Utara | C32: 1205000 Tapanuli Utara | E32: =IK!I34 -> 0 | F32: =E32/D32 -> #DIV/0! | I32: =H32/G32 -> #DIV/0! | L32: =K32/J32 -> #DIV/0! | O32: =N32/M32 -> #DIV/0! | R32: =Q32/P32 -> #DIV/0! | U32: =T32/S32 -> #DIV/0!
A33: 29 | B33: Sumatera Utara | C33: 1206000 Toba Samosir | E33: =IK!I35 -> 0 | F33: =E33/D33 -> #DIV/0! | I33: =H33/G33 -> #DIV/0! | L33: =K33/J33 -> #DIV/0! | O33: =N33/M33 -> #DIV/0! | R33: =Q33/P33 -> #DIV/0! | U33: =T33/S33 -> #DIV/0!
A34: 30 | B34: Sumatera Utara | C34: 1207000 Labuhan Batu | E34: =IK!I36 -> 0 | F34: =E34/D34 -> #DIV/0! | I34: =H34/G34 -> #DIV/0! | L34: =K34/J34 -> #DIV/0! | O34: =N34/M34 -> #DIV/0! | R34: =Q34/P34 -> #DIV/0! | U34: =T34/S34 -> #DIV/0!
A35: 31 | B35: Sumatera Utara | C35: 1208000 Asahan | E35: =IK!I37 -> 0 | F35: =E35/D35 -> #DIV/0! | I35: =H35/G35 -> #DIV/0! | L35: =K35/J35 -> #DIV/0! | O35: =N35/M35 -> #DIV/0! | R35: =Q35/P35 -> #DIV/0! | U35: =T35/S35 -> #DIV/0!
A36: 32 | B36: Sumatera Utara | C36: 1209000 Simalungun | E36: =IK!I38 -> 0 | F36: =E36/D36 -> #DIV/0! | I36: =H36/G36 -> #DIV/0! | L36: =K36/J36 -> #DIV/0! | O36: =N36/M36 -> #DIV/0! | R36: =Q36/P36 -> #DIV/0! | U36: =T36/S36 -> #DIV/0!
A37: 33 | B37: Sumatera Utara | C37: 1210000 Dairi | E37: =IK!#REF! -> #REF! | F37: =E37/D37 -> #REF! | I37: =H37/G37 -> #DIV/0! | L37: =K37/J37 -> #DIV/0! | O37: =N37/M37 -> #DIV/0! | R37: =Q37/P37 -> #DIV/0! | U37: =T37/S37 -> #DIV/0!
A38: 34 | B38: Sumatera Utara | C38: 1211000 Karo | E38: =IK!#REF! -> #REF! | F38: =E38/D38 -> #REF! | I38: =H38/G38 -> #DIV/0! | L38: =K38/J38 -> #DIV/0! | O38: =N38/M38 -> #DIV/0! | R38: =Q38/P38 -> #DIV/0! | U38: =T38/S38 -> #DIV/0!
A39: 35 | B39: Sumatera Utara | C39: 1212000 Deli Serdang | E39: =IK!#REF! -> #REF! | F39: =E39/D39 -> #REF! | I39: =H39/G39 -> #DIV/0! | L39: =K39/J39 -> #DIV/0! | O39: =N39/M39 -> #DIV/0! | R39: =Q39/P39 -> #DIV/0! | U39: =T39/S39 -> #DIV/0!
A40: 36 | B40: Sumatera Utara | C40: 1213000 Langkat | E40: =IK!#REF! -> #REF! | F40: =E40/D40 -> #REF! | I40: =H40/G40 -> #DIV/0! | L40: =K40/J40 -> #DIV/0! | O40: =N40/M40 -> #DIV/0! | R40: =Q40/P40 -> #DIV/0! | U40: =T40/S40 -> #DIV/0!
A41: 37 | B41: Sumatera Utara | C41: 1214000 Nias Selatan | E41: =IK!#REF! -> #REF! | F41: =E41/D41 -> #REF! | I41: =H41/G41 -> #DIV/0! | L41: =K41/J41 -> #DIV/0! | O41: =N41/M41 -> #DIV/0! | R41: =Q41/P41 -> #DIV/0! | U41: =T41/S41 -> #DIV/0!
A42: 38 | B42: Sumatera Utara | C42: 1215000 Humbang Hasundutan | E42: =IK!#REF! -> #REF! | F42: =E42/D42 -> #REF! | I42: =H42/G42 -> #DIV/0! | L42: =K42/J42 -> #DIV/0! | O42: =N42/M42 -> #DIV/0! | R42: =Q42/P42 -> #DIV/0! | U42: =T42/S42 -> #DIV/0!
A43: 39 | B43: Sumatera Utara | C43: 1216000 Pakpak Bharat | E43: =IK!#REF! -> #REF! | F43: =E43/D43 -> #REF! | I43: =H43/G43 -> #DIV/0! | L43: =K43/J43 -> #DIV/0! | O43: =N43/M43 -> #DIV/0! | R43: =Q43/P43 -> #DIV/0! | U43: =T43/S43 -> #DIV/0!
A44: 40 | B44: Sumatera Utara | C44: 1217000 Samosir | E44: =IK!#REF! -> #REF! | F44: =E44/D44 -> #REF! | I44: =H44/G44 -> #DIV/0! | L44: =K44/J44 -> #DIV/0! | O44: =N44/M44 -> #DIV/0! | R44: =Q44/P44 -> #DIV/0! | U44: =T44/S44 -> #DIV/0!
A45: 41 | B45: Sumatera Utara | C45: 1218000 Serdang Bedagai | E45: =IK!#REF! -> #REF! | F45: =E45/D45 -> #REF! | I45: =H45/G45 -> #DIV/0! | L45: =K45/J45 -> #DIV/0! | O45: =N45/M45 -> #DIV/0! | R45: =Q45/P45 -> #DIV/0! | U45: =T45/S45 -> #DIV/0!
A46: 42 | B46: Sumatera Utara | C46: 1219000 Batu Bara | E46: =IK!#REF! -> #REF! | F46: =E46/D46 -> #REF! | I46: =H46/G46 -> #DIV/0! | L46: =K46/J46 -> #DIV/0! | O46: =N46/M46 -> #DIV/0! | R46: =Q46/P46 -> #DIV/0! | U46: =T46/S46 -> #DIV/0!
A47: 43 | B47: Sumatera Utara | C47: 1220000 Padang Lawas Utara | E47: =IK!#REF! -> #REF! | F47: =E47/D47 -> #REF! | I47: =H47/G47 -> #DIV/0! | L47: =K47/J47 -> #DIV/0! | O47: =N47/M47 -> #DIV/0! | R47: =Q47/P47 -> #DIV/0! | U47: =T47/S47 -> #DIV/0!
A48: 44 | B48: Sumatera Utara | C48: 1221000 Padang Lawas | E48: =IK!#REF! -> #REF! | F48: =E48/D48 -> #REF! | I48: =H48/G48 -> #DIV/0! | L48: =K48/J48 -> #DIV/0! | O48: =N48/M48 -> #DIV/0! | R48: =Q48/P48 -> #DIV/0! | U48: =T48/S48 -> #DIV/0!
... A60: 56 | B60: Sumatera Utara | C60: 1278000 Gunungsitoli | E60: =IK!#REF! -> #REF! | F60: =E60/D60 -> #REF! | I60: =H60/G60 -> #DIV/0! | L60: =K60/J60 -> #DIV/0! | O60: =N60/M60 -> #DIV/0! | R60: =Q60/P60 -> #DIV/0! | U60: =T60/S60 -> #DIV/0!
B61: Sumatera Utara | E61: =IK!#REF! -> #REF! | F61: =E61/D61 -> #REF! | I61: =H61/G61 -> #DIV/0! | L61: =K61/J61 -> #DIV/0! | O61: =N61/M61 -> #DIV/0! | R61: =Q61/P61 -> #DIV/0! | U61: =T61/S61 -> #DIV/0!
...
