Workbook

Sheet IK
A1: KETERSEDIAAN PANGAN | D1: Bulan : | E1: 45809 | F1: pilih dulu
A3: NO. | B3: PROVINSI | C3: KABUPATEN/KOTA | D3: LUAS TANAM PADI | J3: LUAS PUSO PADI | P3: LUAS TANAM PADI | T3: LUAS PUSO PADI | X3: KOMPOSIT
D4: Bulan berjalan di 5 tahun sebelum | I4: Bulan Berjalan | J4: Bulan berjalan di 5 tahun sebelum | O4: Bulan Berjalan | P4: Rata-Rata 5 th | Q4: Hasil | T4: Rata-Rata 5 th | U4: Hasil
D5: 2020 | E5: 2021 | F5: 2024 | G5: 2023 | H5: 2024 | J5: 2020 | K5: 2021 | L5: 2024 | M5: 2023 | N5: 2024 | Q5: Value | R5: Bobot | S5: Status | U5: Value | V5: Bobot | W5: Status | X5: Value | Y5: Status | Z5: Indeks
P6: =IF(ISERROR(AVERAGE(D6:H6)),0,AVERAGE(D6:H6)) -> 0 | Q6: =IF(ISERROR(((I6-P6)/P6)*100),0,((I6-P6)/P6)*100) -> 0 | R6: =IF(Q6="","",IF(Q6>=5,3,IF(Q6<-5,1,2))) -> 2 | S6: =IF(R6="","",IF(R6=3,"AMAN",IF(R6=1,"RENTAN","WASPADA"))) -> WASPADA | T6: =(IF(ISERROR(AVERAGE(J6:N6)),0,AVERAGE(J6:N6)))+0.00001 -> 1e-05 | U6: =(IF(ISERROR(((O6-T6)/T6)*100),0,((O6-T6)/T6)*100))+0.00001 -> -99.99999 | V6: =IF(U6="","",IF(U6<-5,3,IF(U6>=5,1,IF(U6=0,3,2)))) -> 3 | W6: =IF(V6="","",IF(V6=3,"AMAN",IF(V6=1,"RENTAN","WASPADA"))) -> AMAN | X6: =R6+V6 -> 5 | Y6: =IF(X6="","",IF(X6<=3,"RENTAN",IF(X6>5,"AMAN","WASPADA"))) -> WASPADA | Z6: =IF(Y6="","",IF(Y6="AMAN","3",IF(Y6="RENTAN","1","2"))) -> 2
P7: =IF(ISERROR(AVERAGE(D7:H7)),0,AVERAGE(D7:H7)) -> 0 | Q7: =IF(ISERROR(((I7-P7)/P7)*100),0,((I7-P7)/P7)*100) -> 0 | R7: =IF(Q7="","",IF(Q7>=5,3,IF(Q7<-5,1,2))) -> 2 | S7: =IF(R7="","",IF(R7=3,"AMAN",IF(R7=1,"RENTAN","WASPADA"))) -> WASPADA | T7: =(IF(ISERROR(AVERAGE(J7:N7)),0,AVERAGE(J7:N7)))+0.00001 -> 1e-05 | U7: =(IF(ISERROR(((O7-T7)/T7)*100),0,((O7-T7)/T7)*100))+0.00001 -> -99.99999 | V7: =IF(U7="","",IF(U7<-5,3,IF(U7>=5,1,IF(U7=0,3,2)))) -> 3 | W7: =IF(V7="","",IF(V7=3,"AMAN",IF(V7=1,"RENTAN","WASPADA"))) -> AMAN | X7: =R7+V7 -> 5 | Y7: =IF(X7="","",IF(X7<=3,"RENTAN",IF(X7>5,"AMAN","WASPADA"))) -> WASPADA | Z7: =IF(Y7="","",IF(Y7="AMAN","3",IF(Y7="RENTAN","1","2"))) -> 2
P8: =IF(ISERROR(AVERAGE(D8:H8)),0,AVERAGE(D8:H8)) -> 0 | Q8: =IF(ISERROR(((I8-P8)/P8)*100),0,((I8-P8)/P8)*100) -> 0 | R8: =IF(Q8="","",IF(Q8>=5,3,IF(Q8<-5,1,2))) -> 2 | S8: =IF(R8="","",IF(R8=3,"AMAN",IF(R8=1,"RENTAN","WASPADA"))) -> WASPADA | T8: =(IF(ISERROR(AVERAGE(J8:N8)),0,AVERAGE(J8:N8)))+0.00001 -> 1e-05 | U8: =(IF(ISERROR(((O8-T8)/T8)*100),0,((O8-T8)/T8)*100))+0.00001 -> -99.99999 | V8: =IF(U8="","",IF(U8<-5,3,IF(U8>=5,1,IF(U8=0,3,2)))) -> 3 | W8: =IF(V8="","",IF(V8=3,"AMAN",IF(V8=1,"RENTAN","WASPADA"))) -> AMAN | X8: =R8+V8 -> 5 | Y8: =IF(X8="","",IF(X8<=3,"RENTAN",IF(X8>5,"AMAN","WASPADA"))) -> WASPADA | Z8: =IF(Y8="","",IF(Y8="AMAN","3",IF(Y8="RENTAN","1","2"))) -> 2
P9: =IF(ISERROR(AVERAGE(D9:H9)),0,AVERAGE(D9:H9)) -> 0 | Q9: =IF(ISERROR(((I9-P9)/P9)*100),0,((I9-P9)/P9)*100) -> 0 | R9: =IF(Q9="","",IF(Q9>=5,3,IF(Q9<-5,1,2))) -> 2 | S9: =IF(R9="","",IF(R9=3,"AMAN",IF(R9=1,"RENTAN","WASPADA"))) -> WASPADA | T9: =(IF(ISERROR(AVERAGE(J9:N9)),0,AVERAGE(J9:N9)))+0.00001 -> 1e-05 | U9: =(IF(ISERROR(((O9-T9)/T9)*100),0,((O9-T9)/T9)*100))+0.00001 -> -99.99999 | V9: =IF(U9="","",IF(U9<-5,3,IF(U9>=5,1,IF(U9=0,3,2)))) -> 3 | W9: =IF(V9="","",IF(V9=3,"AMAN",IF(V9=1,"RENTAN","WASPADA"))) -> AMAN | X9: =R9+V9 -> 5 | Y9: =IF(X9="","",IF(X9<=3,"RENTAN",IF(X9>5,"AMAN","WASPADA"))) -> WASPADA | Z9: =IF(Y9="","",IF(Y9="AMAN","3",IF(Y9="RENTAN","1","2"))) -> 2
P10: =IF(ISERROR(AVERAGE(D10:H10)),0,AVERAGE(D10:H10)) -> 0 | Q10: =IF(ISERROR(((I10-P10)/P10)*100),0,((I10-P10)/P10)*100) -> 0 | R10: =IF(Q10="","",IF(Q10>=5,3,IF(Q10<-5,1,2))) -> 2 | S10: =IF(R10="","",IF(R10=3,"AMAN",IF(R10=1,"RENTAN","WASPADA"))) -> WASPADA | T10: =(IF(ISERROR(AVERAGE(J10:N10)),0,AVERAGE(J10:N10)))+0.00001 -> 1e-05 | U10: =(IF(ISERROR(((O10-T10)/T10)*100),0,((O10-T10)/T10)*100))+0.00001 -> -99.99999 | V10: =IF(U10="","",IF(U10<-5,3,IF(U10>=5,1,IF(U10=0,3,2)))) -> 3 | W10: =IF(V10="","",IF(V10=3,"AMAN",IF(V10=1,"RENTAN","WASPADA"))) -> AMAN | X10: =R10+V10 -> 5 | Y10: =IF(X10="","",IF(X10<=3,"RENTAN",IF(X10>5,"AMAN","WASPADA"))) -> WASPADA | Z10: =IF(Y10="","",IF(Y10="AMAN","3",IF(Y10="RENTAN","1","2"))) -> 2
P11: =IF(ISERROR(AVERAGE(D11:H11)),0,AVERAGE(D11:H11)) -> 0 | Q11: =IF(ISERROR(((I11-P11)/P11)*100),0,((I11-P11)/P11)*100) -> 0 | R11: =IF(Q11="","",IF(Q11>=5,3,IF(Q11<-5,1,2))) -> 2 | S11: =IF(R11="","",IF(R11=3,"AMAN",IF(R11=1,"RENTAN","WASPADA"))) -> WASPADA | T11: =(IF(ISERROR(AVERAGE(J11:N11)),0,AVERAGE(J11:N11)))+0.00001 -> 1e-05 | U11: =(IF(ISERROR(((O11-T11)/T11)*100),0,((O11-T11)/T11)*100))+0.00001 -> -99.99999 | V11: =IF(U11="","",IF(U11<-5,3,IF(U11>=5,1,IF(U11=0,3,2)))) -> 3 | W11: =IF(V11="","",IF(V11=3,"AMAN",IF(V11=1,"RENTAN","WASPADA"))) -> AMAN | X11: =R11+V11 -> 5 | Y11: =IF(X11="","",IF(X11<=3,"RENTAN",IF(X11>5,"AMAN","WASPADA"))) -> WASPADA | Z11: =IF(Y11="","",IF(Y11="AMAN","3",IF(Y11="RENTAN","1","2"))) -> 2
P12: =IF(ISERROR(AVERAGE(D12:H12)),0,AVERAGE(D12:H12)) -> 0 | Q12: =IF(ISERROR(((I12-P12)/P12)*100),0,((I12-P12)/P12)*100) -> 0 | R12: =IF(Q12="","",IF(Q12>=5,3,IF(Q12<-5,1,2))) -> 2 | S12: =IF(R12="","",IF(R12=3,"AMAN",IF(R12=1,"RENTAN","WASPADA"))) -> WASPADA | T12: =(IF(ISERROR(AVERAGE(J12:N12)),0,AVERAGE(J12:N12)))+0.00001 -> 1e-05 | U12: =(IF(ISERROR(((O12-T12)/T12)*100),0,((O12-T12)/T12)*100))+0.00001 -> -99.99999 | V12: =IF(U12="","",IF(U12<-5,3,IF(U12>=5,1,IF(U12=0,3,2)))) -> 3 | W12: =IF(V12="","",IF(V12=3,"AMAN",IF(V12=1,"RENTAN","WASPADA"))) -> AMAN | X12: =R12+V12 -> 5 | Y12: =IF(X12="","",IF(X12<=3,"RENTAN",IF(X12>5,"AMAN","WASPADA"))) -> WASPADA | Z12: =IF(Y12="","",IF(Y12="AMAN","3",IF(Y12="RENTAN","1","2"))) -> 2
P13: =IF(ISERROR(AVERAGE(D13:H13)),0,AVERAGE(D13:H13)) -> 0 | Q13: =IF(ISERROR(((I13-P13)/P13)*100),0,((I13-P13)/P13)*100) -> 0 | R13: =IF(Q13="","",IF(Q13>=5,3,IF(Q13<-5,1,2))) -> 2 | S13: =IF(R13="","",IF(R13=3,"AMAN",IF(R13=1,"RENTAN","WASPADA"))) -> WASPADA | T13: =(IF(ISERROR(AVERAGE(J13:N13)),0,AVERAGE(J13:N13)))+0.00001 -> 1e-05 | U13: =(IF(ISERROR(((O13-T13)/T13)*100),0,((O13-T13)/T13)*100))+0.00001 -> -99.99999 | V13: =IF(U13="","",IF(U13<-5,3,IF(U13>=5,1,IF(U13=0,3,2)))) -> 3 | W13: =IF(V13="","",IF(V13=3,"AMAN",IF(V13=1,"RENTAN","WASPADA"))) -> AMAN | X13: =R13+V13 -> 5 | Y13: =IF(X13="","",IF(X13<=3,"RENTAN",IF(X13>5,"AMAN","WASPADA"))) -> WASPADA | Z13: =IF(Y13="","",IF(Y13="AMAN","3",IF(Y13="RENTAN","1","2"))) -> 2
P14: =IF(ISERROR(AVERAGE(D14:H14)),0,AVERAGE(D14:H14)) -> 0 | Q14: =IF(ISERROR(((I14-P14)/P14)*100),0,((I14-P14)/P14)*100) -> 0 | R14: =IF(Q14="","",IF(Q14>=5,3,IF(Q14<-5,1,2))) -> 2 | S14: =IF(R14="","",IF(R14=3,"AMAN",IF(R14=1,"RENTAN","WASPADA"))) -> WASPADA | T14: =(IF(ISERROR(AVERAGE(J14:N14)),0,AVERAGE(J14:N14)))+0.00001 -> 1e-05 | U14: =(IF(ISERROR(((O14-T14)/T14)*100),0,((O14-T14)/T14)*100))+0.00001 -> -99.99999 | V14: =IF(U14="","",IF(U14<-5,3,IF(U14>=5,1,IF(U14=0,3,2)))) -> 3 | W14: =IF(V14="","",IF(V14=3,"AMAN",IF(V14=1,"RENTAN","WASPADA"))) -> AMAN | X14: =R14+V14 -> 5 | Y14: =IF(X14="","",IF(X14<=3,"RENTAN",IF(X14>5,"AMAN","WASPADA"))) -> WASPADA | Z14: =IF(Y14="","",IF(Y14="AMAN","3",IF(Y14="RENTAN","1","2"))) -> 2
P15: =IF(ISERROR(AVERAGE(D15:H15)),0,AVERAGE(D15:H15)) -> 0 | Q15: =IF(ISERROR(((I15-P15)/P15)*100),0,((I15-P15)/P15)*100) -> 0 | R15: =IF(Q15="","",IF(Q15>=5,3,IF(Q15<-5,1,2))) -> 2 | S15: =IF(R15="","",IF(R15=3,"AMAN",IF(R15=1,"RENTAN","WASPADA"))) -> WASPADA | T15: =(IF(ISERROR(AVERAGE(J15:N15)),0,AVERAGE(J15:N15)))+0.00001 -> 1e-05 | U15: =(IF(ISERROR(((O15-T15)/T15)*100),0,((O15-T15)/T15)*100))+0.00001 -> -99.99999 | V15: =IF(U15="","",IF(U15<-5,3,IF(U15>=5,1,IF(U15=0,3,2)))) -> 3 | W15: =IF(V15="","",IF(V15=3,"AMAN",IF(V15=1,"RENTAN","WASPADA"))) -> AMAN | X15: =R15+V15 -> 5 | Y15: =IF(X15="","",IF(X15<=3,"RENTAN",IF(X15>5,"AMAN","WASPADA"))) -> WASPADA | Z15: =IF(Y15="","",IF(Y15="AMAN","3",IF(Y15="RENTAN","1","2"))) -> 2
P16: =IF(ISERROR(AVERAGE(D16:H16)),0,AVERAGE(D16:H16)) -> 0 | Q16: =IF(ISERROR(((I16-P16)/P16)*100),0,((I16-P16)/P16)*100) -> 0 | R16: =IF(Q16="","",IF(Q16>=5,3,IF(Q16<-5,1,2))) -> 2 | S16: =IF(R16="","",IF(R16=3,"AMAN",IF(R16=1,"RENTAN","WASPADA"))) -> WASPADA | T16: =(IF(ISERROR(AVERAGE(J16:N16)),0,AVERAGE(J16:N16)))+0.00001 -> 1e-05 | U16: =(IF(ISERROR(((O16-T16)/T16)*100),0,((O16-T16)/T16)*100))+0.00001 -> -99.99999 | V16: =IF(U16="","",IF(U16<-5,3,IF(U16>=5,1,IF(U16=0,3,2)))) -> 3 | W16: =IF(V16="","",IF(V16=3,"AMAN",IF(V16=1,"RENTAN","WASPADA"))) -> AMAN | X16: =R16+V16 -> 5 | Y16: =IF(X16="","",IF(X16<=3,"RENTAN",IF(X16>5,"AMAN","WASPADA"))) -> WASPADA | Z16: =IF(Y16="","",IF(Y16="AMAN","3",IF(Y16="RENTAN","1","2"))) -> 2
P17: =IF(ISERROR(AVERAGE(D17:H17)),0,AVERAGE(D17:H17)) -> 0 | Q17: =IF(ISERROR(((I17-P17)/P17)*100),0,((I17-P17)/P17)*100) -> 0 | R17: =IF(Q17="","",IF(Q17>=5,3,IF(Q17<-5,1,2))) -> 2 | S17: =IF(R17="","",IF(R17=3,"AMAN",IF(R17=1,"RENTAN","WASPADA"))) -> WASPADA | T17: =(IF(ISERROR(AVERAGE(J17:N17)),0,AVERAGE(J17:N17)))+0.00001 -> 1e-05 | U17: =(IF(ISERROR(((O17-T17)/T17)*100),0,((O17-T17)/T17)*100))+0.00001 -> -99.99999 | V17: =IF(U17="","",IF(U17<-5,3,IF(U17>=5,1,IF(U17=0,3,2)))) -> 3 | W17: =IF(V17="","",IF(V17=3,"AMAN",IF(V17=1,"RENTAN","WASPADA"))) -> AMAN | X17: =R17+V17 -> 5 | Y17: =IF(X17="","",IF(X17<=3,"RENTAN",IF(X17>5,"AMAN","WASPADA"))) -> WASPADA | Z17: =IF(Y17="","",IF(Y17="AMAN","3",IF(Y17="RENTAN","1","2"))) -> 2
... P38: =IF(ISERROR(AVERAGE(D38:H38)),0,AVERAGE(D38:H38)) -> 0 | Q38: =IF(ISERROR(((I38-P38)/P38)*100),0,((I38-P38)/P38)*100) -> 0 | R38: =IF(Q38="","",IF(Q38>=5,3,IF(Q38<-5,1,2))) -> 2 | S38: =IF(R38="","",IF(R38=3,"AMAN",IF(R38=1,"RENTAN","WASPADA"))) -> WASPADA | T38: =(IF(ISERROR(AVERAGE(J38:N38)),0,AVERAGE(J38:N38)))+0.00001 -> 1e-05 | U38: =(IF(ISERROR(((O38-T38)/T38)*100),0,((O38-T38)/T38)*100))+0.00001 -> -99.99999 | V38: =IF(U38="","",IF(U38<-5,3,IF(U38>=5,1,IF(U38=0,3,2)))) -> 3 | W38: =IF(V38="","",IF(V38=3,"AMAN",IF(V38=1,"RENTAN","WASPADA"))) -> AMAN | X38: =R38+V38 -> 5 | Y38: =IF(X38="","",IF(X38<=3,"RENTAN",IF(X38>5,"AMAN","WASPADA"))) -> WASPADA | Z38: =IF(Y38="","",IF(Y38="AMAN","3",IF(Y38="RENTAN","1","2"))) -> 2
A39: =B3&""&B6 -> PROVINSI | D39: =SUM(D6:D38) -> 0 | E39: =SUM(E6:E38) -> 0 | F39: =SUM(F6:F38) -> 0 | G39: =SUM(G6:G38) -> 0 | H39: =SUM(H6:H38) -> 0 | I39: =SUM(I6:I38) -> 0 | J39: =SUM(J6:J38) -> 0 | K39: =SUM(K6:K38) -> 0 | ... O39: =SUM(O6:O38) -> 0 | P39: =IF(ISERROR(AVERAGE(D39:H39)),0,AVERAGE(D39:H39)) -> 0 | Q39: =IF(ISERROR(((I39-P39)/P39)*100),0,((I39-P39)/P39)*100) -> 0 | R39: =IF(Q39="","",IF(Q39>=5,3,IF(Q39<-5,1,2))) -> 2 | S39: =IF(R39="","",IF(R39=3,"AMAN",IF(R39=1,"RENTAN","WASPADA"))) -> WASPADA | T39: =(IF(ISERROR(AVERAGE(J39:N39)),0,AVERAGE(J39:N39)))+0.00001 -> 1e-05 | U39: =(IF(ISERROR(((O39-T39)/T39)*100),0,((O39-T39)/T39)*100))+0.00001 -> -99.99999 | V39: =IF(U39="","",IF(U39<-5,3,IF(U39>=5,1,IF(U39=0,3,2)))) -> 3 | W39: =IF(V39="","",IF(V39=3,"AMAN",IF(V39=1,"RENTAN","WASPADA"))) -> AMAN | X39: =R39+V39 -> 5 | Y39: =IF(X39="","",IF(X39<=3,"RENTAN",IF(X39>5,"AMAN","WASPADA"))) -> WASPADA | Z39: =IF(Y39="","",IF(Y39="AMAN","3",IF(Y39="RENTAN","1","2"))) -> 2

Sheet IA
A1: AKSES PANGAN | J1: AKSES PANGAN
A2: =SUM(IK!E1) -> 45809 | J2: =SUM(IK!E1) -> 45809
A3: NO. | B3: KOTA | C3: KECAMATAN | D3: HARGA BERAS Bulan berjalan 1 tahun sebelumnya | E3: Bulan Berjalan | F3: HARGA MINYAK GORENG KEMASAN Bulan berjalan 1 tahun sebelumnya | G3: Bulan Berjalan | H3: HARGA TELUR AYAM RAS Bulan berjalan 1 tahun sebelumnya | I3: Bulan Berjalan | J3: BERAS | L3: MINYAK GORENG | N3: TELUR AYAM | P3: BOBOT
J4: Value | K4: Bobot | L4: Value | M4: Bobot | N4: Value | O4: Bobot
D5: =IK!$E$1-360 -> 45449 | E5: =IK!$E$1 -> 45809 | F5: =D5 -> 45449 | G5: =E5 -> 45809 | H5: =F5 -> 45449 | I5: =G5 -> 45809 | P5: VALUE | Q5: STATUS | R5: INDEKS
A6: 1 | B6: CILEGON | C6: Cibeber | D6: 16500 | E6: 14000 | F6: 18000 | G6: 22000 | H6: 27570 | I6: 28000 | J6: =IF(ISERROR(((E6-D6)/D6)*100),0,((E6-D6)/D6)*100) -> -15.151515 | K6: =IF(J6="","",IF(J6>10,1,IF(J6<5,3,2))) -> 3 | L6: =IF(ISERROR(((G6-F6)/F6)*100),0,((G6-F6)/F6)*100) -> 22.222222 | M6: =IF(L6="","",IF(L6>15,1,IF(L6<5,3,2))) -> 1 | N6: =IF(ISERROR(((I6-H6)/H6)*100),0,((I6-H6)/H6)*100) -> 1.5596663 | O6: =IF(N6="","",IF(N6>15,1,IF(N6<5,3,2))) -> 3 | P6: =IF(ISERROR(K6+M6+O6),"",K6+M6+O6) -> 7 | Q6: =IF(P6="","",IF(P6<=5,"RENTAN",IF(P6>7,"AMAN","WASPADA"))) -> WASPADA | R6: =IF(Q6="","",IF(Q6="AMAN","3",IF(Q6="RENTAN","1","2"))) -> 2
C7: Cilegon | D7: 16500 | E7: 14000 | F7: 18000 | G7: 22000 | H7: 27570 | I7: 28000 | J7: =IF(ISERROR(((E7-D7)/D7)*100),0,((E7-D7)/D7)*100) -> -15.151515 | K7: =IF(J7="","",IF(J7>10,1,IF(J7<5,3,2))) -> 3 | L7: =IF(ISERROR(((G7-F7)/F7)*100),0,((G7-F7)/F7)*100) -> 22.222222 | M7: =IF(L7="","",IF(L7>15,1,IF(L7<5,3,2))) -> 1 | N7: =IF(ISERROR(((I7-H7)/H7)*100),0,((I7-H7)/H7)*100) -> 1.5596663 | O7: =IF(N7="","",IF(N7>15,1,IF(N7<5,3,2))) -> 3 | P7: =IF(ISERROR(K7+M7+O7),"",K7+M7+O7) -> 7 | Q7: =IF(P7="","",IF(P7<=5,"RENTAN",IF(P7>7,"AMAN","WASPADA"))) -> WASPADA | R7: =IF(Q7="","",IF(Q7="AMAN","3",IF(Q7="RENTAN","1","2"))) -> 2
C8: Pulomerak | D8: 15000 | E8: 14000 | F8: 17000 | G8: 21000 | H8: 29210 | I8: 28400 | J8: =IF(ISERROR(((E8-D8)/D8)*100),0,((E8-D8)/D8)*100) -> -6.6666667 | K8: =IF(J8="","",IF(J8>10,1,IF(J8<5,3,2))) -> 3 | L8: =IF(ISERROR(((G8-F8)/F8)*100),0,((G8-F8)/F8)*100) -> 23.529412 | M8: =IF(L8="","",IF(L8>15,1,IF(L8<5,3,2))) -> 1 | N8: =IF(ISERROR(((I8-H8)/H8)*100),0,((I8-H8)/H8)*100) -> -2.7730229 | O8: =IF(N8="","",IF(N8>15,1,IF(N8<5,3,2))) -> 3 | P8: =IF(ISERROR(K8+M8+O8),"",K8+M8+O8) -> 7 | Q8: =IF(P8="","",IF(P8<=5,"RENTAN",IF(P8>7,"AMAN","WASPADA"))) -> WASPADA | R8: =IF(Q8="","",IF(Q8="AMAN","3",IF(Q8="RENTAN","1","2"))) -> 2
C9: Ciwandan | D9: 14730 | E9: 13500 | F9: 17000 | G9: 21300 | H9: 28000 | I9: 28000 | J9: =IF(ISERROR(((E9-D9)/D9)*100),0,((E9-D9)/D9)*100) -> -8.3503055 | K9: =IF(J9="","",IF(J9>10,1,IF(J9<5,3,2))) -> 3 | L9: =IF(ISERROR(((G9-F9)/F9)*100),0,((G9-F9)/F9)*100) -> 25.294118 | M9: =IF(L9="","",IF(L9>15,1,IF(L9<5,3,2))) -> 1 | N9: =IF(ISERROR(((I9-H9)/H9)*100),0,((I9-H9)/H9)*100) -> 0 | O9: =IF(N9="","",IF(N9>15,1,IF(N9<5,3,2))) -> 3 | P9: =IF(ISERROR(K9+M9+O9),"",K9+M9+O9) -> 7 | Q9: =IF(P9="","",IF(P9<=5,"RENTAN",IF(P9>7,"AMAN","WASPADA"))) -> WASPADA | R9: =IF(Q9="","",IF(Q9="AMAN","3",IF(Q9="RENTAN","1","2"))) -> 2
C10: Jombang | D10: 14730 | E10: 13500 | F10: 17000 | G10: 21300 | H10: 28000 | I10: 28000 | J10: =IF(ISERROR(((E10-D10)/D10)*100),0,((E10-D10)/D10)*100) -> -8.3503055 | K10: =IF(J10="","",IF(J10>10,1,IF(J10<5,3,2))) -> 3 | L10: =IF(ISERROR(((G10-F10)/F10)*100),0,((G10-F10)/F10)*100) -> 25.294118 | M10: =IF(L10="","",IF(L10>15,1,IF(L10<5,3,2))) -> 1 | N10: =IF(ISERROR(((I10-H10)/H10)*100),0,((I10-H10)/H10)*100) -> 0 | O10: =IF(N10="","",IF(N10>15,1,IF(N10<5,3,2))) -> 3 | P10: =IF(ISERROR(K10+M10+O10),"",K10+M10+O10) -> 7 | Q10: =IF(P10="","",IF(P10<=5,"RENTAN",IF(P10>7,"AMAN","WASPADA"))) -> WASPADA | R10: =IF(Q10="","",IF(Q10="AMAN","3",IF(Q10="RENTAN","1","2"))) -> 2
C11: Gerogol | D11: 15000 | E11: 14000 | F11: 17000 | G11: 21000 | H11: 29210 | I11: 28400 | J11: =IF(ISERROR(((E11-D11)/D11)*100),0,((E11-D11)/D11)*100) -> -6.6666667 | K11: =IF(J11="","",IF(J11>10,1,IF(J11<5,3,2))) -> 3 | L11: =IF(ISERROR(((G11-F11)/F11)*100),0,((G11-F11)/F11)*100) -> 23.529412 | M11: =IF(L11="","",IF(L11>15,1,IF(L11<5,3,2))) -> 1 | N11: =IF(ISERROR(((I11-H11)/H11)*100),0,((I11-H11)/H11)*100) -> -2.7730229 | O11: =IF(N11="","",IF(N11>15,1,IF(N11<5,3,2))) -> 3 | P11: =IF(ISERROR(K11+M11+O11),"",K11+M11+O11) -> 7 | Q11: =IF(P11="","",IF(P11<=5,"RENTAN",IF(P11>7,"AMAN","WASPADA"))) -> WASPADA | R11: =IF(Q11="","",IF(Q11="AMAN","3",IF(Q11="RENTAN","1","2"))) -> 2
C12: Purwakarta | D12: 14730 | E12: 13500 | F12: 17000 | G12: 21000 | H12: 28000 | I12: 28000 | J12: =IF(ISERROR(((E12-D12)/D12)*100),0,((E12-D12)/D12)*100) -> -8.3503055 | K12: =IF(J12="","",IF(J12>10,1,IF(J12<5,3,2))) -> 3 | L12: =IF(ISERROR(((G12-F12)/F12)*100),0,((G12-F12)/F12)*100) -> 23.529412 | M12: =IF(L12="","",IF(L12>15,1,IF(L12<5,3,2))) -> 1 | N12: =IF(ISERROR(((I12-H12)/H12)*100),0,((I12-H12)/H12)*100) -> 0 | O12: =IF(N12="","",IF(N12>15,1,IF(N12<5,3,2))) -> 3 | P12: =IF(ISERROR(K12+M12+O12),"",K12+M12+O12) -> 7 | Q12: =IF(P12="","",IF(P12<=5,"RENTAN",IF(P12>7,"AMAN","WASPADA"))) -> WASPADA | R12: =IF(Q12="","",IF(Q12="AMAN","3",IF(Q12="RENTAN","1","2"))) -> 2
C13: Citangkil | D13: 14730 | E13: 13500 | F13: 17000 | G13: 21300 | H13: 28000 | I13: 28000 | J13: =IF(ISERROR(((E13-D13)/D13)*100),0,((E13-D13)/D13)*100) -> -8.3503055 | K13: =IF(J13="","",IF(J13>10,1,IF(J13<5,3,2))) -> 3 | L13: =IF(ISERROR(((G13-F13)/F13)*100),0,((G13-F13)/F13)*100) -> 25.294118 | M13: =IF(L13="","",IF(L13>15,1,IF(L13<5,3,2))) -> 1 | N13: =IF(ISERROR(((I13-H13)/H13)*100),0,((I13-H13)/H13)*100) -> 0 | O13: =IF(N13="","",IF(N13>15,1,IF(N13<5,3,2))) -> 3 | P13: =IF(ISERROR(K13+M13+O13),"",K13+M13+O13) -> 7 | Q13: =IF(P13="","",IF(P13<=5,"RENTAN",IF(P13>7,"AMAN","WASPADA"))) -> WASPADA | R13: =IF(Q13="","",IF(Q13="AMAN","3",IF(Q13="RENTAN","1","2"))) -> 2
A14: =B3&" "&B6 -> KOTA CILEGON | D14: =AVERAGE(D6:D13) -> 15240 | E14: 14000 | F14: =AVERAGE(F6:F13) -> 17250 | G14: 21300 | H14: =AVERAGE(H6:H13) -> 28195 | I14: 28000 | J14: =IF(ISERROR(((E14-D14)/D14)*100),0,((E14-D14)/D14)*100) -> -8.1364829 | K14: =IF(J14="","",IF(J14>10,1,IF(J14<5,3,2))) -> 3 | L14: =IF(ISERROR(((G14-F14)/F14)*100),0,((G14-F14)/F14)*100) -> 23.478261 | M14: =IF(L14="","",IF(L14>15,1,IF(L14<5,3,2))) -> 1 | N14: =IF(ISERROR(((I14-H14)/H14)*100),0,((I14-H14)/H14)*100) -> -0.69161199 | O14: =IF(N14="","",IF(N14>15,1,IF(N14<5,3,2))) -> 3 | P14: =IF(ISERROR(K14+M14+O14),"",K14+M14+O14) -> 7 | Q14: =IF(P14="","",IF(P14<=5,"RENTAN",IF(P14>7,"AMAN","WASPADA"))) -> WASPADA | R14: =IF(Q14="","",IF(Q14="AMAN","3",IF(Q14="RENTAN","1","2"))) -> 2

Sheet IP
A1: PEMANFAATAN PANGAN
A2: =SUM(IK!E1) -> 45809
A4: NO. | B4: KOTA | C4: KECAMATAN | D4: BB Sangat Kurang | E4: BB Kurang | F4: BB Normal | G4: Risiko BB Lebih | H4: BB Sangat Kurang + BB Kurang | I4: TOTAL BB/U | J4: HASIL
J5: VALUE | K5: BOBOT | L5: STATUS
A6: 1 | B6: CILEGON | C6: Cibeber | D6: 28 | E6: 51 | F6: 3723 | G6: 56 | H6: =D6+E6 -> 79 | I6: =SUM(D6:G6) -> 3858 | J6: =IF(ISERROR((H6/I6)*100),0,((H6/I6)*100)) -> 2.0476931 | K6: =IF(J6="","",IF(J6<10,3,IF(J6>15,1,2))) -> 3 | L6: =IF(K6="","",IF(K6=3,"AMAN",IF(K6=1,"RENTAN","WASPADA"))) -> AMAN
C7: Cilegon | D7: 32 | E7: 187 | F7: 4338 | G7: 219 | H7: =D7+E7 -> 219 | I7: =SUM(D7:G7) -> 4776 | J7: =IF(ISERROR((H7/I7)*100),0,((H7/I7)*100)) -> 4.5854271 | K7: =IF(J7="","",IF(J7<10,3,IF(J7>15,1,2))) -> 3 | L7: =IF(K7="","",IF(K7=3,"AMAN",IF(K7=1,"RENTAN","WASPADA"))) -> AMAN
C8: Pulomerak | D8: 44 | E8: 199 | F8: 2603 | G8: 153 | H8: =D8+E8 -> 243 | I8: =SUM(D8:G8) -> 2999 | J8: =IF(ISERROR((H8/I8)*100),0,((H8/I8)*100)) -> 8.1027009 | K8: =IF(J8="","",IF(J8<10,3,IF(J8>15,1,2))) -> 3 | L8: =IF(K8="","",IF(K8=3,"AMAN",IF(K8=1,"RENTAN","WASPADA"))) -> AMAN
C9: Ciwandan | D9: 31 | E9: 112 | F9: 2463 | G9: 109 | H9: =D9+E9 -> 143 | I9: =SUM(D9:G9) -> 2715 | J9: =IF(ISERROR((H9/I9)*100),0,((H9/I9)*100)) -> 5.267035 | K9: =IF(J9="","",IF(J9<10,3,IF(J9>15,1,2))) -> 3 | L9: =IF(K9="","",IF(K9=3,"AMAN",IF(K9=1,"RENTAN","WASPADA"))) -> AMAN
C10: Jombang | D10: 32 | E10: 165 | F10: 2192 | G10: 213 | H10: =D10+E10 -> 197 | I10: =SUM(D10:G10) -> 2602 | J10: =IF(ISERROR((H10/I10)*100),0,((H10/I10)*100)) -> 7.5710992 | K10: =IF(J10="","",IF(J10<10,3,IF(J10>15,1,2))) -> 3 | L10: =IF(K10="","",IF(K10=3,"AMAN",IF(K10=1,"RENTAN","WASPADA"))) -> AMAN
C11: Gerogol | D11: 30 | E11: 148 | F11: 2897 | G11: 135 | H11: =D11+E11 -> 178 | I11: =SUM(D11:G11) -> 3210 | J11: =IF(ISERROR((H11/I11)*100),0,((H11/I11)*100)) -> 5.5451713 | K11: =IF(J11="","",IF(J11<10,3,IF(J11>15,1,2))) -> 3 | L11: =IF(K11="","",IF(K11=3,"AMAN",IF(K11=1,"RENTAN","WASPADA"))) -> AMAN
C12: Purwakarta | D12: 26 | E12: 122 | F12: 3317 | G12: 148 | H12: =D12+E12 -> 148 | I12: =SUM(D12:G12) -> 3613 | J12: =IF(ISERROR((H12/I12)*100),0,((H12/I12)*100)) -> 4.0963188 | K12: =IF(J12="","",IF(J12<10,3,IF(J12>15,1,2))) -> 3 | L12: =IF(K12="","",IF(K12=3,"AMAN",IF(K12=1,"RENTAN","WASPADA"))) -> AMAN
C13: Citangkil | D13: 64 | E13: 204 | F13: 3036 | G13: 93 | H13: =D13+E13 -> 268 | I13: =SUM(D13:G13) -> 3397 | J13: =IF(ISERROR((H13/I13)*100),0,((H13/I13)*100)) -> 7.8893141 | K13: =IF(J13="","",IF(J13<10,3,IF(J13>15,1,2))) -> 3 | L13: =IF(K13="","",IF(K13=3,"AMAN",IF(K13=1,"RENTAN","WASPADA"))) -> AMAN
A14: =B4&" "&B6 -> KOTA CILEGON | D14: =SUM(D6:D13) -> 287 | E14: =SUM(E6:E13) -> 1188 | F14: =SUM(F6:F13) -> 24569 | G14: =SUM(G6:G13) -> 1126 | H14: =D14+E14 -> 1475 | I14: =SUM(D14:G14) -> 27170 | J14: =IF(ISERROR((H14/I14)*100),0,((H14/I14)*100)) -> 5.4287817 | K14: =IF(J14="","",IF(J14<10,3,IF(J14>15,1,2))) -> 3 | L14: =IF(K14="","",IF(K14=3,"AMAN",IF(K14=1,"RENTAN","WASPADA"))) -> AMAN
D17: Status BB/U Balita | E17: Jumlah balita (orang)
D18: BB Sangat Kurang | E18: =SUM(D14) -> 287 | F18: {=SUM((E18:E19)/I14)*100} -> 5.4287817
D19: BB Kurang | E19: =SUM(E14) -> 1188
D20: BB Normal | E20: =SUM(F14) -> 24569
D21: Risiko BB Lebih | E21: =SUM(G14) -> 1126
E28: =SUM(E18:E19) -> 1475
E31: =SUM(E20/I14) -> 0.90426941
E32: =SUM(E28/I14) -> 0.054287817
E36: =SUM(E21/I14) -> 0.041442768
G75: feb
F77: 32 | G77: 95 | H77: 3817 | I77: 102
F78: 63 | G78: 251 | H78: 5176 | I78: 226
F79: 38 | G79: 149 | H79: 2954 | I79: 136
F80: 14 | G80: 102 | H80: 2213 | I80: 190
F81: 48 | G81: 154 | H81: 2503 | I81: 158
F82: 24 | G82: 102 | H82: 3459 | I82: 164
F83: 28 | G83: 123 | H83: 3470 | I83: 118
F84: 48 | G84: 141 | H84: 4018 | I84: 82

Sheet IKB
A1: INDEKS KOMPOSIT KETAHANAN PANGAN BULANAN
A2: =SUM(IK!E1) -> 45809
A3: NO | B3: KOTA | C3: KECAMATAN | D3: IA | E3: IP | F3: SKOR KOMPOSIT BULANAN | G3: KETERANGAN KOMPOSIT BULANAN | H3: INDEKS KOMPOSIT BULANAN (IKB)
A4: 1 | B4: CILEGON | C4: Cibeber | D4: =IA!R6 -> 2 | E4: =IP!K6 -> 3 | F4: =IF(ISERROR(D4+E4),"",D4+E4) -> 5 | G4: =IF(F4="","",IF(F4<=3,"RENTAN",IF(F4>5,"AMAN","WASPADA"))) -> WASPADA | H4: =IF(G4="","",IF(G4="aman","3",IF(G4="rentan","1","2"))) -> 2
C5: Cilegon | D5: =IA!R7 -> 2 | E5: =IP!K7 -> 3 | F5: =IF(ISERROR(D5+E5),"",D5+E5) -> 5 | G5: =IF(F5="","",IF(F5<=3,"RENTAN",IF(F5>5,"AMAN","WASPADA"))) -> WASPADA | H5: =IF(G5="","",IF(G5="aman","3",IF(G5="rentan","1","2"))) -> 2
C6: Pulomerak | D6: =IA!R8 -> 2 | E6: =IP!K8 -> 3 | F6: =IF(ISERROR(D6+E6),"",D6+E6) -> 5 | G6: =IF(F6="","",IF(F6<=3,"RENTAN",IF(F6>5,"AMAN","WASPADA"))) -> WASPADA | H6: =IF(G6="","",IF(G6="aman","3",IF(G6="rentan","1","2"))) -> 2
C7: Ciwandan | D7: =IA!R9 -> 2 | E7: =IP!K9 -> 3 | F7: =IF(ISERROR(D7+E7),"",D7+E7) -> 5 | G7: =IF(F7="","",IF(F7<=3,"RENTAN",IF(F7>5,"AMAN","WASPADA"))) -> WASPADA | H7: =IF(G7="","",IF(G7="aman","3",IF(G7="rentan","1","2"))) -> 2
C8: Jombang | D8: =IA!R10 -> 2 | E8: =IP!K10 -> 3 | F8: =IF(ISERROR(D8+E8),"",D8+E8) -> 5 | G8: =IF(F8="","",IF(F8<=3,"RENTAN",IF(F8>5,"AMAN","WASPADA"))) -> WASPADA | H8: =IF(G8="","",IF(G8="aman","3",IF(G8="rentan","1","2"))) -> 2
C9: Gerogol | D9: =IA!R11 -> 2 | E9: =IP!K11 -> 3 | F9: =IF(ISERROR(D9+E9),"",D9+E9) -> 5 | G9: =IF(F9="","",IF(F9<=3,"RENTAN",IF(F9>5,"AMAN","WASPADA"))) -> WASPADA | H9: =IF(G9="","",IF(G9="aman","3",IF(G9="rentan","1","2"))) -> 2
C10: Purwakarta | D10: =IA!R12 -> 2 | E10: =IP!K12 -> 3 | F10: =IF(ISERROR(D10+E10),"",D10+E10) -> 5 | G10: =IF(F10="","",IF(F10<=3,"RENTAN",IF(F10>5,"AMAN","WASPADA"))) -> WASPADA | H10: =IF(G10="","",IF(G10="aman","3",IF(G10="rentan","1","2"))) -> 2
C11: Citangkil | D11: =IA!R13 -> 2 | E11: =IP!K13 -> 3 | F11: =IF(ISERROR(D11+E11),"",D11+E11) -> 5 | G11: =IF(F11="","",IF(F11<=3,"RENTAN",IF(F11>5,"AMAN","WASPADA"))) -> WASPADA | H11: =IF(G11="","",IF(G11="aman","3",IF(G11="rentan","1","2"))) -> 2
A12: =B3&" "&B4 -> KOTA CILEGON | D12: =IA!R14 -> 2 | E12: =IP!K14 -> 3 | F12: =IF(ISERROR(D12+E12),"",D12+E12) -> 5 | G12: =IF(F12="","",IF(F12<=3,"RENTAN",IF(F12>5,"AMAN","WASPADA"))) -> WASPADA | H12: =IF(G12="","",IF(G12="aman","3",IF(G12="rentan","1","2"))) -> 2

Sheet grafik akses
C2: GRAFIK AKSES PANGAN, SKPG KOTA CILEGON
C3: =SUM(IA!J2) -> 45809
D26: Bulan berjalan | E26: Bulan berjalan 1 tahun sebelumnya | F26: r=Selisih harga
C27: Beras medium | D27: =SUM(IA!E14) -> 14000 | E27: =SUM(IA!D14) -> 15240 | F27: =SUM(IA!J14) -> -8.1364829
C28: Minyak goreng kemasan | D28: =SUM(IA!G14) -> 21300 | E28: =SUM(IA!F14) -> 17250 | F28: =SUM(IA!L14) -> 23.478261
C29: Telur ayam ras | D29: =SUM(IA!I14) -> 28000 | E29: =SUM(IA!H14) -> 28195 | F29: =SUM(IA!N14) -> -0.69161199
N43: r < 5% | O43: : Aman
N44: r ≤ 5% ≤ 10% | O44: : Waspada
N45: r > 10% | O45: : Rentan

Sheet grafik pemanfaatan
C2: GRAFIK ASPEK PEMANFAATAN PANGAN
C3: =SUM(IK!E1) -> 45809

Sheet Sheet1
B1: 45658
B2: 45689
B3: 45717
B4: 45748
B5: 45778
B6: 45809
B7: 45839
B8: 45870
B9: 45901
B10: 45931
B11: 45962
B12: 45992

Sheet Sheet2
A1: KETERSEDIAAN PANGAN
A2: NO. | B2: PROVINSI | C2: KABUPATEN/KOTA | D2: JULI | G2: AGUSTUS | J2: SEPTEMBER | M2: OKTOBER | P2: NOVEMBER | S2: DESEMBER
D3: % REAL | E3: LUAS | F3: HASIL 100% | G3: % REAL | H3: LUAS | I3: HASIL 100% | J3: % REAL | K3: LUAS | L3: HASIL 100% | M3: % REAL | N3: LUAS | O3: HASIL 100% | P3: % REAL | Q3: LUAS | R3: HASIL 100% | S3: % REAL | T3: LUAS | U3: HASIL 100%
A4: 1 | B4: Aceh | C4: 1101000 Simeulue | E4: =IK!I6 -> 0 | F4: =E4/D4 -> #DIV/0! | I4: =H4/G4 -> #DIV/0! | L4: =K4/J4 -> #DIV/0! | O4: =N4/M4 -> #DIV/0! | R4: =Q4/P4 -> #DIV/0! | U4: =T4/S4 -> #DIV/0!
A5: 2 | B5: Aceh | C5: 1102000 Aceh Singkil | E5: =IK!I7 -> 0 | F5: =E5/D5 -> #DIV/0! | I5: =H5/G5 -> #DIV/0! | L5: =K5/J5 -> #DIV/0! | O5: =N5/M5 -> #DIV/0! | R5: =Q5/P5 -> #DIV/0! | U5: =T5/S5 -> #DIV/0!
A6: 3 | B6: Aceh | C6: 1103000 Aceh Selatan | E6: =IK!I8 -> 0 | F6: =E6/D6 -> #DIV/0! | I6: =H6/G6 -> #DIV/0! | L6: =K6/J6 -> #DIV/0! | O6: =N6/M6 -> #DIV/0! | R6: =Q6/P6 -> #DIV/0! | U6: =T6/S6 -> #DIV/0!
A7: 4 | B7: Aceh | C7: 1104000 Aceh Tenggara | E7: =IK!I9 -> 0 | F7: =E7/D7 -> #DIV/0! | I7: =H7/G7 -> #DIV/0! | L7: =K7/J7 -> #DIV/0! | O7: =N7/M7 -> #DIV/0! | R7: =Q7/P7 -> #DIV/0! | U7: =T7/S7 -> #DIV/0!
A8: 5 | B8: Aceh | C8: 1105000 Aceh Timur | E8: =IK!I10 -> 0 | F8: =E8/D8 -> #DIV/0! | I8: =H8/G8 -> #DIV/0! | L8: =K8/J8 -> #DIV/0! | O8: =N8/M8 -> #DIV/0! | R8: =Q8/P8 -> #DIV/0! | U8: =T8/S8 -> #DIV/0!
A9: 6 | B9: Aceh | C9: 1106000 Aceh Tengah | E9: =IK!I11 -> 0 | F9: =E9/D9 -> #DIV/0! | I9: =H9/G9 -> #DIV/0! | L9: =K9/J9 -> #DIV/0! | O9: =N9/M9 -> #DIV/0! | R9: =Q9/P9 -> #DIV/0! | U9: =T9/S9 -> #DIV/0!
A10: 7 | B10: Aceh | C10: 1107000 Aceh Barat | E10: =IK!I12 -> 0 | F10: =E10/D10 -> #DIV/0! | I10: =H10/G10 -> #DIV/0! | L10: =K10/J10 -> #DIV/0! | O10: =N10/M10 -> #DIV/0! | R10: =Q10/P10 -> #DIV/0! | U10: =T10/S10 -> #DIV/0!
A11: 8 | B11: Aceh | C11: 1108000 Aceh Besar | E11: =IK!I13 -> 0 | F11: =E11/D11 -> #DIV/0! | I11: =H11/G11 -> #DIV/0! | L11: =K11/J11 -> #DIV/0! | O11: =N11/M11 -> #DIV/0! | R11: =Q11/P11 -> #DIV/0! | U11: =T11/S11 -> #DIV/0!
A12: 9 | B12: Aceh | C12: 1109000 Pidie | E12: =IK!I14 -> 0 | F12: =E12/D12 -> #DIV/0! | I12: =H12/G12 -> #DIV/0! | L12: =K12/J12 -> #DIV/0! | O12: =N12/M12 -> #DIV/0! | R12: =Q12/P12 -> #DIV/0! | U12: =T12/S12 -> #DIV/0!
A13: 10 | B13: Aceh | C13: 1110000 Bireuen | E13: =IK!I15 -> 0 | F13: =E13/D13 -> #DIV/0! | I13: =H13/G13 -> #DIV/0! | L13: =K13/J13 -> #DIV/0! | O13: =N13/M13 -> #DIV/0! | R13: =Q13/P13 -> #DIV/0! | U13: =T13/S13 -> #DIV/0!
A14: 11 | B14: Aceh | C14: 1111000 Aceh Utara | E14: =IK!I16 -> 0 | F14: =E14/D14 -> #DIV/0! | I14: =H14/G14 -> #DIV/0! | L14: =K14/J14 -> #DIV/0! | O14: =N14/M14 -> #DIV/0! | R14: =Q14/P14 -> #DIV/0! | U14: =T14/S14 -> #DIV/0!
A15: 12 | B15: Aceh | C15: 1112000 Aceh Barat Daya | E15: =IK!I17 -> 0 | F15: =E15/D15 -> #DIV/0! | I15: =H15/G15 -> #DIV/0! | L15: =K15/J15 -> #DIV/0! | O15: =N15/M15 -> #DIV/0! | R15: =Q15/P15 -> #DIV/0! | U15: =T15/S15 -> #DIV/0!
... A26: 23 | B26: Aceh | C26: 1175000 Subulussalam | E26: =IK!I28 -> 0 | F26: =E26/D26 -> #DIV/0! | I26: =H26/G26 -> #DIV/0! | L26: =K26/J26 -> #DIV/0! | O26: =N26/M26 -> #DIV/0! | R26: =Q26/P26 -> #DIV/0! | U26: =T26/S26 -> #DIV/0!
B27: Aceh | E27: =IK!I29 -> 0 | F27: =E27/D27 -> #DIV/0! | I27: =H27/G27 -> #DIV/0! | L27: =K27/J27 -> #DIV/0! | O27: =N27/M27 -> #DIV/0! | R27: =Q27/P27 -> #DIV/0! | U27: =T27/S27 -> #DIV/0!
A28: 24 | B28: Sumatera Utara | C28: 1201000 Nias | E28: =IK!I30 -> 0 | F28: =E28/D28 -> #DIV/0! | I28: =H28/G28 -> #DIV/0! | L28: =K28/J28 -> #DIV/0! | O28: =N28/M28 -> #DIV/0! | R28: =Q28/P28 -> #DIV/0! | U28: =T28/S28 -> #DIV/0!
A29: 25 | B29: Sumatera Utara | C29: 1202000 Mandailing Natal | E29: =IK!I31 -> 0 | F29: =E29/D29 -> #DIV/0! | I29: =H29/G29 -> #DIV/0! | L29: =K29/J29 -> #DIV/0! | O29: =N29/M29 -> #DIV/0! | R29: =Q29/P29 -> #DIV/0! | U29: =T29/S29 -> #DIV/0!
A30: 26 | B30: Sumatera Utara | C30: 1203000 Tapanuli Selatan | E30: =IK!I32 -> 0 | F30: =E30/D30 -> #DIV/0! | I30: =H30/G30 -> #DIV/0! | L30: =K30/J30 -> #DIV/0! | O30: =N30/M30 -> #DIV/0! | R30: =Q30/P30 -> #DIV/0! | U30: =T30/S30 -> #DIV/0!
A31: 27 | B31: Sumatera Utara | C31: 1204000 Tapanuli Tengah | E31: =IK!I33 -> 0 | F31: =E31/D31 -> #DIV/0! | I31: =H31/G31 -> #DIV/0! | L31: =K31/J31 -> #DIV/0! | O31: =N31/M31 -> #DIV/0! | R31: =Q31/P31 -> #DIV/0! | U31: =T31/S31 -> #DIV/0!
A32: 28 | B32: Sumatera Utara | C32: 1205000 Tapanuli Utara | E32: =IK!I34 -> 0 | F32: =E32/D32 -> #DIV/0! | I32: =H32/G32 -> #DIV/0! | L32: =K32/J32 -> #DIV/0! | O32: =N32/M32 -> #DIV/0! | R32: =Q32/P32 -> #DIV/0! | U32: =T32/S32 -> #DIV/0!
A33: 29 | B33: Sumatera Utara | C33: 1206000 Toba Samosir | E33: =IK!I35 -> 0 | F33: =E33/D33 -> #DIV/0! | I33: =H33/G33 -> #DIV/0! | L33: =K33/J33 -> #DIV/0! | O33: =N33/M33 -> #DIV/0! | R33: =Q33/P33 -> #DIV/0! | U33: =T33/S33 -> #DIV/0!
A34: 30 | B34: Sumatera Utara | C34: 1207000 Labuhan Batu | E34: =IK!I36 -> 0 | F34: =E34/D34 -> #DIV/0! | I34: =H34/G34 -> #DIV/0! | L34: =K34/J34 -> #DIV/0! | O34: =N34/M34 -> #DIV/0! | R34: =Q34/P34 -> #DIV/0! | U34: =T34/S34 -> #DIV/0!
A35: 31 | B35: Sumatera Utara | C35: 1208000 Asahan | E35: =IK!I37 -> 0 | F35: =E35/D35 -> #DIV/0! | I35: =H35/G35 -> #DIV/0! | L35: =K35/J35 -> #DIV/0! | O35: =N35/M35 -> #DIV/0! | R35: =Q35/P35 -> #DIV/0! | U35: =T35/S35 -> #DIV/0!
A36: 32 | B36: Sumatera Utara | C36: 1209000 Simalungun | E36: =IK!I38 -> 0 | F36: =E36/D36 -> #DIV/0! | I36: =H36/G36 -> #DIV/0! | L36: =K36/J36 -> #DIV/0! | O36: =N36/M36 -> #DIV/0! | R36: =Q36/P36 -> #DIV/0! | U36: =T36/S36 -> #DIV/0!
A37: 33 | B37: Sumatera Utara | C37: 1210000 Dairi | E37: =IK!#REF! -> #REF! | F37: =E37/D37 -> #REF! | I37: =H37/G37 -> #DIV/0! | L37: =K37/J37 -> #DIV/0! | O37: =N37/M37 -> #DIV/0! | R37: =Q37/P37 -> #DIV/0! | U37: =T37/S37 -> #DIV/0!
A38: 34 | B38: Sumatera Utara | C38: 1211000 Karo | E38: =IK!#REF! -> #REF! | F38: =E38/D38 -> #REF! | I38: =H38/G38 -> #DIV/0! | L38: =K38/J38 -> #DIV/0! | O38: =N38/M38 -> #DIV/0! | R38: =Q38/P38 -> #DIV/0! | U38: =T38/S38 -> #DIV/0!
A39: 35 | B39: Sumatera Utara | C39: 1212000 Deli Serdang | E39: =IK!#REF! -> #REF! | F39: =E39/D39 -> #REF! | I39: =H39/G39 -> #DIV/0! | L39: =K39/J39 -> #DIV/0! | O39: =N39/M39 -> #DIV/0! | R39: =Q39/P39 -> #DIV/0! | U39: =T39/S39 -> #DIV/0!
A40: 36 | B40: Sumatera Utara | C40: 1213000 Langkat | E40: =IK!#REF! -> #REF! | F40: =E40/D40 -> #REF! | I40: =H40/G40 -> #DIV/0! | L40: =K40/J40 -> #DIV/0! | O40: =N40/M40 -> #DIV/0! | R40: =Q40/P40 -> #DIV/0! | U40: =T40/S40 -> #DIV/0!
A41: 37 | B41: Sumatera Utara | C41: 1214000 Nias Selatan | E41: =IK!#REF! -> #REF! | F41: =E41/D41 -> #REF! | I41: =H41/G41 -> #DIV/0! | L41: =K41/J41 -> #DIV/0! | O41: =N41/M41 -> #DIV/0! | R41: =Q41/P41 -> #DIV/0! | U41: =T41/S41 -> #DIV/0!
A42: 38 | B42: Sumatera Utara | C42: 1215000 Humbang Hasundutan | E42: =IK!#REF! -> #REF! | F42: =E42/D42 -> #REF! | I42: =H42/G42 -> #DIV/0! | L42: =K42/J42 -> #DIV/0! | O42: =N42/M42 -> #DIV/0! | R42: =Q42/P42 -> #DIV/0! | U42: =T42/S42 -> #DIV/0!
A43: 39 | B43: Sumatera Utara | C43: 1216000 Pakpak Bharat | E43: =IK!#REF! -> #REF! | F43: =E43/D43 -> #REF! | I43: =H43/G43 -> #DIV/0! | L43: =K43/J43 -> #DIV/0! | O43: =N43/M43 -> #DIV/0! | R43: =Q43/P43 -> #DIV/0! | U43: =T43/S43 -> #DIV/0!
A44: 40 | B44: Sumatera Utara | C44: 1217000 Samosir | E44: =IK!#REF! -> #REF! | F44: =E44/D44 -> #REF! | I44: =H44/G44 -> #DIV/0! | L44: =K44/J44 -> #DIV/0! | O44: =N44/M44 -> #DIV/0! | R44: =Q44/P44 -> #DIV/0! | U44: =T44/S44 -> #DIV/0!
A45: 41 | B45: Sumatera Utara | C45: 1218000 Serdang Bedagai | E45: =IK!#REF! -> #REF! | F45: =E45/D45 -> #REF! | I45: =H45/G45 -> #DIV/0! | L45: =K45/J45 -> #DIV/0! | O45: =N45/M45 -> #DIV/0! | R45: =Q45/P45 -> #DIV/0! | U45: =T45/S45 -> #DIV/0!
A46: 42 | B46: Sumatera Utara | C46: 1219000 Batu Bara | E46: =IK!#REF! -> #REF! | F46: =E46/D46 -> #REF! | I46: =H46/G46 -> #DIV/0! | L46: =K46/J46 -> #DIV/0! | O46: =N46/M46 -> #DIV/0! | R46: =Q46/P46 -> #DIV/0! | U46: =T46/S46 -> #DIV/0!
A47: 43 | B47: Sumatera Utara | C47: 1220000 Padang Lawas Utara | E47: =IK!#REF! -> #REF! | F47: =E47/D47 -> #REF! | I47: =H47/G47 -> #DIV/0! | L47: =K47/J47 -> #DIV/0! | O47: =N47/M47 -> #DIV/0! | R47: =Q47/P47 -> #DIV/0! | U47: =T47/S47 -> #DIV/0!
A48: 44 | B48: Sumatera Utara | C48: 1221000 Padang Lawas | E48: =IK!#REF! -> #REF! | F48: =E48/D48 -> #REF! | I48: =H48/G48 -> #DIV/0! | L48: =K48/J48 -> #DIV/0! | O48: =N48/M48 -> #DIV/0! | R48: =Q48/P48 -> #DIV/0! | U48: =T48/S48 -> #DIV/0!
... A60: 56 | B60: Sumatera Utara | C60: 1278000 Gunungsitoli | E60: =IK!#REF! -> #REF! | F60: =E60/D60 -> #REF! | I60: =H60/G60 -> #DIV/0! | L60: =K60/J60 -> #DIV/0! | O60: =N60/M60 -> #DIV/0! | R60: =Q60/P60 -> #DIV/0! | U60: =T60/S60 -> #DIV/0!
B61: Sumatera Utara | E61: =IK!#REF! -> #REF! | F61: =E61/D61 -> #REF! | I61: =H61/G61 -> #DIV/0! | L61: =K61/J61 -> #DIV/0! | O61: =N61/M61 -> #DIV/0! | R61: =Q61/P61 -> #DIV/0! | U61: =T61/S61 -> #DIV/0!
...
