Workbook

Sheet input SKDN 2026
B1: Lembar Entri Indikator SKPG (Pemantauan status gizi balita) Kota Cilegon
B2: 2026
B4: JANUARI | D4: BB Sgt Krg | E4: BB Krg | F4: BB Normal | G4: BB Lebih | I4: JAN | J4: =D4 -> BB Sgt Krg | K4: =E4 -> BB Krg | L4: =F4 -> BB Normal | M4: =G4 -> BB Lebih | O4: RATA-RATA KEC | P4: =J4 -> BB Sgt Krg | Q4: =K4 -> BB Krg | R4: =L4 -> BB Normal | S4: =M4 -> BB Lebih
B5: Ciwandan | C5: GUNUNG SUGIH | D5: 2 | E5: 24 | F5: 328 | G5: 10 | I5: Ciwandan | J5: =SUM(D11) -> 58 | K5: =SUM(E11) -> 287 | L5: =SUM(F11) -> 3145 | M5: =SUM(G11) -> 94 | O5: Ciwandan | P5: =AVERAGE(J5+J16+J27+J38+J49+J60+J71+J82+J93+J104+J115+J126) -> 58 | Q5: =AVERAGE(K5+K16+K27+K38+K49+K60+K71+K82+K93+K104+K115+K126) -> 287 | R5: =AVERAGE(L5+L16+L27+L38+L49+L60+L71+L82+L93+L104+L115+L126) -> 3145 | S5: =AVERAGE(M5+M16+M27+M38+M49+M60+M71+M82+M93+M104+M115+M126) -> 94
B6: Ciwandan | C6: KEPUH | D6: 6 | E6: 47 | F6: 549 | G6: 22 | I6: Citangkil | J6: =SUM(D108) -> 38 | K6: =SUM(E108) -> 203 | L6: =SUM(F108) -> 4253 | M6: =SUM(G108) -> 234 | O6: Citangkil | P6: =AVERAGE(J6+J17+J28+J39+J50+J61+J72+J83+J94+J105+J116+J127) -> 38 | Q6: =AVERAGE(K6+K17+K28+K39+K50+K61+K72+K83+K94+K105+K116+K127) -> 203 | R6: =AVERAGE(L6+L17+L28+L39+L50+L61+L72+L83+L94+L105+L116+L127) -> 4253 | S6: =AVERAGE(M6+M17+M28+M39+M50+M61+M72+M83+M94+M105+M116+M127) -> 234
B7: Ciwandan | C7: RANDAKARI | D7: 8 | E7: 21 | F7: 551 | G7: 7 | I7: Pulomerak | J7: =SUM(D213) -> 35 | K7: =SUM(E213) -> 198 | L7: =SUM(F213) -> 2444 | M7: =SUM(G213) -> 150 | O7: Pulomerak | P7: =AVERAGE(J7+J18+J29+J40+J51+J62+J73+J84+J95+J106+J117+J128) -> 35 | Q7: =AVERAGE(K7+K18+K29+K40+K51+K62+K73+K84+K95+K106+K117+K128) -> 198 | R7: =AVERAGE(L7+L18+L29+L40+L51+L62+L73+L84+L95+L106+L117+L128) -> 2444 | S7: =AVERAGE(M7+M18+M29+M40+M51+M62+M73+M84+M95+M106+M117+M128) -> 150
B8: Ciwandan | C8: TEGALRATU | D8: 16 | E8: 85 | F8: 706 | G8: 33 | I8: Purwakarta | J8: =SUM(D311) -> 29 | K8: =SUM(E311) -> 94 | L8: =SUM(F311) -> 1342 | M8: =SUM(G311) -> 91 | O8: Purwakarta | P8: =AVERAGE(J8+J19+J30+J41+J52+J63+J74+J85+J96+J107+J118+J129) -> 29 | Q8: =AVERAGE(K8+K19+K30+K41+K52+K63+K74+K85+K96+K107+K118+K129) -> 94 | R8: =AVERAGE(L8+L19+L30+L41+L52+L63+L74+L85+L96+L107+L118+L129) -> 1342 | S8: =AVERAGE(M8+M19+M30+M41+M52+M63+M74+M85+M96+M107+M118+M129) -> 91
B9: Ciwandan | C9: BANJARNEGARA | D9: 17 | E9: 70 | F9: 553 | G9: 12 | I9: Grogol | J9: =SUM(D405) -> 41 | K9: =SUM(E405) -> 165 | L9: =SUM(F405) -> 1829 | M9: =SUM(G405) -> 100 | O9: Grogol | P9: =AVERAGE(J9+J20+J31+J42+J53+J64+J75+J86+J97+J108+J119+J130) -> 41 | Q9: =AVERAGE(K9+K20+K31+K42+K53+K64+K75+K86+K97+K108+K119+K130) -> 165 | R9: =AVERAGE(L9+L20+L31+L42+L53+L64+L75+L86+L97+L108+L119+L130) -> 1829 | S9: =AVERAGE(M9+M20+M31+M42+M53+M64+M75+M86+M97+M108+M119+M130) -> 100
B10: Ciwandan | C10: KUBANGSARI | D10: 9 | E10: 40 | F10: 458 | G10: 10 | I10: Cilegon | J10: =SUM(D502) -> 27 | K10: =SUM(E502) -> 122 | L10: =SUM(F502) -> 2890 | M10: =SUM(G502) -> 173 | O10: Cilegon | P10: =AVERAGE(J10+J21+J32+J43+J54+J65+J76+J87+J98+J109+J120+J131) -> 27 | Q10: =AVERAGE(K10+K21+K32+K43+K54+K65+K76+K87+K98+K109+K120+K131) -> 122 | R10: =AVERAGE(L10+L21+L32+L43+L54+L65+L76+L87+L98+L109+L120+L131) -> 2890 | S10: =AVERAGE(M10+M21+M32+M43+M54+M65+M76+M87+M98+M109+M120+M131) -> 173
D11: =SUM(D5:D10) -> 58 | E11: =SUM(E5:E10) -> 287 | F11: =SUM(F5:F10) -> 3145 | G11: =SUM(G5:G10) -> 94 | I11: Jombang | J11: =D598 -> 23 | K11: =E598 -> 112 | L11: =F598 -> 3321 | M11: =G598 -> 131 | O11: Jombang | P11: =AVERAGE(J11+J22+J33+J44+J55+J66+J77+J88+J99+J110+J121+J132) -> 23 | Q11: =AVERAGE(K11+K22+K33+K44+K55+K66+K77+K88+K99+K110+K121+K132) -> 112 | R11: =AVERAGE(L11+L22+L33+L44+L55+L66+L77+L88+L99+L110+L121+L132) -> 3321 | S11: =AVERAGE(M11+M22+M33+M44+M55+M66+M77+M88+M99+M110+M121+M132) -> 131
B12: FEBRUARI | D12: BB Sgt Krg | E12: BB Krg | F12: BB Normal | G12: BB Lebih | I12: Cibeber | J12: =SUM(D695) -> 55 | K12: =SUM(E695) -> 212 | L12: =SUM(F695) -> 3469 | M12: =SUM(G695) -> 113 | O12: Cibeber | P12: =AVERAGE(J12+J23+J34+J45+J56+J67+J78+J89+J100+J111+J122+J133) -> 55 | Q12: =AVERAGE(K12+K23+K34+K45+K56+K67+K78+K89+K100+K111+K122+K133) -> 212 | R12: =AVERAGE(L12+L23+L34+L45+L56+L67+L78+L89+L100+L111+L122+L133) -> 3469 | S12: =AVERAGE(M12+M23+M34+M45+M56+M67+M78+M89+M100+M111+M122+M133) -> 113
B13: Ciwandan | C13: GUNUNG SUGIH
B14: Ciwandan | C14: KEPUH
B15: Ciwandan | C15: RANDAKARI | I15: FEB | J15: =J4 -> BB Sgt Krg | K15: =K4 -> BB Krg | L15: =L4 -> BB Normal | M15: =M4 -> BB Lebih | O15: RATA-RATA KEL | P15: =J15 -> BB Sgt Krg | Q15: =K15 -> BB Krg | R15: =L15 -> BB Normal | S15: =M15 -> BB Lebih
B16: Ciwandan | C16: TEGALRATU | I16: Ciwandan | J16: =SUM(D19) -> 0 | K16: =SUM(E19) -> 0 | L16: =SUM(F19) -> 0 | M16: =SUM(G19) -> 0 | O16: GUNUNG SUGIH | P16: =AVERAGE(D5+D13+D21+D29+D37+D45+D53+D61+D69+D77+D85+D93) -> 2 | Q16: =AVERAGE(E5+E13+E21+E29+E37+E45+E53+E61+E69+E77+E85+E93) -> 24 | R16: =AVERAGE(F5+F13+F21+F29+F37+F45+F53+F61+F69+F77+F85+F93) -> 328 | S16: =AVERAGE(G5+G13+G21+G29+G37+G45+G53+G61+G69+G77+G85+G93) -> 10
B17: Ciwandan | C17: BANJARNEGARA | I17: Citangkil | J17: =SUM(D117) -> 0 | K17: =SUM(E117) -> 0 | L17: =SUM(F117) -> 0 | M17: =SUM(G117) -> 0 | O17: KEPUH | P17: =AVERAGE(D6+D14+D22+D30+D38+D46+D54+D62+D70+D78+D86+D94) -> 6 | Q17: =AVERAGE(E6+E14+E22+E30+E38+E46+E54+E62+E70+E78+E86+E94) -> 47 | R17: =AVERAGE(F6+F14+F22+F30+F38+F46+F54+F62+F70+F78+F86+F94) -> 549 | S17: =AVERAGE(G6+G14+G22+G30+G38+G46+G54+G62+G70+G78+G86+G94) -> 22
B18: Ciwandan | C18: KUBANGSARI | I18: Pulomerak | J18: =SUM(D221) -> 0 | K18: =SUM(E221) -> 0 | L18: =SUM(F221) -> 0 | M18: =SUM(G221) -> 0 | O18: RANDAKARI | P18: =AVERAGE(D7+D15+D23+D31+D39+D47+D55+D63+D71+D79+D87+D95) -> 8 | Q18: =AVERAGE(E7+E15+E23+E31+E39+E47+E55+E63+E71+E79+E87+E95) -> 21 | R18: =AVERAGE(F7+F15+F23+F31+F39+F47+F55+F63+F71+F79+F87+F95) -> 551 | S18: =AVERAGE(G7+G15+G23+G31+G39+G47+G55+G63+G71+G79+G87+G95) -> 7
D19: =SUM(D13:D18) -> 0 | E19: =SUM(E13:E18) -> 0 | F19: =SUM(F13:F18) -> 0 | G19: =SUM(G13:G18) -> 0 | I19: Purwakarta | J19: =SUM(D319) -> 0 | K19: =SUM(E319) -> 0 | L19: =SUM(F319) -> 0 | M19: =SUM(G319) -> 0 | O19: TEGALRATU | P19: =AVERAGE(D8+D16+D24+D32+D40+D48+D56+D64+D72+D80+D88+D96) -> 16 | Q19: =AVERAGE(E8+E16+E24+E32+E40+E48+E56+E64+E72+E80+E88+E96) -> 85 | R19: =AVERAGE(F8+F16+F24+F32+F40+F48+F56+F64+F72+F80+F88+F96) -> 706 | S19: =AVERAGE(G8+G16+G24+G32+G40+G48+G56+G64+G72+G80+G88+G96) -> 33
B20: MARET | D20: BB Sgt Krg | E20: BB Krg | F20: BB Normal | G20: BB Lebih | I20: Grogol | J20: =SUM(D413) -> 0 | K20: =SUM(E413) -> 0 | L20: 0 | M20: =SUM(G413) -> 0 | O20: BANJARNEGARA | P20: =AVERAGE(D9+D17+D25+D33+D41+D49+D57+D65+D73+D81+D89+D97) -> 17 | Q20: =AVERAGE(E9+E17+E25+E33+E41+E49+E57+E65+E73+E81+E89+E97) -> 70 | R20: =AVERAGE(F9+F17+F25+F33+F41+F49+F57+F65+F73+F81+F89+F97) -> 553 | S20: =AVERAGE(G9+G17+G25+G33+G41+G49+G57+G65+G73+G81+G89+G97) -> 12
B21: Ciwandan | C21: GUNUNG SUGIH | I21: Cilegon | J21: =SUM(D510) -> 0 | K21: =SUM(E510) -> 0 | L21: =SUM(F510) -> 0 | M21: =SUM(G510) -> 0 | O21: KUBANGSARI | P21: =AVERAGE(D10+D18+D26+D34+D42+D50+D58+D66+D74+D82+D90+D98) -> 9 | Q21: =AVERAGE(E10+E18+E26+E34+E42+E50+E58+E66+E74+E82+E90+E98) -> 40 | R21: =AVERAGE(F10+F18+F26+F34+F42+F50+F58+F66+F74+F82+F90+F98) -> 458 | S21: =AVERAGE(G10+G18+G26+G34+G42+G50+G58+G66+G74+G82+G90+G98) -> 10
B22: Ciwandan | C22: KEPUH | I22: Jombang | J22: =SUM(D606) -> 0 | K22: =SUM(E606) -> 0 | L22: =SUM(F606) -> 0 | M22: =SUM(G606) -> 0 | O22: TAMANBARU | P22: =AVERAGE(D101+D110+D119+D128+D137+D146+D155+D164+D173+D182+D191+D200) -> 7 | Q22: =AVERAGE(E101+E110+E119+E128+E137+E146+E155+E164+E173+E182+E191+E200) -> 31 | R22: =AVERAGE(F101+F110+F119+F128+F137+F146+F155+F164+F173+F182+F191+F200) -> 596 | S22: =AVERAGE(G101+G110+G119+G128+G137+G146+G155+G164+G173+G182+G191+G200) -> 29
B23: Ciwandan | C23: RANDAKARI | I23: Cibeber | J23: =SUM(D703) -> 0 | K23: =SUM(E703) -> 0 | L23: =SUM(F703) -> 0 | M23: =SUM(G703) -> 0 | O23: CITANGKIL | P23: =AVERAGE(D102+D111+D120+D129+D138+D147+D156+D165+D174+D183+D192+D201) -> 10 | Q23: =AVERAGE(E102+E111+E120+E129+E138+E147+E156+E165+E174+E183+E192+E201) -> 69 | R23: =AVERAGE(F102+F111+F120+F129+F138+F147+F156+F165+F174+F183+F192+F201) -> 660 | S23: =AVERAGE(G102+G111+G120+G129+G138+G147+G156+G165+G174+G183+G192+G201) -> 45
B24: Ciwandan | C24: TEGALRATU | O24: KEBONSARI | P24: =AVERAGE(D103+D112+D121+D130+D139+D148+D157+D166+D175+D184+D193+D202) -> 4 | Q24: =AVERAGE(E103+E112+E121+E130+E139+E148+E157+E166+E175+E184+E193+E202) -> 19 | R24: =AVERAGE(F103+F112+F121+F130+F139+F148+F157+F166+F175+F184+F193+F202) -> 672 | S24: =AVERAGE(G103+G112+G121+G130+G139+G148+G157+G166+G175+G184+G193+G202) -> 56
B25: Ciwandan | C25: BANJARNEGARA | O25: DERINGO | P25: =AVERAGE(D104+D113+D122+D131+D140+D149+D158+D167+D176+D185+D194+D203) -> 5 | Q25: =AVERAGE(E104+E113+E122+E131+E140+E149+E158+E167+E176+E185+E194+E203) -> 22 | R25: =AVERAGE(F104+F113+F122+F131+F140+F149+F158+F167+F176+F185+F194+F203) -> 847 | S25: =AVERAGE(G104+G113+G122+G131+G140+G149+G158+G167+G176+G185+G194+G203) -> 20
B26: Ciwandan | C26: KUBANGSARI | I26: MAR | J26: =J15 -> BB Sgt Krg | K26: =K15 -> BB Krg | L26: =L15 -> BB Normal | M26: =M15 -> BB Lebih | O26: LEBAKDENOK | P26: =AVERAGE(D105+D114+D123+D132+D141+D150+D159+D168+D177+D186+D195+D204) -> 2 | Q26: =AVERAGE(E105+E114+E123+E132+E141+E150+E159+E168+E177+E186+E195+E204) -> 21 | R26: =AVERAGE(F105+F114+F123+F132+F141+F150+F159+F168+F177+F186+F195+F204) -> 701 | S26: =AVERAGE(G105+G114+G123+G132+G141+G150+G159+G168+G177+G186+G195+G204) -> 23
D27: =SUM(D21:D26) -> 0 | E27: =SUM(E21:E26) -> 0 | F27: =SUM(F21:F26) -> 0 | G27: =SUM(G21:G26) -> 0 | I27: Ciwandan | J27: =SUM(D27) -> 0 | K27: =SUM(E27) -> 0 | L27: =SUM(F27) -> 0 | M27: =SUM(G27) -> 0 | O27: WARNASARI | P27: =AVERAGE(D106+D115+D124+D133+D142+D151+D160+D169+D178+D187+D196+D205) -> 6 | Q27: =AVERAGE(E106+E115+E124+E133+E142+E151+E160+E169+E178+E187+E196+E205) -> 24 | R27: =AVERAGE(F106+F115+F124+F133+F142+F151+F160+F169+F178+F187+F196+F205) -> 506 | S27: =AVERAGE(G106+G115+G124+G133+G142+G151+G160+G169+G178+G187+G196+G205) -> 45
B28: APRIL | D28: BB Sgt Krg | E28: BB Krg | F28: BB Normal | G28: BB Lebih | I28: Citangkil | J28: =SUM(D126) -> 0 | K28: =SUM(E126) -> 0 | L28: =SUM(F126) -> 0 | M28: =SUM(G126) -> 0 | O28: SAMANGRAYA | P28: =AVERAGE(D107+D116+D125+D134+D143+D152+D161+D170+D179+D188+D197+D206) -> 4 | Q28: =AVERAGE(E107+E116+E125+E134+E143+E152+E161+E170+E179+E188+E197+E206) -> 17 | R28: =AVERAGE(F107+F116+F125+F134+F143+F152+F161+F170+F179+F188+F197+F206) -> 271 | S28: =AVERAGE(G107+G116+G125+G134+G143+G152+G161+G170+G179+G188+G197+G206) -> 16
B29: Ciwandan | C29: GUNUNG SUGIH | I29: Pulomerak | J29: =SUM(D229) -> 0 | K29: =SUM(E229) -> 0 | L29: =SUM(F229) -> 0 | M29: =SUM(G229) -> 0 | O29: MEKARSARI | P29: =AVERAGE(D209+D217+D225+D233+D241+D249+D257+D265+D273+D281+D289+D297) -> 14 | Q29: =AVERAGE(E209+E217+E225+E233+E241+E249+E257+E265+E273+E281+E289+E297) -> 63 | R29: =AVERAGE(F209+F217+F225+F233+F241+F249+F257+F265+F273+F281+F289+F297) -> 677 | S29: =AVERAGE(G209+G217+G225+G233+G241+G249+G257+G265+G273+G281+G289+G297) -> 37
B30: Ciwandan | C30: KEPUH | I30: Purwakarta | J30: =SUM(D327) -> 0 | K30: =SUM(E327) -> 0 | L30: =SUM(F327) -> 0 | M30: =SUM(G327) -> 0 | O30: TAMANSARI | P30: =AVERAGE(D210+D218+D226+D234+D242+D250+D258+D266+D274+D282+D290+D298) -> 16 | Q30: =AVERAGE(E210+E218+E226+E234+E242+E250+E258+E266+E274+E282+E290+E298) -> 57 | R30: =AVERAGE(F210+F218+F226+F234+F242+F250+F258+F266+F274+F282+F290+F298) -> 668 | S30: =AVERAGE(G210+G218+G226+G234+G242+G250+G258+G266+G274+G282+G290+G298) -> 29
B31: Ciwandan | C31: RANDAKARI | I31: Grogol | J31: =SUM(D421) -> 0 | K31: =SUM(E421) -> 0 | L31: =SUM(F421) -> 0 | M31: =SUM(G421) -> 0 | O31: LEBAK GEDE | P31: =AVERAGE(D211+D219+D227+D235+D243+D251+D259+D267+D275+D283+D291+D299) -> 1 | Q31: =AVERAGE(E211+E219+E227+E235+E243+E251+E259+E267+E275+E283+E291+E299) -> 44 | R31: =AVERAGE(F211+F219+F227+F235+F243+F251+F259+F267+F275+F283+F291+F299) -> 711 | S31: =AVERAGE(G211+G219+G227+G235+G243+G251+G259+G267+G275+G283+G291+G299) -> 15
B32: Ciwandan | C32: TEGALRATU | I32: Cilegon | J32: =SUM(D518) -> 0 | K32: =SUM(E518) -> 0 | L32: =SUM(F518) -> 0 | M32: =SUM(G518) -> 0 | O32: SURALAYA | P32: =AVERAGE(D212+D220+D228+D236+D244+D252+D260+D268+D276+D284+D292+D300) -> 4 | Q32: =AVERAGE(E212+E220+E228+E236+E244+E252+E260+E268+E276+E284+E292+E300) -> 34 | R32: =AVERAGE(F212+F220+F228+F236+F244+F252+F260+F268+F276+F284+F292+F300) -> 388 | S32: =AVERAGE(G212+G220+G228+G236+G244+G252+G260+G268+G276+G284+G292+G300) -> 69
B33: Ciwandan | C33: BANJARNEGARA | I33: Jombang | J33: =SUM(D614) -> 0 | K33: =SUM(E614) -> 0 | L33: =SUM(F614) -> 0 | M33: =SUM(G614) -> 0 | O33: PABEAN | P33: =AVERAGE(D305+D313+D321+D329+D337+D345+D353+D361+D369+D377+D385+D393) -> 1 | Q33: =AVERAGE(E305+E313+E321+E329+E337+E345+E353+E361+E369+E377+E385+E393) -> 9 | R33: =AVERAGE(F305+F313+F321+F329+F337+F345+F353+F361+F369+F377+F385+F393) -> 121 | S33: =AVERAGE(G305+G313+G321+G329+G337+G345+G353+G361+G369+G377+G385+G393) -> 14
B34: Ciwandan | C34: KUBANGSARI | I34: Cibeber | J34: =SUM(D711) -> 0 | K34: =SUM(E711) -> 0 | L34: =SUM(F711) -> 0 | M34: =SUM(G711) -> 0 | O34: TEGAL BUNDER | P34: =AVERAGE(D306+D314+D322+D330+D338+D346+D354+D362+D370+D378+D386+D394) -> 9 | Q34: =AVERAGE(E306+E314+E322+E330+E338+E346+E354+E362+E370+E378+E386+E394) -> 26 | R34: =AVERAGE(F306+F314+F322+F330+F338+F346+F354+F362+F370+F378+F386+F394) -> 170 | S34: =AVERAGE(G306+G314+G322+G330+G338+G346+G354+G362+G370+G378+G386+G394) -> 9
D35: =SUM(D29:D34) -> 0 | E35: =SUM(E29:E34) -> 0 | F35: =SUM(F29:F34) -> 0 | G35: =SUM(G29:G34) -> 0 | O35: PURWAKARTA | P35: =AVERAGE(D307+D315+D323+D331+D339+D347+D355+D363+D371+D379+D387+D395) -> 8 | Q35: =AVERAGE(E307+E315+E323+E331+E339+E347+E355+E363+E371+E379+E387+E395) -> 9 | R35: =AVERAGE(F307+F315+F323+F331+F339+F347+F355+F363+F371+F379+F387+F395) -> 178 | S35: =AVERAGE(G307+G315+G323+G331+G339+G347+G355+G363+G371+G379+G387+G395) -> 8
B36: MEI | D36: BB Sgt Krg | E36: BB Krg | F36: BB Normal | G36: BB Lebih | O36: KOTABUMI | P36: =AVERAGE(D308+D316+D324+D332+D340+D348+D356+D364+D372+D380+D388+D396) -> 2 | Q36: =AVERAGE(E308+E316+E324+E332+E340+E348+E356+E364+E372+E380+E388+E396) -> 17 | R36: =AVERAGE(F308+F316+F324+F332+F340+F348+F356+F364+F372+F380+F388+F396) -> 285 | S36: =AVERAGE(G308+G316+G324+G332+G340+G348+G356+G364+G372+G380+G388+G396) -> 9
B37: Ciwandan | C37: GUNUNG SUGIH | I37: APR | J37: =J26 -> BB Sgt Krg | K37: =K26 -> BB Krg | L37: =L26 -> BB Normal | M37: =M26 -> BB Lebih | O37: KEBON DALEM | P37: =AVERAGE(D309+D317+D325+D333+D341+D349+D357+D365+D373+D381+D389+D397) -> 7 | Q37: =AVERAGE(E309+E317+E325+E333+E341+E349+E357+E365+E373+E381+E389+E397) -> 30 | R37: =AVERAGE(F309+F317+F325+F333+F341+F349+F357+F365+F373+F381+F389+F397) -> 544 | S37: =AVERAGE(G309+G317+G325+G333+G341+G349+G357+G365+G373+G381+G389+G397) -> 47
B38: Ciwandan | C38: KEPUH | I38: Ciwandan | J38: =SUM(D35) -> 0 | K38: =SUM(E35) -> 0 | L38: =SUM(F35) -> 0 | M38: =SUM(G35) -> 0 | O38: RAMANUJU | P38: =AVERAGE(D310+D318+D326+D334+D342+D350+D358+D366+D374+D382+D390+D398) -> 2 | Q38: =AVERAGE(E310+E318+E326+E334+E342+E350+E358+E366+E374+E382+E390+E398) -> 3 | R38: =AVERAGE(F310+F318+F326+F334+F342+F350+F358+F366+F374+F382+F390+F398) -> 44 | S38: =AVERAGE(G310+G318+G326+G334+G342+G350+G358+G366+G374+G382+G390+G398) -> 4
B39: Ciwandan | C39: RANDAKARI | I39: Citangkil | J39: =SUM(D135) -> 0 | K39: =SUM(E135) -> 0 | L39: =SUM(F135) -> 0 | M39: =SUM(G135) -> 0 | O39: KOTASARI | P39: =AVERAGE(D401+D409+D417+D425+D433+D441+D449+D457+D465+D473+D481+D489) -> 6 | Q39: =AVERAGE(E401+E409+E417+E425+E433+E441+E449+E457+E465+E473+E481+E489) -> 25 | R39: =AVERAGE(F401+F409+F417+F425+F433+F441+F449+F457+F465+F473+F481+F489) -> 390 | S39: =AVERAGE(G401+G409+G417+G425+G433+G441+G449+G457+G465+G473+G481+G489) -> 31
B40: Ciwandan | C40: TEGALRATU | I40: Pulomerak | J40: =SUM(D237) -> 0 | K40: =SUM(E237) -> 0 | L40: =SUM(F237) -> 0 | M40: =SUM(G237) -> 0 | O40: GROGOL | P40: =AVERAGE(D402+D410+D418+D426+D434+D442+D450+D458+D466+D474+D482+D490) -> 11 | Q40: =AVERAGE(E402+E410+E418+E426+E434+E442+E450+E458+E466+E474+E482+E490) -> 46 | R40: =AVERAGE(F402+F410+F418+F426+F434+F442+F450+F458+F466+F474+F482+F490) -> 244 | S40: =AVERAGE(G402+G410+G418+G426+G434+G442+G450+G458+G466+G474+G482+G490) -> 12
B41: Ciwandan | C41: BANJARNEGARA | I41: Purwakarta | J41: =SUM(D335) -> 0 | K41: =SUM(E335) -> 0 | L41: =SUM(F335) -> 0 | M41: =SUM(G335) -> 0 | O41: RAWA ARUM | P41: =AVERAGE(D403+D411+D419+D427+D435+D443+D451+D459+D467+D475+D483+D491) -> 10 | Q41: =AVERAGE(E403+E411+E419+E427+E435+E443+E451+E459+E467+E475+E483+E491) -> 30 | R41: =AVERAGE(F403+F411+F419+F427+F435+F443+F451+F459+F467+F475+F483+F491) -> 466 | S41: =AVERAGE(G403+G411+G419+G427+G435+G443+G451+G459+G467+G475+G483+G491) -> 26
...

Sheet sinkronize
A1: BPS | C1: WEB
A2: 8 | C2: 1 | D2: Cibeber | E2: 55 | F2: 212 | G2: 3469 | H2: 113
A3: 6 | C3: 2 | D3: Cilegon | E3: 27 | F3: 122 | G3: 2890 | H3: 173
A4: 3 | C4: 3 | D4: Pulomerak | E4: 35 | F4: 198 | G4: 2444 | H4: 150
A5: 1 | C5: 4 | D5: Ciwandan | E5: 58 | F5: 287 | G5: 3145 | H5: 94
A6: 7 | C6: 5 | D6: Jombang | E6: 23 | F6: 112 | G6: 3321 | H6: 131
A7: 5 | C7: 6 | D7: Grogol | E7: 41 | F7: 165 | G7: 1829 | H7: 100
A8: 4 | C8: 7 | D8: Purwakarta | E8: 29 | F8: 94 | G8: 1342 | H8: 91
A9: 2 | C9: 8 | D9: Citangkil | E9: 38 | F9: 203 | G9: 4253 | H9: 234

Sheet bobot komposit
A1: SKPG (Sistem Kewaspadaan Pangan dan Gizi)
A2: Kota Cilegon 2025
A4: Balita BB Sangat Kurang | G4: Balita BB Kurang | M4: Balita BB Normal | R4: Balita BB Resiko Berlebih | Y4: Komposit
A5: NO | B5: KECAMATAN | C5: KELURAHAN | D5: RATA-RATA | E5: Bobot | G5: NO | H5: KECAMATAN | I5: KELURAHAN | J5: RATA-RATA | K5: Bobot | M5: NO | N5: KECAMATAN | O5: KELURAHAN | P5: RATA-RATA | Q5: Bobot | R5: NO | S5: KECAMATAN | T5: KELURAHAN | U5: RATA-RATA
A6: 1 | B6: Ciwandan | C6: GUNUNG SUGIH | D6: ='input SKDN 2026'!P16 -> 2 | E6: =IF(D6>90,"1",IF(D6=90,"2",IF(D6>=80,"2",IF(D6<80,"3")))) -> 3 | G6: 1 | H6: Ciwandan | I6: GUNUNG SUGIH | J6: ='input SKDN 2026'!Q16 -> 24 | K6: =IF(J6>10,"3",IF(J6=10,"2",IF(J6=5,"2",IF(J6>5,"2",IF(J6<5,"1"))))) -> 3 | M6: 1 | N6: Ciwandan | O6: GUNUNG SUGIH | P6: ='input SKDN 2026'!R16 -> 328 | Q6: =IF(P6<10,"1",IF(P6=10,"2",IF(P6=20,"2",IF(P6>10,"2",IF(P6>20,"3"))))) -> 2 | R6: 1 | S6: Ciwandan | T6: GUNUNG SUGIH | U6: ='input SKDN 2026'!S16 -> 10 | Y6: =SUM(E6+K6+Q6) -> 8
A7: 2 | B7: Ciwandan | C7: KEPUH | D7: ='input SKDN 2026'!P17 -> 6 | E7: =IF(D7>90,"1",IF(D7=90,"2",IF(D7>=80,"2",IF(D7<80,"3")))) -> 3 | G7: 2 | H7: Ciwandan | I7: KEPUH | J7: ='input SKDN 2026'!Q17 -> 47 | K7: =IF(J7>10,"3",IF(J7=10,"2",IF(J7=5,"2",IF(J7>5,"2",IF(J7<5,"1"))))) -> 3 | M7: 2 | N7: Ciwandan | O7: KEPUH | P7: ='input SKDN 2026'!R17 -> 549 | Q7: =IF(P7<10,"1",IF(P7=10,"2",IF(P7=20,"2",IF(P7>10,"2",IF(P7>20,"3"))))) -> 2 | R7: 2 | S7: Ciwandan | T7: KEPUH | U7: ='input SKDN 2026'!S17 -> 22 | Y7: =SUM(E7+K7+Q7) -> 8
A8: 3 | B8: Ciwandan | C8: RANDAKARI | D8: ='input SKDN 2026'!P18 -> 8 | E8: =IF(D8>90,"1",IF(D8=90,"2",IF(D8>=80,"2",IF(D8<80,"3")))) -> 3 | G8: 3 | H8: Ciwandan | I8: RANDAKARI | J8: ='input SKDN 2026'!Q18 -> 21 | K8: =IF(J8>10,"3",IF(J8=10,"2",IF(J8=5,"2",IF(J8>5,"2",IF(J8<5,"1"))))) -> 3 | M8: 3 | N8: Ciwandan | O8: RANDAKARI | P8: ='input SKDN 2026'!R18 -> 551 | Q8: =IF(P8<10,"1",IF(P8=10,"2",IF(P8=20,"2",IF(P8>10,"2",IF(P8>20,"3"))))) -> 2 | R8: 3 | S8: Ciwandan | T8: RANDAKARI | U8: ='input SKDN 2026'!S18 -> 7 | Y8: =SUM(E8+K8+Q8) -> 8
A9: 4 | B9: Ciwandan | C9: TEGALRATU | D9: ='input SKDN 2026'!P19 -> 16 | E9: =IF(D9>90,"1",IF(D9=90,"2",IF(D9>=80,"2",IF(D9<80,"3")))) -> 3 | G9: 4 | H9: Ciwandan | I9: TEGALRATU | J9: ='input SKDN 2026'!Q19 -> 85 | K9: =IF(J9>10,"3",IF(J9=10,"2",IF(J9=5,"2",IF(J9>5,"2",IF(J9<5,"1"))))) -> 3 | M9: 4 | N9: Ciwandan | O9: TEGALRATU | P9: ='input SKDN 2026'!R19 -> 706 | Q9: =IF(P9<10,"1",IF(P9=10,"2",IF(P9=20,"2",IF(P9>10,"2",IF(P9>20,"3"))))) -> 2 | R9: 4 | S9: Ciwandan | T9: TEGALRATU | U9: ='input SKDN 2026'!S19 -> 33 | Y9: =SUM(E9+K9+Q9) -> 8
A10: 5 | B10: Ciwandan | C10: BANJARNEGARA | D10: ='input SKDN 2026'!P20 -> 17 | E10: =IF(D10>90,"1",IF(D10=90,"2",IF(D10>=80,"2",IF(D10<80,"3")))) -> 3 | G10: 5 | H10: Ciwandan | I10: BANJARNEGARA | J10: ='input SKDN 2026'!Q20 -> 70 | K10: =IF(J10>10,"3",IF(J10=10,"2",IF(J10=5,"2",IF(J10>5,"2",IF(J10<5,"1"))))) -> 3 | M10: 5 | N10: Ciwandan | O10: BANJARNEGARA | P10: ='input SKDN 2026'!R20 -> 553 | Q10: =IF(P10<10,"1",IF(P10=10,"2",IF(P10=20,"2",IF(P10>10,"2",IF(P10>20,"3"))))) -> 2 | R10: 5 | S10: Ciwandan | T10: BANJARNEGARA | U10: ='input SKDN 2026'!S20 -> 12 | Y10: =SUM(E10+K10+Q10) -> 8
A11: 6 | B11: Ciwandan | C11: KUBANGSARI | D11: ='input SKDN 2026'!P21 -> 9 | E11: =IF(D11>90,"1",IF(D11=90,"2",IF(D11>=80,"2",IF(D11<80,"3")))) -> 3 | G11: 6 | H11: Ciwandan | I11: KUBANGSARI | J11: ='input SKDN 2026'!Q21 -> 40 | K11: =IF(J11>10,"3",IF(J11=10,"2",IF(J11=5,"2",IF(J11>5,"2",IF(J11<5,"1"))))) -> 3 | M11: 6 | N11: Ciwandan | O11: KUBANGSARI | P11: ='input SKDN 2026'!R21 -> 458 | Q11: =IF(P11<10,"1",IF(P11=10,"2",IF(P11=20,"2",IF(P11>10,"2",IF(P11>20,"3"))))) -> 2 | R11: 6 | S11: Ciwandan | T11: KUBANGSARI | U11: ='input SKDN 2026'!S21 -> 10 | Y11: =SUM(E11+K11+Q11) -> 8
A12: 7 | B12: Citangkil | C12: SAMANGRAYA | D12: ='input SKDN 2026'!P22 -> 7 | E12: =IF(D12>90,"1",IF(D12=90,"2",IF(D12>=80,"2",IF(D12<80,"3")))) -> 3 | G12: 7 | H12: Citangkil | I12: SAMANGRAYA | J12: ='input SKDN 2026'!Q22 -> 31 | K12: =IF(J12>10,"3",IF(J12=10,"2",IF(J12=5,"2",IF(J12>5,"2",IF(J12<5,"1"))))) -> 3 | M12: 7 | N12: Citangkil | O12: SAMANGRAYA | P12: ='input SKDN 2026'!R22 -> 596 | Q12: =IF(P12<10,"1",IF(P12=10,"2",IF(P12=20,"2",IF(P12>10,"2",IF(P12>20,"3"))))) -> 2 | R12: 7 | S12: Citangkil | T12: SAMANGRAYA | U12: ='input SKDN 2026'!S22 -> 29 | Y12: =SUM(E12+K12+Q12) -> 8
A13: 8 | B13: Citangkil | C13: DERINGO | D13: ='input SKDN 2026'!P23 -> 10 | E13: =IF(D13>90,"1",IF(D13=90,"2",IF(D13>=80,"2",IF(D13<80,"3")))) -> 3 | G13: 8 | H13: Citangkil | I13: DERINGO | J13: ='input SKDN 2026'!Q23 -> 69 | K13: =IF(J13>10,"3",IF(J13=10,"2",IF(J13=5,"2",IF(J13>5,"2",IF(J13<5,"1"))))) -> 3 | M13: 8 | N13: Citangkil | O13: DERINGO | P13: ='input SKDN 2026'!R23 -> 660 | Q13: =IF(P13<10,"1",IF(P13=10,"2",IF(P13=20,"2",IF(P13>10,"2",IF(P13>20,"3"))))) -> 2 | R13: 8 | S13: Citangkil | T13: DERINGO | U13: ='input SKDN 2026'!S23 -> 45 | Y13: =SUM(E13+K13+Q13) -> 8
A14: 9 | B14: Citangkil | C14: WARNASARI | D14: ='input SKDN 2026'!P24 -> 4 | E14: =IF(D14>90,"1",IF(D14=90,"2",IF(D14>=80,"2",IF(D14<80,"3")))) -> 3 | G14: 9 | H14: Citangkil | I14: WARNASARI | J14: ='input SKDN 2026'!Q24 -> 19 | K14: =IF(J14>10,"3",IF(J14=10,"2",IF(J14=5,"2",IF(J14>5,"2",IF(J14<5,"1"))))) -> 3 | M14: 9 | N14: Citangkil | O14: WARNASARI | P14: ='input SKDN 2026'!R24 -> 672 | Q14: =IF(P14<10,"1",IF(P14=10,"2",IF(P14=20,"2",IF(P14>10,"2",IF(P14>20,"3"))))) -> 2 | R14: 9 | S14: Citangkil | T14: WARNASARI | U14: ='input SKDN 2026'!S24 -> 56 | Y14: =SUM(E14+K14+Q14) -> 8
A15: 10 | B15: Citangkil | C15: KEBONSARI | D15: ='input SKDN 2026'!P25 -> 5 | E15: =IF(D15>90,"1",IF(D15=90,"2",IF(D15>=80,"2",IF(D15<80,"3")))) -> 3 | G15: 10 | H15: Citangkil | I15: KEBONSARI | J15: ='input SKDN 2026'!Q25 -> 22 | K15: =IF(J15>10,"3",IF(J15=10,"2",IF(J15=5,"2",IF(J15>5,"2",IF(J15<5,"1"))))) -> 3 | M15: 10 | N15: Citangkil | O15: KEBONSARI | P15: ='input SKDN 2026'!R25 -> 847 | Q15: =IF(P15<10,"1",IF(P15=10,"2",IF(P15=20,"2",IF(P15>10,"2",IF(P15>20,"3"))))) -> 2 | R15: 10 | S15: Citangkil | T15: KEBONSARI | U15: ='input SKDN 2026'!S25 -> 20 | Y15: =SUM(E15+K15+Q15) -> 8
A16: 11 | B16: Citangkil | C16: LEBAKDENOK | D16: ='input SKDN 2026'!P26 -> 2 | E16: =IF(D16>90,"1",IF(D16=90,"2",IF(D16>=80,"2",IF(D16<80,"3")))) -> 3 | G16: 11 | H16: Citangkil | I16: LEBAK DENOK | J16: ='input SKDN 2026'!Q26 -> 21 | K16: =IF(J16>10,"3",IF(J16=10,"2",IF(J16=5,"2",IF(J16>5,"2",IF(J16<5,"1"))))) -> 3 | M16: 11 | N16: Citangkil | O16: LEBAK DENOK | P16: ='input SKDN 2026'!R26 -> 701 | Q16: =IF(P16<10,"1",IF(P16=10,"2",IF(P16=20,"2",IF(P16>10,"2",IF(P16>20,"3"))))) -> 2 | R16: 11 | S16: Citangkil | T16: LEBAK DENOK | U16: ='input SKDN 2026'!S26 -> 23 | Y16: =SUM(E16+K16+Q16) -> 8
A17: 12 | B17: Citangkil | C17: TAMANBARU | D17: ='input SKDN 2026'!P27 -> 6 | E17: =IF(D17>90,"1",IF(D17=90,"2",IF(D17>=80,"2",IF(D17<80,"3")))) -> 3 | G17: 12 | H17: Citangkil | I17: TAMANBARU | J17: ='input SKDN 2026'!Q27 -> 24 | K17: =IF(J17>10,"3",IF(J17=10,"2",IF(J17=5,"2",IF(J17>5,"2",IF(J17<5,"1"))))) -> 3 | M17: 12 | N17: Citangkil | O17: TAMANBARU | P17: ='input SKDN 2026'!R27 -> 506 | Q17: =IF(P17<10,"1",IF(P17=10,"2",IF(P17=20,"2",IF(P17>10,"2",IF(P17>20,"3"))))) -> 2 | R17: 12 | S17: Citangkil | T17: TAMANBARU | U17: ='input SKDN 2026'!S27 -> 45 | Y17: =SUM(E17+K17+Q17) -> 8
... A48: 43 | B48: Cibeber | C48: CIKERAI | D48: ='input SKDN 2026'!P58 -> 9 | E48: =IF(D48>90,"1",IF(D48=90,"2",IF(D48>=80,"2",IF(D48<80,"3")))) -> 3 | G48: 43 | H48: Cibeber | I48: CIKERAI | J48: ='input SKDN 2026'!Q58 -> 31 | K48: =IF(J48>10,"3",IF(J48=10,"2",IF(J48=5,"2",IF(J48>5,"2",IF(J48<5,"1"))))) -> 3 | M48: 43 | N48: Cibeber | O48: CIKERAI | P48: ='input SKDN 2026'!R58 -> 578 | Q48: =IF(P48<10,"1",IF(P48=10,"2",IF(P48=20,"2",IF(P48>10,"2",IF(P48>20,"3"))))) -> 2 | R48: 43 | S48: Cibeber | T48: CIKERAI | U48: ='input SKDN 2026'!S58 -> 18 | Y48: =SUM(E48+K48+Q48) -> 8
