Workbook

Sheet 0.1 Produksi Pangan & Penduduk
A1: VALIDASI DATA PRODUKSI DAN JUMLAH PENDUDUK
A2: Food Security and Vulnerability Atlas Tahun 2025
A3: Kabupaten/Kota: | C3: Cilegon | G3: 1.a. Produksi Padi (ton) | M3: 1.b. Produksi Jagung (ton) | S3: 1.c. Produksi Ubi Kayu (ton) | Y3: 1.d. Produksi Ubi Jalar (ton) | AE3: 1.e. Produksi Sagu (ton) | AK3: 1.f. Produksi Pisang (ton) | AQ3: 1.g. Jumlah Penduduk (Jiwa)
G4: Tahun 2024 | M4: Tahun 2024 | S4: Tahun 2024 | Y4: Tahun 2024 | AE4: Tahun 2024 | AK4: Tahun 2024 | AQ4: Tahun 2024
A5: No. | B5: Nama Kecamatan | C5: Kode Kecamatan | D5: Kode Desa/Kelurahan Kemendagri | E5: Kode Desa/Kelurahan BPS | F5: Nama Desa/Kelurahan | G5: Sumber: Dinas Pertanian | H5: Sumber: BPS | I5: Sumber: Validasi Desa | J5: KESEPAKATAN: Data yang Dipakai di FSVA | K5: Keterangan | M5: Sumber: Dinas Pertanian | N5: Sumber: BPS | O5: Sumber: Validasi Desa | P5: KESEPAKATAN: Data yang Dipakai di FSVA | Q5: Keterangan | S5: Sumber: Dinas Pertanian | T5: Sumber: BPS | U5: Sumber: Validasi Desa | V5: KESEPAKATAN: Data yang Dipakai di FSVA | W5: Keterangan | Y5: Sumber: Dinas Pertanian | Z5: Sumber: BPS | AA5: Sumber: Validasi Desa | AB5: KESEPAKATAN: Data yang Dipakai di FSVA | AC5: Keterangan | AE5: Sumber: Dinas Pertanian | AF5: Sumber: BPS | AG5: Sumber: Validasi Desa | AH5: KESEPAKATAN: Data yang Dipakai di FSVA | AI5: Keterangan | AK5: Sumber: Dinas Pertanian | AL5: Sumber: BPS | AM5: Sumber: Validasi Desa | AN5: KESEPAKATAN: Data yang Dipakai di FSVA | AO5: Keterangan | AQ5: Sumber: Dinas Dukcapil
A6: 1 | B6: CIWANDAN | C6: 3672010 | D6: 36.72.04.1004 | E6: 3672010001 | F6: Gunung Sugih | G6: 205.82 | J6: 205.82 | M6: 0 | P6: 0 | S6: 8.575 | V6: 8.575 | Y6: 0.1 | AB6: 0.1 | AH6: 0 | AN6: 0 | AQ6: 6740
A7: 2 | B7: CIWANDAN | C7: 3672010 | D7: 36.72.04.1005 | E7: 3672010002 | F7: Kepuh | G7: 240.12 | J7: 240.12 | M7: 0.978947 | P7: 0.978947 | S7: 8.575 | V7: 8.575 | Y7: 0 | AB7: 0 | AH7: 0 | AN7: 0 | AQ7: 9326
A8: 3 | B8: CIWANDAN | C8: 3672010 | D8: 36.72.04.1006 | E8: 3672010003 | F8: Randakari | G8: 280.14 | J8: 280.14 | M8: 1.468421 | P8: 1.468421 | S8: 9.8 | V8: 9.8 | Y8: 0 | AB8: 0 | AH8: 0 | AN8: 0 | AQ8: 9845
A9: 4 | B9: CIWANDAN | C9: 3672010 | D9: 36.72.04.1007 | E9: 3672010004 | F9: Tegal Ratu | G9: 514.54 | J9: 514.54 | M9: 0.978947 | P9: 0.978947 | S9: 8.575 | V9: 8.575 | Y9: 0.2 | AB9: 0.2 | AH9: 0 | AN9: 0 | AQ9: 11987
A10: 5 | B10: CIWANDAN | C10: 3672010 | D10: 36.72.04.1001 | E10: 3672010005 | F10: Banjar Negara | G10: 291.58 | J10: 291.58 | M10: 0.978947 | P10: 0.978947 | S10: 6.125 | V10: 6.125 | Y10: 0.1 | AB10: 0.1 | AH10: 0 | AN10: 0 | AQ10: 8475
A11: 6 | B11: CIWANDAN | C11: 3672010 | D11: 36.72.04.1002 | E11: 3672010013 | F11: Kubangsari | G11: 400.2 | J11: 400.2 | M11: 4.894737 | P11: 4.894737 | S11: 7.35 | V11: 7.35 | Y11: 0.1 | AB11: 0.1 | AH11: 0 | AN11: 0 | AQ11: 8233
A12: 7 | B12: CITANGKIL | C12: 3672011 | D12: 36.72.08.1002 | E12: 3672011006 | F12: Deringo | G12: 328.14 | J12: 328.14 | M12: 4.84 | P12: 1.4 | S12: 15 | V12: 15 | Y12: 2.625 | AB12: 2.625 | AH12: 0 | AN12: 0 | AQ12: 10465
A13: 8 | B13: CITANGKIL | C13: 3672011 | D13: 36.72.08.1004 | E13: 3672011007 | F13: Lebak Denok | G13: 293.6 | J13: 293.6 | M13: 1.452 | P13: 1.5 | S13: 15 | V13: 15 | Y13: 1.3125 | AB13: 1.3125 | AH13: 0 | AN13: 0 | AQ13: 13322
A14: 9 | B14: CITANGKIL | C14: 3672011 | D14: 36.72.08.1003 | E14: 3672011008 | F14: Taman Baru | G14: 483.58 | J14: 483.58 | M14: 4.84 | P14: 2.3 | S14: 15 | V14: 15 | Y14: 3.62 | AB14: 3.62 | AH14: 0 | AN14: 0 | AQ14: 9930
A15: 10 | B15: CITANGKIL | C15: 3672011 | D15: 36.72.08.1001 | E15: 3672011009 | F15: Citangkil | G15: 23.03 | J15: 23.03 | M15: 0 | P15: 0.7 | S15: 3 | V15: 3 | Y15: 1.3125 | AB15: 1.3125 | AH15: 0 | AN15: 0 | AQ15: 16751
A16: 11 | B16: CITANGKIL | C16: 3672011 | D16: 36.72.08.1005 | E16: 3672011010 | F16: Kebonsari | G16: 115.14 | J16: 115.14 | M16: 0 | P16: 0.9 | S16: 3 | V16: 3 | Y16: 1.3125 | AB16: 1.3125 | AH16: 0 | AN16: 0 | AQ16: 12218
A17: 12 | B17: CITANGKIL | C17: 3672011 | D17: 36.72.08.1007 | E17: 3672011011 | F17: Warnasari | G17: 0 | J17: 0 | M17: 0 | P17: 3.4 | S17: 1.5 | V17: 1.5 | Y17: 0 | AB17: 0 | AH17: 0 | AN17: 0 | AQ17: 14502
... A37: 32 | B37: CILEGON | C37: 3672030 | D37: 36.72.02.1004 | E37: 3672030005 | F37: Ketileng | G37: 48.5 | J37: 48.5 | M37: 0.4 | P37: 0.4 | S37: 0.7 | V37: 0.7 | Y37: 0.74768772 | AB37: 0.74768772 | AH37: 0 | AN37: 0 | AQ37: 7844
A38: 33 | B38: JOMBANG | C38: 3672031 | D38: 36.72.05.1002 | E38: 3672031001 | F38: Jombang Wetan | G38: 58 | J38: 58 | M38: 0 | P38: 0 | S38: - | V38: - | Y38: 0 | AB38: 0 | AH38: 0 | AN38: 0 | AQ38: 22265
A39: 34 | B39: JOMBANG | C39: 3672031 | D39: 36.72.05.1003 | E39: 3672031002 | F39: Masigit | G39: 94.44 | J39: 94.44 | M39: 3.916667 | P39: 3.916667 | S39: - | V39: - | Y39: 0 | AB39: 0 | AH39: 0 | AN39: 0 | AQ39: 15798
A40: 35 | B40: JOMBANG | C40: 3672031 | D40: 36.72.05.1004 | E40: 3672031003 | F40: Panggung Rawi | G40: 1180.5 | J40: 1180.5 | M40: 9.791667 | P40: 9.791667 | S40: - | V40: - | Y40: 0 | AB40: 0 | AH40: 0 | AN40: 0 | AQ40: 11372
A41: 36 | B41: JOMBANG | C41: 3672031 | D41: 36.72.05.1005 | E41: 3672031004 | F41: Gedong Dalem | G41: 666.98 | J41: 666.98 | M41: 4.895833 | P41: 4.895833 | S41: - | V41: - | Y41: 0 | AB41: 0 | AH41: 0 | AN41: 0 | AQ41: 9038
A42: 37 | B42: JOMBANG | C42: 3672031 | D42: 36.72.05.1001 | E42: 3672031005 | F42: Sukmajaya | G42: 661.08 | J42: 661.08 | M42: 4.895833 | P42: 4.895833 | S42: - | V42: - | Y42: 0 | AB42: 0 | AH42: 0 | AN42: 0 | AQ42: 14573
A43: 38 | B43: CIBEBER | C43: 3672040 | D43: 36.72.01.1003 | E43: 3672040001 | F43: Bulakan | G43: 115.89 | J43: 115.89 | M43: 5.1333 | P43: 5.1333 | S43: 114.9474 | V43: 114.9474 | Y43: 15.75 | AB43: 15.75 | AH43: 0 | AN43: 0 | AQ43: 6541
A44: 39 | B44: CIBEBER | C44: 3672040 | D44: 36.72.01.1004 | E44: 3672040002 | F44: Cikerai | G44: 139.07 | J44: 139.07 | M44: 7.7 | P44: 7.7 | S44: 65.68421 | V44: 65.68421 | Y44: 15.75 | AB44: 15.75 | AH44: 0 | AN44: 0 | AQ44: 4498
A45: 40 | B45: CIBEBER | C45: 3672040 | D45: 36.72.01.1005 | E45: 3672040003 | F45: Kalitimbang | G45: 185.42 | J45: 185.42 | M45: 5.1333 | P45: 5.1333 | S45: 16.42105 | V45: 16.42105 | Y45: 10.5 | AB45: 10.5 | AH45: 0 | AN45: 0 | AQ45: 8694
A46: 41 | B46: CIBEBER | C46: 3672040 | D46: 36.72.01.1006 | E46: 3672040004 | F46: Karang Asem | G46: 237.57 | J46: 237.57 | M46: 5.1333 | P46: 5.1333 | S46: 16.42105 | V46: 16.42105 | Y46: 0 | AB46: 0 | AH46: 0 | AN46: 0 | AQ46: 13460
A47: 42 | B47: CIBEBER | C47: 3672040 | D47: 36.72.01.1001 | E47: 3672040005 | F47: Cibeber | G47: 602.62 | J47: 602.62 | M47: 20.5333 | P47: 20.5333 | S47: 65.68421 | V47: 65.68421 | Y47: 5.25 | AB47: 5.25 | AH47: 0 | AN47: 0 | AQ47: 23331
A48: 43 | B48: CIBEBER | C48: 3672040 | D48: 36.72.01.1002 | E48: 3672040006 | F48: Kedaleman | G48: 579.44 | J48: 579.44 | M48: 10.26667 | P48: 10.26667 | S48: 32.84211 | V48: 32.84211 | Y48: 5.25 | AB48: 5.25 | AH48: 0 | AN48: 0 | AQ48: 10696
C49: =LEFT(D49,8)
C50: =LEFT(D50,8)
C51: =LEFT(D51,8)
C52: =LEFT(D52,8)
C53: =LEFT(D53,8)
C54: =LEFT(D54,8)
C55: =LEFT(D55,8)
C56: =LEFT(D56,8)
C57: =LEFT(D57,8)
C58: =LEFT(D58,8)
C59: =LEFT(D59,8)
...

Sheet 0.2 Konsumsi Energi
A1: VALIDASI DATA KONSUMSI ENERGI
A2: ='0.1 Produksi Pangan & Penduduk'!A2 -> Food Security and Vulnerability Atlas Tahun 2025
A3: ='0.1 Produksi Pangan & Penduduk'!A3 -> Kabupaten/Kota: | C3: =IF('0.1 Produksi Pangan & Penduduk'!C3="","",'0.1 Produksi Pangan & Penduduk'!C3) -> Cilegon | G3: Konsumsi Energi (kkal/kap/hr) | M3: Standar Kebutuhan Energi (kkal/kap/hr) | O3: 2. Rasio Kunsumsi Energi
G4: Tahun 2024 | M4: Tahun 2024 | O4: Tahun 2024
A5: No. | B5: Nama Kecamatan | C5: Kode Kecamatan | D5: Kode Desa/Kelurahan Kemendagri | E5: Kode Desa/Kelurahan BPS | F5: Nama Desa/Kelurahan | G5: Sumber: Badan Pangan Nasional (SAE) | H5: Sumber: BPS | I5: Sumber: Validasi Desa | J5: KESEPAKATAN: Data yang Dipakai di FSVA | K5: Keterangan | M5: Sumber: PMK 28 Tahun 2019 tentang Angka Kecukupan Energi | O5: PERHITUNGAN: Data yang Dipakai di FSVA
A6: =IF('0.1 Produksi Pangan & Penduduk'!A6="","",'0.1 Produksi Pangan & Penduduk'!A6) -> 1 | B6: =IF('0.1 Produksi Pangan & Penduduk'!B6="","",'0.1 Produksi Pangan & Penduduk'!B6) -> CIWANDAN | C6: =IF('0.1 Produksi Pangan & Penduduk'!C6="","",'0.1 Produksi Pangan & Penduduk'!C6) -> 3672010 | D6: =IF('0.1 Produksi Pangan & Penduduk'!D6="","",'0.1 Produksi Pangan & Penduduk'!D6) -> 36.72.04.1004 | E6: =IF('0.1 Produksi Pangan & Penduduk'!E6="","",'0.1 Produksi Pangan & Penduduk'!E6) -> 3672010001 | F6: =IF('0.1 Produksi Pangan & Penduduk'!F6="","",'0.1 Produksi Pangan & Penduduk'!F6) -> Gunung Sugih | G6: 2055.48 | J6: 2055.48 | M6: 2100 | O6: =IF(J6="","",IFERROR((J6/M6)*100,0)) -> 97.88
A7: =IF('0.1 Produksi Pangan & Penduduk'!A7="","",'0.1 Produksi Pangan & Penduduk'!A7) -> 2 | B7: =IF('0.1 Produksi Pangan & Penduduk'!B7="","",'0.1 Produksi Pangan & Penduduk'!B7) -> CIWANDAN | C7: =IF('0.1 Produksi Pangan & Penduduk'!C7="","",'0.1 Produksi Pangan & Penduduk'!C7) -> 3672010 | D7: =IF('0.1 Produksi Pangan & Penduduk'!D7="","",'0.1 Produksi Pangan & Penduduk'!D7) -> 36.72.04.1005 | E7: =IF('0.1 Produksi Pangan & Penduduk'!E7="","",'0.1 Produksi Pangan & Penduduk'!E7) -> 3672010002 | F7: =IF('0.1 Produksi Pangan & Penduduk'!F7="","",'0.1 Produksi Pangan & Penduduk'!F7) -> Kepuh | G7: 2032.8 | J7: 2032.8 | M7: 2100 | O7: =IF(J7="","",IFERROR((J7/M7)*100,0)) -> 96.8
A8: =IF('0.1 Produksi Pangan & Penduduk'!A8="","",'0.1 Produksi Pangan & Penduduk'!A8) -> 3 | B8: =IF('0.1 Produksi Pangan & Penduduk'!B8="","",'0.1 Produksi Pangan & Penduduk'!B8) -> CIWANDAN | C8: =IF('0.1 Produksi Pangan & Penduduk'!C8="","",'0.1 Produksi Pangan & Penduduk'!C8) -> 3672010 | D8: =IF('0.1 Produksi Pangan & Penduduk'!D8="","",'0.1 Produksi Pangan & Penduduk'!D8) -> 36.72.04.1006 | E8: =IF('0.1 Produksi Pangan & Penduduk'!E8="","",'0.1 Produksi Pangan & Penduduk'!E8) -> 3672010003 | F8: =IF('0.1 Produksi Pangan & Penduduk'!F8="","",'0.1 Produksi Pangan & Penduduk'!F8) -> Randakari | G8: 2017.47 | J8: 2017.47 | M8: 2100 | O8: =IF(J8="","",IFERROR((J8/M8)*100,0)) -> 96.07
A9: =IF('0.1 Produksi Pangan & Penduduk'!A9="","",'0.1 Produksi Pangan & Penduduk'!A9) -> 4 | B9: =IF('0.1 Produksi Pangan & Penduduk'!B9="","",'0.1 Produksi Pangan & Penduduk'!B9) -> CIWANDAN | C9: =IF('0.1 Produksi Pangan & Penduduk'!C9="","",'0.1 Produksi Pangan & Penduduk'!C9) -> 3672010 | D9: =IF('0.1 Produksi Pangan & Penduduk'!D9="","",'0.1 Produksi Pangan & Penduduk'!D9) -> 36.72.04.1007 | E9: =IF('0.1 Produksi Pangan & Penduduk'!E9="","",'0.1 Produksi Pangan & Penduduk'!E9) -> 3672010004 | F9: =IF('0.1 Produksi Pangan & Penduduk'!F9="","",'0.1 Produksi Pangan & Penduduk'!F9) -> Tegal Ratu | G9: 2055.27 | J9: 2055.27 | M9: 2100 | O9: =IF(J9="","",IFERROR((J9/M9)*100,0)) -> 97.87
A10: =IF('0.1 Produksi Pangan & Penduduk'!A10="","",'0.1 Produksi Pangan & Penduduk'!A10) -> 5 | B10: =IF('0.1 Produksi Pangan & Penduduk'!B10="","",'0.1 Produksi Pangan & Penduduk'!B10) -> CIWANDAN | C10: =IF('0.1 Produksi Pangan & Penduduk'!C10="","",'0.1 Produksi Pangan & Penduduk'!C10) -> 3672010 | D10: =IF('0.1 Produksi Pangan & Penduduk'!D10="","",'0.1 Produksi Pangan & Penduduk'!D10) -> 36.72.04.1001 | E10: =IF('0.1 Produksi Pangan & Penduduk'!E10="","",'0.1 Produksi Pangan & Penduduk'!E10) -> 3672010005 | F10: =IF('0.1 Produksi Pangan & Penduduk'!F10="","",'0.1 Produksi Pangan & Penduduk'!F10) -> Banjar Negara | G10: 2068.08 | J10: 2068.08 | M10: 2100 | O10: =IF(J10="","",IFERROR((J10/M10)*100,0)) -> 98.48
A11: =IF('0.1 Produksi Pangan & Penduduk'!A11="","",'0.1 Produksi Pangan & Penduduk'!A11) -> 6 | B11: =IF('0.1 Produksi Pangan & Penduduk'!B11="","",'0.1 Produksi Pangan & Penduduk'!B11) -> CIWANDAN | C11: =IF('0.1 Produksi Pangan & Penduduk'!C11="","",'0.1 Produksi Pangan & Penduduk'!C11) -> 3672010 | D11: =IF('0.1 Produksi Pangan & Penduduk'!D11="","",'0.1 Produksi Pangan & Penduduk'!D11) -> 36.72.04.1002 | E11: =IF('0.1 Produksi Pangan & Penduduk'!E11="","",'0.1 Produksi Pangan & Penduduk'!E11) -> 3672010013 | F11: =IF('0.1 Produksi Pangan & Penduduk'!F11="","",'0.1 Produksi Pangan & Penduduk'!F11) -> Kubangsari | G11: 2035.95 | J11: 2035.95 | M11: 2100 | O11: =IF(J11="","",IFERROR((J11/M11)*100,0)) -> 96.95
A12: =IF('0.1 Produksi Pangan & Penduduk'!A12="","",'0.1 Produksi Pangan & Penduduk'!A12) -> 7 | B12: =IF('0.1 Produksi Pangan & Penduduk'!B12="","",'0.1 Produksi Pangan & Penduduk'!B12) -> CITANGKIL | C12: =IF('0.1 Produksi Pangan & Penduduk'!C12="","",'0.1 Produksi Pangan & Penduduk'!C12) -> 3672011 | D12: =IF('0.1 Produksi Pangan & Penduduk'!D12="","",'0.1 Produksi Pangan & Penduduk'!D12) -> 36.72.08.1002 | E12: =IF('0.1 Produksi Pangan & Penduduk'!E12="","",'0.1 Produksi Pangan & Penduduk'!E12) -> 3672011006 | F12: =IF('0.1 Produksi Pangan & Penduduk'!F12="","",'0.1 Produksi Pangan & Penduduk'!F12) -> Deringo | G12: 2034.69 | J12: 2034.69 | M12: 2100 | O12: =IF(J12="","",IFERROR((J12/M12)*100,0)) -> 96.89
A13: =IF('0.1 Produksi Pangan & Penduduk'!A13="","",'0.1 Produksi Pangan & Penduduk'!A13) -> 8 | B13: =IF('0.1 Produksi Pangan & Penduduk'!B13="","",'0.1 Produksi Pangan & Penduduk'!B13) -> CITANGKIL | C13: =IF('0.1 Produksi Pangan & Penduduk'!C13="","",'0.1 Produksi Pangan & Penduduk'!C13) -> 3672011 | D13: =IF('0.1 Produksi Pangan & Penduduk'!D13="","",'0.1 Produksi Pangan & Penduduk'!D13) -> 36.72.08.1004 | E13: =IF('0.1 Produksi Pangan & Penduduk'!E13="","",'0.1 Produksi Pangan & Penduduk'!E13) -> 3672011007 | F13: =IF('0.1 Produksi Pangan & Penduduk'!F13="","",'0.1 Produksi Pangan & Penduduk'!F13) -> Lebak Denok | G13: 2032.17 | J13: 2032.17 | M13: 2100 | O13: =IF(J13="","",IFERROR((J13/M13)*100,0)) -> 96.77
A14: =IF('0.1 Produksi Pangan & Penduduk'!A14="","",'0.1 Produksi Pangan & Penduduk'!A14) -> 9 | B14: =IF('0.1 Produksi Pangan & Penduduk'!B14="","",'0.1 Produksi Pangan & Penduduk'!B14) -> CITANGKIL | C14: =IF('0.1 Produksi Pangan & Penduduk'!C14="","",'0.1 Produksi Pangan & Penduduk'!C14) -> 3672011 | D14: =IF('0.1 Produksi Pangan & Penduduk'!D14="","",'0.1 Produksi Pangan & Penduduk'!D14) -> 36.72.08.1003 | E14: =IF('0.1 Produksi Pangan & Penduduk'!E14="","",'0.1 Produksi Pangan & Penduduk'!E14) -> 3672011008 | F14: =IF('0.1 Produksi Pangan & Penduduk'!F14="","",'0.1 Produksi Pangan & Penduduk'!F14) -> Taman Baru | G14: 2058.63 | J14: 2058.63 | M14: 2100 | O14: =IF(J14="","",IFERROR((J14/M14)*100,0)) -> 98.03
A15: =IF('0.1 Produksi Pangan & Penduduk'!A15="","",'0.1 Produksi Pangan & Penduduk'!A15) -> 10 | B15: =IF('0.1 Produksi Pangan & Penduduk'!B15="","",'0.1 Produksi Pangan & Penduduk'!B15) -> CITANGKIL | C15: =IF('0.1 Produksi Pangan & Penduduk'!C15="","",'0.1 Produksi Pangan & Penduduk'!C15) -> 3672011 | D15: =IF('0.1 Produksi Pangan & Penduduk'!D15="","",'0.1 Produksi Pangan & Penduduk'!D15) -> 36.72.08.1001 | E15: =IF('0.1 Produksi Pangan & Penduduk'!E15="","",'0.1 Produksi Pangan & Penduduk'!E15) -> 3672011009 | F15: =IF('0.1 Produksi Pangan & Penduduk'!F15="","",'0.1 Produksi Pangan & Penduduk'!F15) -> Citangkil | G15: 2049.81 | J15: 2049.81 | M15: 2100 | O15: =IF(J15="","",IFERROR((J15/M15)*100,0)) -> 97.61
A16: =IF('0.1 Produksi Pangan & Penduduk'!A16="","",'0.1 Produksi Pangan & Penduduk'!A16) -> 11 | B16: =IF('0.1 Produksi Pangan & Penduduk'!B16="","",'0.1 Produksi Pangan & Penduduk'!B16) -> CITANGKIL | C16: =IF('0.1 Produksi Pangan & Penduduk'!C16="","",'0.1 Produksi Pangan & Penduduk'!C16) -> 3672011 | D16: =IF('0.1 Produksi Pangan & Penduduk'!D16="","",'0.1 Produksi Pangan & Penduduk'!D16) -> 36.72.08.1005 | E16: =IF('0.1 Produksi Pangan & Penduduk'!E16="","",'0.1 Produksi Pangan & Penduduk'!E16) -> 3672011010 | F16: =IF('0.1 Produksi Pangan & Penduduk'!F16="","",'0.1 Produksi Pangan & Penduduk'!F16) -> Kebonsari | G16: 2057.58 | J16: 2057.58 | M16: 2100 | O16: =IF(J16="","",IFERROR((J16/M16)*100,0)) -> 97.98
A17: =IF('0.1 Produksi Pangan & Penduduk'!A17="","",'0.1 Produksi Pangan & Penduduk'!A17) -> 12 | B17: =IF('0.1 Produksi Pangan & Penduduk'!B17="","",'0.1 Produksi Pangan & Penduduk'!B17) -> CITANGKIL | C17: =IF('0.1 Produksi Pangan & Penduduk'!C17="","",'0.1 Produksi Pangan & Penduduk'!C17) -> 3672011 | D17: =IF('0.1 Produksi Pangan & Penduduk'!D17="","",'0.1 Produksi Pangan & Penduduk'!D17) -> 36.72.08.1007 | E17: =IF('0.1 Produksi Pangan & Penduduk'!E17="","",'0.1 Produksi Pangan & Penduduk'!E17) -> 3672011011 | F17: =IF('0.1 Produksi Pangan & Penduduk'!F17="","",'0.1 Produksi Pangan & Penduduk'!F17) -> Warnasari | G17: 2005.92 | J17: 2005.92 | M17: 2100 | O17: =IF(J17="","",IFERROR((J17/M17)*100,0)) -> 95.52
... A48: =IF('0.1 Produksi Pangan & Penduduk'!A48="","",'0.1 Produksi Pangan & Penduduk'!A48) -> 43 | B48: =IF('0.1 Produksi Pangan & Penduduk'!B48="","",'0.1 Produksi Pangan & Penduduk'!B48) -> CIBEBER | C48: =IF('0.1 Produksi Pangan & Penduduk'!C48="","",'0.1 Produksi Pangan & Penduduk'!C48) -> 3672040 | D48: =IF('0.1 Produksi Pangan & Penduduk'!D48="","",'0.1 Produksi Pangan & Penduduk'!D48) -> 36.72.01.1002 | E48: =IF('0.1 Produksi Pangan & Penduduk'!E48="","",'0.1 Produksi Pangan & Penduduk'!E48) -> 3672040006 | F48: =IF('0.1 Produksi Pangan & Penduduk'!F48="","",'0.1 Produksi Pangan & Penduduk'!F48) -> Kedaleman | G48: 2023.98 | J48: 2023.98 | M48: 2100 | O48: =IF(J48="","",IFERROR((J48/M48)*100,0)) -> 96.38
A49: =IF('0.1 Produksi Pangan & Penduduk'!A49="","",'0.1 Produksi Pangan & Penduduk'!A49) | B49: =IF('0.1 Produksi Pangan & Penduduk'!B49="","",'0.1 Produksi Pangan & Penduduk'!B49) | C49: =IF('0.1 Produksi Pangan & Penduduk'!C49="","",'0.1 Produksi Pangan & Penduduk'!C49) | D49: =IF('0.1 Produksi Pangan & Penduduk'!D49="","",'0.1 Produksi Pangan & Penduduk'!D49) | E49: =IF('0.1 Produksi Pangan & Penduduk'!E49="","",'0.1 Produksi Pangan & Penduduk'!E49) | F49: =IF('0.1 Produksi Pangan & Penduduk'!F49="","",'0.1 Produksi Pangan & Penduduk'!F49) | M49: 2100 | O49: =IF(J49="","",IFERROR((J49/M49)*100,0))
A50: =IF('0.1 Produksi Pangan & Penduduk'!A50="","",'0.1 Produksi Pangan & Penduduk'!A50) | B50: =IF('0.1 Produksi Pangan & Penduduk'!B50="","",'0.1 Produksi Pangan & Penduduk'!B50) | C50: =IF('0.1 Produksi Pangan & Penduduk'!C50="","",'0.1 Produksi Pangan & Penduduk'!C50) | D50: =IF('0.1 Produksi Pangan & Penduduk'!D50="","",'0.1 Produksi Pangan & Penduduk'!D50) | E50: =IF('0.1 Produksi Pangan & Penduduk'!E50="","",'0.1 Produksi Pangan & Penduduk'!E50) | F50: =IF('0.1 Produksi Pangan & Penduduk'!F50="","",'0.1 Produksi Pangan & Penduduk'!F50) | M50: 2100 | O50: =IF(J50="","",IFERROR((J50/M50)*100,0))
A51: =IF('0.1 Produksi Pangan & Penduduk'!A51="","",'0.1 Produksi Pangan & Penduduk'!A51) | B51: =IF('0.1 Produksi Pangan & Penduduk'!B51="","",'0.1 Produksi Pangan & Penduduk'!B51) | C51: =IF('0.1 Produksi Pangan & Penduduk'!C51="","",'0.1 Produksi Pangan & Penduduk'!C51) | D51: =IF('0.1 Produksi Pangan & Penduduk'!D51="","",'0.1 Produksi Pangan & Penduduk'!D51) | E51: =IF('0.1 Produksi Pangan & Penduduk'!E51="","",'0.1 Produksi Pangan & Penduduk'!E51) | F51: =IF('0.1 Produksi Pangan & Penduduk'!F51="","",'0.1 Produksi Pangan & Penduduk'!F51) | M51: 2100 | O51: =IF(J51="","",IFERROR((J51/M51)*100,0))
A52: =IF('0.1 Produksi Pangan & Penduduk'!A52="","",'0.1 Produksi Pangan & Penduduk'!A52) | B52: =IF('0.1 Produksi Pangan & Penduduk'!B52="","",'0.1 Produksi Pangan & Penduduk'!B52) | C52: =IF('0.1 Produksi Pangan & Penduduk'!C52="","",'0.1 Produksi Pangan & Penduduk'!C52) | D52: =IF('0.1 Produksi Pangan & Penduduk'!D52="","",'0.1 Produksi Pangan & Penduduk'!D52) | E52: =IF('0.1 Produksi Pangan & Penduduk'!E52="","",'0.1 Produksi Pangan & Penduduk'!E52) | F52: =IF('0.1 Produksi Pangan & Penduduk'!F52="","",'0.1 Produksi Pangan & Penduduk'!F52) | M52: 2100 | O52: =IF(J52="","",IFERROR((J52/M52)*100,0))
A53: =IF('0.1 Produksi Pangan & Penduduk'!A53="","",'0.1 Produksi Pangan & Penduduk'!A53) | B53: =IF('0.1 Produksi Pangan & Penduduk'!B53="","",'0.1 Produksi Pangan & Penduduk'!B53) | C53: =IF('0.1 Produksi Pangan & Penduduk'!C53="","",'0.1 Produksi Pangan & Penduduk'!C53) | D53: =IF('0.1 Produksi Pangan & Penduduk'!D53="","",'0.1 Produksi Pangan & Penduduk'!D53) | E53: =IF('0.1 Produksi Pangan & Penduduk'!E53="","",'0.1 Produksi Pangan & Penduduk'!E53) | F53: =IF('0.1 Produksi Pangan & Penduduk'!F53="","",'0.1 Produksi Pangan & Penduduk'!F53) | M53: 2100 | O53: =IF(J53="","",IFERROR((J53/M53)*100,0))
A54: =IF('0.1 Produksi Pangan & Penduduk'!A54="","",'0.1 Produksi Pangan & Penduduk'!A54) | B54: =IF('0.1 Produksi Pangan & Penduduk'!B54="","",'0.1 Produksi Pangan & Penduduk'!B54) | C54: =IF('0.1 Produksi Pangan & Penduduk'!C54="","",'0.1 Produksi Pangan & Penduduk'!C54) | D54: =IF('0.1 Produksi Pangan & Penduduk'!D54="","",'0.1 Produksi Pangan & Penduduk'!D54) | E54: =IF('0.1 Produksi Pangan & Penduduk'!E54="","",'0.1 Produksi Pangan & Penduduk'!E54) | F54: =IF('0.1 Produksi Pangan & Penduduk'!F54="","",'0.1 Produksi Pangan & Penduduk'!F54) | M54: 2100 | O54: =IF(J54="","",IFERROR((J54/M54)*100,0))
A55: =IF('0.1 Produksi Pangan & Penduduk'!A55="","",'0.1 Produksi Pangan & Penduduk'!A55) | B55: =IF('0.1 Produksi Pangan & Penduduk'!B55="","",'0.1 Produksi Pangan & Penduduk'!B55) | C55: =IF('0.1 Produksi Pangan & Penduduk'!C55="","",'0.1 Produksi Pangan & Penduduk'!C55) | D55: =IF('0.1 Produksi Pangan & Penduduk'!D55="","",'0.1 Produksi Pangan & Penduduk'!D55) | E55: =IF('0.1 Produksi Pangan & Penduduk'!E55="","",'0.1 Produksi Pangan & Penduduk'!E55) | F55: =IF('0.1 Produksi Pangan & Penduduk'!F55="","",'0.1 Produksi Pangan & Penduduk'!F55) | M55: 2100 | O55: =IF(J55="","",IFERROR((J55/M55)*100,0))
A56: =IF('0.1 Produksi Pangan & Penduduk'!A56="","",'0.1 Produksi Pangan & Penduduk'!A56) | B56: =IF('0.1 Produksi Pangan & Penduduk'!B56="","",'0.1 Produksi Pangan & Penduduk'!B56) | C56: =IF('0.1 Produksi Pangan & Penduduk'!C56="","",'0.1 Produksi Pangan & Penduduk'!C56) | D56: =IF('0.1 Produksi Pangan & Penduduk'!D56="","",'0.1 Produksi Pangan & Penduduk'!D56) | E56: =IF('0.1 Produksi Pangan & Penduduk'!E56="","",'0.1 Produksi Pangan & Penduduk'!E56) | F56: =IF('0.1 Produksi Pangan & Penduduk'!F56="","",'0.1 Produksi Pangan & Penduduk'!F56) | M56: 2100 | O56: =IF(J56="","",IFERROR((J56/M56)*100,0))
A57: =IF('0.1 Produksi Pangan & Penduduk'!A57="","",'0.1 Produksi Pangan & Penduduk'!A57) | B57: =IF('0.1 Produksi Pangan & Penduduk'!B57="","",'0.1 Produksi Pangan & Penduduk'!B57) | C57: =IF('0.1 Produksi Pangan & Penduduk'!C57="","",'0.1 Produksi Pangan & Penduduk'!C57) | D57: =IF('0.1 Produksi Pangan & Penduduk'!D57="","",'0.1 Produksi Pangan & Penduduk'!D57) | E57: =IF('0.1 Produksi Pangan & Penduduk'!E57="","",'0.1 Produksi Pangan & Penduduk'!E57) | F57: =IF('0.1 Produksi Pangan & Penduduk'!F57="","",'0.1 Produksi Pangan & Penduduk'!F57) | M57: 2100 | O57: =IF(J57="","",IFERROR((J57/M57)*100,0))
A58: =IF('0.1 Produksi Pangan & Penduduk'!A58="","",'0.1 Produksi Pangan & Penduduk'!A58) | B58: =IF('0.1 Produksi Pangan & Penduduk'!B58="","",'0.1 Produksi Pangan & Penduduk'!B58) | C58: =IF('0.1 Produksi Pangan & Penduduk'!C58="","",'0.1 Produksi Pangan & Penduduk'!C58) | D58: =IF('0.1 Produksi Pangan & Penduduk'!D58="","",'0.1 Produksi Pangan & Penduduk'!D58) | E58: =IF('0.1 Produksi Pangan & Penduduk'!E58="","",'0.1 Produksi Pangan & Penduduk'!E58) | F58: =IF('0.1 Produksi Pangan & Penduduk'!F58="","",'0.1 Produksi Pangan & Penduduk'!F58) | M58: 2100 | O58: =IF(J58="","",IFERROR((J58/M58)*100,0))
A59: =IF('0.1 Produksi Pangan & Penduduk'!A59="","",'0.1 Produksi Pangan & Penduduk'!A59) | B59: =IF('0.1 Produksi Pangan & Penduduk'!B59="","",'0.1 Produksi Pangan & Penduduk'!B59) | C59: =IF('0.1 Produksi Pangan & Penduduk'!C59="","",'0.1 Produksi Pangan & Penduduk'!C59) | D59: =IF('0.1 Produksi Pangan & Penduduk'!D59="","",'0.1 Produksi Pangan & Penduduk'!D59) | E59: =IF('0.1 Produksi Pangan & Penduduk'!E59="","",'0.1 Produksi Pangan & Penduduk'!E59) | F59: =IF('0.1 Produksi Pangan & Penduduk'!F59="","",'0.1 Produksi Pangan & Penduduk'!F59) | M59: 2100 | O59: =IF(J59="","",IFERROR((J59/M59)*100,0))
A60: =IF('0.1 Produksi Pangan & Penduduk'!A60="","",'0.1 Produksi Pangan & Penduduk'!A60) | B60: =IF('0.1 Produksi Pangan & Penduduk'!B60="","",'0.1 Produksi Pangan & Penduduk'!B60) | C60: =IF('0.1 Produksi Pangan & Penduduk'!C60="","",'0.1 Produksi Pangan & Penduduk'!C60) | D60: =IF('0.1 Produksi Pangan & Penduduk'!D60="","",'0.1 Produksi Pangan & Penduduk'!D60) | E60: =IF('0.1 Produksi Pangan & Penduduk'!E60="","",'0.1 Produksi Pangan & Penduduk'!E60) | F60: =IF('0.1 Produksi Pangan & Penduduk'!F60="","",'0.1 Produksi Pangan & Penduduk'!F60) | M60: 2100 | O60: =IF(J60="","",IFERROR((J60/M60)*100,0))
... A860: =IF('0.1 Produksi Pangan & Penduduk'!A860="","",'0.1 Produksi Pangan & Penduduk'!A860) | B860: =IF('0.1 Produksi Pangan & Penduduk'!B860="","",'0.1 Produksi Pangan & Penduduk'!B860) | C860: =IF('0.1 Produksi Pangan & Penduduk'!C860="","",'0.1 Produksi Pangan & Penduduk'!C860) | D860: =IF('0.1 Produksi Pangan & Penduduk'!D860="","",'0.1 Produksi Pangan & Penduduk'!D860) | E860: =IF('0.1 Produksi Pangan & Penduduk'!E860="","",'0.1 Produksi Pangan & Penduduk'!E860) | F860: =IF('0.1 Produksi Pangan & Penduduk'!F860="","",'0.1 Produksi Pangan & Penduduk'!F860) | M860: 2100 | O860: =IF(J860="","",IFERROR((J860/M860)*100,0))

Sheet 0.3 Konsumsi Protein Hewani
A1: VALIDASI DATA KONSUMSI PROTEIN
A2: ='0.1 Produksi Pangan & Penduduk'!A2 -> Food Security and Vulnerability Atlas Tahun 2025
A3: ='0.1 Produksi Pangan & Penduduk'!A3 -> Kabupaten/Kota: | C3: =IF('0.1 Produksi Pangan & Penduduk'!C3="","",'0.1 Produksi Pangan & Penduduk'!C3) -> Cilegon | G3: Konsumsi Protein Hewani (gr/kap/hr) | M3: Standar Kebutuhan Protein Hewani (gr/kap/hr) | O3: 3. Rasio Konsumsi Protein Hewani
G4: Tahun 2024 | M4: Tahun 2024 | O4: Tahun 2024
A5: No. | B5: Nama Kecamatan | C5: Kode Kecamatan | D5: Kode Desa/Kelurahan Kemendagri | E5: Kode Desa/Kelurahan BPS | F5: Nama Desa/Kelurahan | G5: Sumber: Badan Pangan Nasional (SAE) | H5: Sumber: BPS | I5: Sumber: Validasi Desa | J5: KESEPAKATAN: Data yang Dipakai di FSVA | K5: Keterangan | M5: Sumber: Kesepakatan Tim FSVA Nasional | O5: PERHITUNGAN: Data yang Dipakai di FSVA
A6: =IF('0.1 Produksi Pangan & Penduduk'!A6="","",'0.1 Produksi Pangan & Penduduk'!A6) -> 1 | B6: =IF('0.1 Produksi Pangan & Penduduk'!B6="","",'0.1 Produksi Pangan & Penduduk'!B6) -> CIWANDAN | C6: =IF('0.1 Produksi Pangan & Penduduk'!C6="","",'0.1 Produksi Pangan & Penduduk'!C6) -> 3672010 | D6: =IF('0.1 Produksi Pangan & Penduduk'!D6="","",'0.1 Produksi Pangan & Penduduk'!D6) -> 36.72.04.1004 | E6: =IF('0.1 Produksi Pangan & Penduduk'!E6="","",'0.1 Produksi Pangan & Penduduk'!E6) -> 3672010001 | F6: =IF('0.1 Produksi Pangan & Penduduk'!F6="","",'0.1 Produksi Pangan & Penduduk'!F6) -> Gunung Sugih | G6: 18.995375 | J6: 18.995375 | M6: 25 | O6: =IF(J6="","",IFERROR((J6/M6)*100,"")) -> 75.9815
A7: =IF('0.1 Produksi Pangan & Penduduk'!A7="","",'0.1 Produksi Pangan & Penduduk'!A7) -> 2 | B7: =IF('0.1 Produksi Pangan & Penduduk'!B7="","",'0.1 Produksi Pangan & Penduduk'!B7) -> CIWANDAN | C7: =IF('0.1 Produksi Pangan & Penduduk'!C7="","",'0.1 Produksi Pangan & Penduduk'!C7) -> 3672010 | D7: =IF('0.1 Produksi Pangan & Penduduk'!D7="","",'0.1 Produksi Pangan & Penduduk'!D7) -> 36.72.04.1005 | E7: =IF('0.1 Produksi Pangan & Penduduk'!E7="","",'0.1 Produksi Pangan & Penduduk'!E7) -> 3672010002 | F7: =IF('0.1 Produksi Pangan & Penduduk'!F7="","",'0.1 Produksi Pangan & Penduduk'!F7) -> Kepuh | G7: 18.4821 | J7: 18.4821 | M7: 25 | O7: =IF(J7="","",IFERROR((J7/M7)*100,"")) -> 73.9284
A8: =IF('0.1 Produksi Pangan & Penduduk'!A8="","",'0.1 Produksi Pangan & Penduduk'!A8) -> 3 | B8: =IF('0.1 Produksi Pangan & Penduduk'!B8="","",'0.1 Produksi Pangan & Penduduk'!B8) -> CIWANDAN | C8: =IF('0.1 Produksi Pangan & Penduduk'!C8="","",'0.1 Produksi Pangan & Penduduk'!C8) -> 3672010 | D8: =IF('0.1 Produksi Pangan & Penduduk'!D8="","",'0.1 Produksi Pangan & Penduduk'!D8) -> 36.72.04.1006 | E8: =IF('0.1 Produksi Pangan & Penduduk'!E8="","",'0.1 Produksi Pangan & Penduduk'!E8) -> 3672010003 | F8: =IF('0.1 Produksi Pangan & Penduduk'!F8="","",'0.1 Produksi Pangan & Penduduk'!F8) -> Randakari | G8: 18.620425 | J8: 18.620425 | M8: 25 | O8: =IF(J8="","",IFERROR((J8/M8)*100,"")) -> 74.4817
A9: =IF('0.1 Produksi Pangan & Penduduk'!A9="","",'0.1 Produksi Pangan & Penduduk'!A9) -> 4 | B9: =IF('0.1 Produksi Pangan & Penduduk'!B9="","",'0.1 Produksi Pangan & Penduduk'!B9) -> CIWANDAN | C9: =IF('0.1 Produksi Pangan & Penduduk'!C9="","",'0.1 Produksi Pangan & Penduduk'!C9) -> 3672010 | D9: =IF('0.1 Produksi Pangan & Penduduk'!D9="","",'0.1 Produksi Pangan & Penduduk'!D9) -> 36.72.04.1007 | E9: =IF('0.1 Produksi Pangan & Penduduk'!E9="","",'0.1 Produksi Pangan & Penduduk'!E9) -> 3672010004 | F9: =IF('0.1 Produksi Pangan & Penduduk'!F9="","",'0.1 Produksi Pangan & Penduduk'!F9) -> Tegal Ratu | G9: 19.6346 | J9: 19.6346 | M9: 25 | O9: =IF(J9="","",IFERROR((J9/M9)*100,"")) -> 78.5384
A10: =IF('0.1 Produksi Pangan & Penduduk'!A10="","",'0.1 Produksi Pangan & Penduduk'!A10) -> 5 | B10: =IF('0.1 Produksi Pangan & Penduduk'!B10="","",'0.1 Produksi Pangan & Penduduk'!B10) -> CIWANDAN | C10: =IF('0.1 Produksi Pangan & Penduduk'!C10="","",'0.1 Produksi Pangan & Penduduk'!C10) -> 3672010 | D10: =IF('0.1 Produksi Pangan & Penduduk'!D10="","",'0.1 Produksi Pangan & Penduduk'!D10) -> 36.72.04.1001 | E10: =IF('0.1 Produksi Pangan & Penduduk'!E10="","",'0.1 Produksi Pangan & Penduduk'!E10) -> 3672010005 | F10: =IF('0.1 Produksi Pangan & Penduduk'!F10="","",'0.1 Produksi Pangan & Penduduk'!F10) -> Banjar Negara | G10: 19.601325 | J10: 19.601325 | M10: 25 | O10: =IF(J10="","",IFERROR((J10/M10)*100,"")) -> 78.4053
A11: =IF('0.1 Produksi Pangan & Penduduk'!A11="","",'0.1 Produksi Pangan & Penduduk'!A11) -> 6 | B11: =IF('0.1 Produksi Pangan & Penduduk'!B11="","",'0.1 Produksi Pangan & Penduduk'!B11) -> CIWANDAN | C11: =IF('0.1 Produksi Pangan & Penduduk'!C11="","",'0.1 Produksi Pangan & Penduduk'!C11) -> 3672010 | D11: =IF('0.1 Produksi Pangan & Penduduk'!D11="","",'0.1 Produksi Pangan & Penduduk'!D11) -> 36.72.04.1002 | E11: =IF('0.1 Produksi Pangan & Penduduk'!E11="","",'0.1 Produksi Pangan & Penduduk'!E11) -> 3672010013 | F11: =IF('0.1 Produksi Pangan & Penduduk'!F11="","",'0.1 Produksi Pangan & Penduduk'!F11) -> Kubangsari | G11: 19.561775 | J11: 19.561775 | M11: 25 | O11: =IF(J11="","",IFERROR((J11/M11)*100,"")) -> 78.2471
A12: =IF('0.1 Produksi Pangan & Penduduk'!A12="","",'0.1 Produksi Pangan & Penduduk'!A12) -> 7 | B12: =IF('0.1 Produksi Pangan & Penduduk'!B12="","",'0.1 Produksi Pangan & Penduduk'!B12) -> CITANGKIL | C12: =IF('0.1 Produksi Pangan & Penduduk'!C12="","",'0.1 Produksi Pangan & Penduduk'!C12) -> 3672011 | D12: =IF('0.1 Produksi Pangan & Penduduk'!D12="","",'0.1 Produksi Pangan & Penduduk'!D12) -> 36.72.08.1002 | E12: =IF('0.1 Produksi Pangan & Penduduk'!E12="","",'0.1 Produksi Pangan & Penduduk'!E12) -> 3672011006 | F12: =IF('0.1 Produksi Pangan & Penduduk'!F12="","",'0.1 Produksi Pangan & Penduduk'!F12) -> Deringo | G12: 19.003975 | J12: 19.003975 | M12: 25 | O12: =IF(J12="","",IFERROR((J12/M12)*100,"")) -> 76.0159
A13: =IF('0.1 Produksi Pangan & Penduduk'!A13="","",'0.1 Produksi Pangan & Penduduk'!A13) -> 8 | B13: =IF('0.1 Produksi Pangan & Penduduk'!B13="","",'0.1 Produksi Pangan & Penduduk'!B13) -> CITANGKIL | C13: =IF('0.1 Produksi Pangan & Penduduk'!C13="","",'0.1 Produksi Pangan & Penduduk'!C13) -> 3672011 | D13: =IF('0.1 Produksi Pangan & Penduduk'!D13="","",'0.1 Produksi Pangan & Penduduk'!D13) -> 36.72.08.1004 | E13: =IF('0.1 Produksi Pangan & Penduduk'!E13="","",'0.1 Produksi Pangan & Penduduk'!E13) -> 3672011007 | F13: =IF('0.1 Produksi Pangan & Penduduk'!F13="","",'0.1 Produksi Pangan & Penduduk'!F13) -> Lebak Denok | G13: 19.277 | J13: 19.277 | M13: 25 | O13: =IF(J13="","",IFERROR((J13/M13)*100,"")) -> 77.108
A14: =IF('0.1 Produksi Pangan & Penduduk'!A14="","",'0.1 Produksi Pangan & Penduduk'!A14) -> 9 | B14: =IF('0.1 Produksi Pangan & Penduduk'!B14="","",'0.1 Produksi Pangan & Penduduk'!B14) -> CITANGKIL | C14: =IF('0.1 Produksi Pangan & Penduduk'!C14="","",'0.1 Produksi Pangan & Penduduk'!C14) -> 3672011 | D14: =IF('0.1 Produksi Pangan & Penduduk'!D14="","",'0.1 Produksi Pangan & Penduduk'!D14) -> 36.72.08.1003 | E14: =IF('0.1 Produksi Pangan & Penduduk'!E14="","",'0.1 Produksi Pangan & Penduduk'!E14) -> 3672011008 | F14: =IF('0.1 Produksi Pangan & Penduduk'!F14="","",'0.1 Produksi Pangan & Penduduk'!F14) -> Taman Baru | G14: 20.72925 | J14: 20.72925 | M14: 25 | O14: =IF(J14="","",IFERROR((J14/M14)*100,"")) -> 82.917
A15: =IF('0.1 Produksi Pangan & Penduduk'!A15="","",'0.1 Produksi Pangan & Penduduk'!A15) -> 10 | B15: =IF('0.1 Produksi Pangan & Penduduk'!B15="","",'0.1 Produksi Pangan & Penduduk'!B15) -> CITANGKIL | C15: =IF('0.1 Produksi Pangan & Penduduk'!C15="","",'0.1 Produksi Pangan & Penduduk'!C15) -> 3672011 | D15: =IF('0.1 Produksi Pangan & Penduduk'!D15="","",'0.1 Produksi Pangan & Penduduk'!D15) -> 36.72.08.1001 | E15: =IF('0.1 Produksi Pangan & Penduduk'!E15="","",'0.1 Produksi Pangan & Penduduk'!E15) -> 3672011009 | F15: =IF('0.1 Produksi Pangan & Penduduk'!F15="","",'0.1 Produksi Pangan & Penduduk'!F15) -> Citangkil | G15: 20.9528 | J15: 20.9528 | M15: 25 | O15: =IF(J15="","",IFERROR((J15/M15)*100,"")) -> 83.8112
A16: =IF('0.1 Produksi Pangan & Penduduk'!A16="","",'0.1 Produksi Pangan & Penduduk'!A16) -> 11 | B16: =IF('0.1 Produksi Pangan & Penduduk'!B16="","",'0.1 Produksi Pangan & Penduduk'!B16) -> CITANGKIL | C16: =IF('0.1 Produksi Pangan & Penduduk'!C16="","",'0.1 Produksi Pangan & Penduduk'!C16) -> 3672011 | D16: =IF('0.1 Produksi Pangan & Penduduk'!D16="","",'0.1 Produksi Pangan & Penduduk'!D16) -> 36.72.08.1005 | E16: =IF('0.1 Produksi Pangan & Penduduk'!E16="","",'0.1 Produksi Pangan & Penduduk'!E16) -> 3672011010 | F16: =IF('0.1 Produksi Pangan & Penduduk'!F16="","",'0.1 Produksi Pangan & Penduduk'!F16) -> Kebonsari | G16: 20.13145 | J16: 20.13145 | M16: 25 | O16: =IF(J16="","",IFERROR((J16/M16)*100,"")) -> 80.5258
A17: =IF('0.1 Produksi Pangan & Penduduk'!A17="","",'0.1 Produksi Pangan & Penduduk'!A17) -> 12 | B17: =IF('0.1 Produksi Pangan & Penduduk'!B17="","",'0.1 Produksi Pangan & Penduduk'!B17) -> CITANGKIL | C17: =IF('0.1 Produksi Pangan & Penduduk'!C17="","",'0.1 Produksi Pangan & Penduduk'!C17) -> 3672011 | D17: =IF('0.1 Produksi Pangan & Penduduk'!D17="","",'0.1 Produksi Pangan & Penduduk'!D17) -> 36.72.08.1007 | E17: =IF('0.1 Produksi Pangan & Penduduk'!E17="","",'0.1 Produksi Pangan & Penduduk'!E17) -> 3672011011 | F17: =IF('0.1 Produksi Pangan & Penduduk'!F17="","",'0.1 Produksi Pangan & Penduduk'!F17) -> Warnasari | G17: 19.723575 | J17: 19.723575 | M17: 25 | O17: =IF(J17="","",IFERROR((J17/M17)*100,"")) -> 78.8943
... A48: =IF('0.1 Produksi Pangan & Penduduk'!A48="","",'0.1 Produksi Pangan & Penduduk'!A48) -> 43 | B48: =IF('0.1 Produksi Pangan & Penduduk'!B48="","",'0.1 Produksi Pangan & Penduduk'!B48) -> CIBEBER | C48: =IF('0.1 Produksi Pangan & Penduduk'!C48="","",'0.1 Produksi Pangan & Penduduk'!C48) -> 3672040 | D48: =IF('0.1 Produksi Pangan & Penduduk'!D48="","",'0.1 Produksi Pangan & Penduduk'!D48) -> 36.72.01.1002 | E48: =IF('0.1 Produksi Pangan & Penduduk'!E48="","",'0.1 Produksi Pangan & Penduduk'!E48) -> 3672040006 | F48: =IF('0.1 Produksi Pangan & Penduduk'!F48="","",'0.1 Produksi Pangan & Penduduk'!F48) -> Kedaleman | G48: 19.987075 | J48: 19.987075 | M48: 25 | O48: =IF(J48="","",IFERROR((J48/M48)*100,"")) -> 79.9483
A49: =IF('0.1 Produksi Pangan & Penduduk'!A49="","",'0.1 Produksi Pangan & Penduduk'!A49) | B49: =IF('0.1 Produksi Pangan & Penduduk'!B49="","",'0.1 Produksi Pangan & Penduduk'!B49) | C49: =IF('0.1 Produksi Pangan & Penduduk'!C49="","",'0.1 Produksi Pangan & Penduduk'!C49) | D49: =IF('0.1 Produksi Pangan & Penduduk'!D49="","",'0.1 Produksi Pangan & Penduduk'!D49) | E49: =IF('0.1 Produksi Pangan & Penduduk'!E49="","",'0.1 Produksi Pangan & Penduduk'!E49) | F49: =IF('0.1 Produksi Pangan & Penduduk'!F49="","",'0.1 Produksi Pangan & Penduduk'!F49) | M49: 25 | O49: =IF(J49="","",IFERROR((J49/M49)*100,""))
A50: =IF('0.1 Produksi Pangan & Penduduk'!A50="","",'0.1 Produksi Pangan & Penduduk'!A50) | B50: =IF('0.1 Produksi Pangan & Penduduk'!B50="","",'0.1 Produksi Pangan & Penduduk'!B50) | C50: =IF('0.1 Produksi Pangan & Penduduk'!C50="","",'0.1 Produksi Pangan & Penduduk'!C50) | D50: =IF('0.1 Produksi Pangan & Penduduk'!D50="","",'0.1 Produksi Pangan & Penduduk'!D50) | E50: =IF('0.1 Produksi Pangan & Penduduk'!E50="","",'0.1 Produksi Pangan & Penduduk'!E50) | F50: =IF('0.1 Produksi Pangan & Penduduk'!F50="","",'0.1 Produksi Pangan & Penduduk'!F50) | M50: 25 | O50: =IF(J50="","",IFERROR((J50/M50)*100,""))
A51: =IF('0.1 Produksi Pangan & Penduduk'!A51="","",'0.1 Produksi Pangan & Penduduk'!A51) | B51: =IF('0.1 Produksi Pangan & Penduduk'!B51="","",'0.1 Produksi Pangan & Penduduk'!B51) | C51: =IF('0.1 Produksi Pangan & Penduduk'!C51="","",'0.1 Produksi Pangan & Penduduk'!C51) | D51: =IF('0.1 Produksi Pangan & Penduduk'!D51="","",'0.1 Produksi Pangan & Penduduk'!D51) | E51: =IF('0.1 Produksi Pangan & Penduduk'!E51="","",'0.1 Produksi Pangan & Penduduk'!E51) | F51: =IF('0.1 Produksi Pangan & Penduduk'!F51="","",'0.1 Produksi Pangan & Penduduk'!F51) | M51: 25 | O51: =IF(J51="","",IFERROR((J51/M51)*100,""))
A52: =IF('0.1 Produksi Pangan & Penduduk'!A52="","",'0.1 Produksi Pangan & Penduduk'!A52) | B52: =IF('0.1 Produksi Pangan & Penduduk'!B52="","",'0.1 Produksi Pangan & Penduduk'!B52) | C52: =IF('0.1 Produksi Pangan & Penduduk'!C52="","",'0.1 Produksi Pangan & Penduduk'!C52) | D52: =IF('0.1 Produksi Pangan & Penduduk'!D52="","",'0.1 Produksi Pangan & Penduduk'!D52) | E52: =IF('0.1 Produksi Pangan & Penduduk'!E52="","",'0.1 Produksi Pangan & Penduduk'!E52) | F52: =IF('0.1 Produksi Pangan & Penduduk'!F52="","",'0.1 Produksi Pangan & Penduduk'!F52) | M52: 25 | O52: =IF(J52="","",IFERROR((J52/M52)*100,""))
A53: =IF('0.1 Produksi Pangan & Penduduk'!A53="","",'0.1 Produksi Pangan & Penduduk'!A53) | B53: =IF('0.1 Produksi Pangan & Penduduk'!B53="","",'0.1 Produksi Pangan & Penduduk'!B53) | C53: =IF('0.1 Produksi Pangan & Penduduk'!C53="","",'0.1 Produksi Pangan & Penduduk'!C53) | D53: =IF('0.1 Produksi Pangan & Penduduk'!D53="","",'0.1 Produksi Pangan & Penduduk'!D53) | E53: =IF('0.1 Produksi Pangan & Penduduk'!E53="","",'0.1 Produksi Pangan & Penduduk'!E53) | F53: =IF('0.1 Produksi Pangan & Penduduk'!F53="","",'0.1 Produksi Pangan & Penduduk'!F53) | M53: 25 | O53: =IF(J53="","",IFERROR((J53/M53)*100,""))
A54: =IF('0.1 Produksi Pangan & Penduduk'!A54="","",'0.1 Produksi Pangan & Penduduk'!A54) | B54: =IF('0.1 Produksi Pangan & Penduduk'!B54="","",'0.1 Produksi Pangan & Penduduk'!B54) | C54: =IF('0.1 Produksi Pangan & Penduduk'!C54="","",'0.1 Produksi Pangan & Penduduk'!C54) | D54: =IF('0.1 Produksi Pangan & Penduduk'!D54="","",'0.1 Produksi Pangan & Penduduk'!D54) | E54: =IF('0.1 Produksi Pangan & Penduduk'!E54="","",'0.1 Produksi Pangan & Penduduk'!E54) | F54: =IF('0.1 Produksi Pangan & Penduduk'!F54="","",'0.1 Produksi Pangan & Penduduk'!F54) | M54: 25 | O54: =IF(J54="","",IFERROR((J54/M54)*100,""))
A55: =IF('0.1 Produksi Pangan & Penduduk'!A55="","",'0.1 Produksi Pangan & Penduduk'!A55) | B55: =IF('0.1 Produksi Pangan & Penduduk'!B55="","",'0.1 Produksi Pangan & Penduduk'!B55) | C55: =IF('0.1 Produksi Pangan & Penduduk'!C55="","",'0.1 Produksi Pangan & Penduduk'!C55) | D55: =IF('0.1 Produksi Pangan & Penduduk'!D55="","",'0.1 Produksi Pangan & Penduduk'!D55) | E55: =IF('0.1 Produksi Pangan & Penduduk'!E55="","",'0.1 Produksi Pangan & Penduduk'!E55) | F55: =IF('0.1 Produksi Pangan & Penduduk'!F55="","",'0.1 Produksi Pangan & Penduduk'!F55) | M55: 25 | O55: =IF(J55="","",IFERROR((J55/M55)*100,""))
A56: =IF('0.1 Produksi Pangan & Penduduk'!A56="","",'0.1 Produksi Pangan & Penduduk'!A56) | B56: =IF('0.1 Produksi Pangan & Penduduk'!B56="","",'0.1 Produksi Pangan & Penduduk'!B56) | C56: =IF('0.1 Produksi Pangan & Penduduk'!C56="","",'0.1 Produksi Pangan & Penduduk'!C56) | D56: =IF('0.1 Produksi Pangan & Penduduk'!D56="","",'0.1 Produksi Pangan & Penduduk'!D56) | E56: =IF('0.1 Produksi Pangan & Penduduk'!E56="","",'0.1 Produksi Pangan & Penduduk'!E56) | F56: =IF('0.1 Produksi Pangan & Penduduk'!F56="","",'0.1 Produksi Pangan & Penduduk'!F56) | M56: 25 | O56: =IF(J56="","",IFERROR((J56/M56)*100,""))
A57: =IF('0.1 Produksi Pangan & Penduduk'!A57="","",'0.1 Produksi Pangan & Penduduk'!A57) | B57: =IF('0.1 Produksi Pangan & Penduduk'!B57="","",'0.1 Produksi Pangan & Penduduk'!B57) | C57: =IF('0.1 Produksi Pangan & Penduduk'!C57="","",'0.1 Produksi Pangan & Penduduk'!C57) | D57: =IF('0.1 Produksi Pangan & Penduduk'!D57="","",'0.1 Produksi Pangan & Penduduk'!D57) | E57: =IF('0.1 Produksi Pangan & Penduduk'!E57="","",'0.1 Produksi Pangan & Penduduk'!E57) | F57: =IF('0.1 Produksi Pangan & Penduduk'!F57="","",'0.1 Produksi Pangan & Penduduk'!F57) | M57: 25 | O57: =IF(J57="","",IFERROR((J57/M57)*100,""))
A58: =IF('0.1 Produksi Pangan & Penduduk'!A58="","",'0.1 Produksi Pangan & Penduduk'!A58) | B58: =IF('0.1 Produksi Pangan & Penduduk'!B58="","",'0.1 Produksi Pangan & Penduduk'!B58) | C58: =IF('0.1 Produksi Pangan & Penduduk'!C58="","",'0.1 Produksi Pangan & Penduduk'!C58) | D58: =IF('0.1 Produksi Pangan & Penduduk'!D58="","",'0.1 Produksi Pangan & Penduduk'!D58) | E58: =IF('0.1 Produksi Pangan & Penduduk'!E58="","",'0.1 Produksi Pangan & Penduduk'!E58) | F58: =IF('0.1 Produksi Pangan & Penduduk'!F58="","",'0.1 Produksi Pangan & Penduduk'!F58) | M58: 25 | O58: =IF(J58="","",IFERROR((J58/M58)*100,""))
A59: =IF('0.1 Produksi Pangan & Penduduk'!A59="","",'0.1 Produksi Pangan & Penduduk'!A59) | B59: =IF('0.1 Produksi Pangan & Penduduk'!B59="","",'0.1 Produksi Pangan & Penduduk'!B59) | C59: =IF('0.1 Produksi Pangan & Penduduk'!C59="","",'0.1 Produksi Pangan & Penduduk'!C59) | D59: =IF('0.1 Produksi Pangan & Penduduk'!D59="","",'0.1 Produksi Pangan & Penduduk'!D59) | E59: =IF('0.1 Produksi Pangan & Penduduk'!E59="","",'0.1 Produksi Pangan & Penduduk'!E59) | F59: =IF('0.1 Produksi Pangan & Penduduk'!F59="","",'0.1 Produksi Pangan & Penduduk'!F59) | M59: 25 | O59: =IF(J59="","",IFERROR((J59/M59)*100,""))
A60: =IF('0.1 Produksi Pangan & Penduduk'!A60="","",'0.1 Produksi Pangan & Penduduk'!A60) | B60: =IF('0.1 Produksi Pangan & Penduduk'!B60="","",'0.1 Produksi Pangan & Penduduk'!B60) | C60: =IF('0.1 Produksi Pangan & Penduduk'!C60="","",'0.1 Produksi Pangan & Penduduk'!C60) | D60: =IF('0.1 Produksi Pangan & Penduduk'!D60="","",'0.1 Produksi Pangan & Penduduk'!D60) | E60: =IF('0.1 Produksi Pangan & Penduduk'!E60="","",'0.1 Produksi Pangan & Penduduk'!E60) | F60: =IF('0.1 Produksi Pangan & Penduduk'!F60="","",'0.1 Produksi Pangan & Penduduk'!F60) | M60: 25 | O60: =IF(J60="","",IFERROR((J60/M60)*100,""))
... A860: =IF('0.1 Produksi Pangan & Penduduk'!A860="","",'0.1 Produksi Pangan & Penduduk'!A860) | B860: =IF('0.1 Produksi Pangan & Penduduk'!B860="","",'0.1 Produksi Pangan & Penduduk'!B860) | C860: =IF('0.1 Produksi Pangan & Penduduk'!C860="","",'0.1 Produksi Pangan & Penduduk'!C860) | D860: =IF('0.1 Produksi Pangan & Penduduk'!D860="","",'0.1 Produksi Pangan & Penduduk'!D860) | E860: =IF('0.1 Produksi Pangan & Penduduk'!E860="","",'0.1 Produksi Pangan & Penduduk'!E860) | F860: =IF('0.1 Produksi Pangan & Penduduk'!F860="","",'0.1 Produksi Pangan & Penduduk'!F860) | M860: 25 | O860: =IF(J860="","",IFERROR((J860/M860)*100,""))

Sheet 0.4 Stok_Cadangan
A1: VALIDASI DATA CADANGAN PANGAN
A2: ='0.1 Produksi Pangan & Penduduk'!A2 -> Food Security and Vulnerability Atlas Tahun 2025
A3: ='0.1 Produksi Pangan & Penduduk'!A3 -> Kabupaten/Kota: | C3: =IF('0.1 Produksi Pangan & Penduduk'!C3="","",'0.1 Produksi Pangan & Penduduk'!C3) -> Cilegon | G3: 4.a. Cadangan Beras Pemerintah Daerah/CBPD (ton) | K3: 4.b. Lumbung Pangan Masyarakat (ton) | O3: Cadangan Pangan (ton) | R3: Jumlah Penduduk (Jiwa) | T3: 4. Rasio Cadangan Pangan per Kapita
G4: Tahun 2024 | K4: Tahun 2024 | O4: Tahun 2024 | R4: Tahun 2024 | T4: Tahun 2024
A5: No. | B5: Nama Kecamatan | C5: Kode Kecamatan | D5: Kode Desa/Kelurahan Kemendagri | E5: Kode Desa/Kelurahan BPS | F5: Nama Desa/Kelurahan | G5: Sumber: Dinas Pangan | H5: Sumber: Kementan | I5: Sumber: Validasi Desa | J5: KESEPAKATAN: Data yang Dipakai di FSVA | K5: Sumber: Dinas Pangan | L5: Sumber: BPS | M5: Sumber: Validasi Desa | N5: KESEPAKATAN: Data yang Dipakai di FSVA | O5: Total Cadangan Pangan | P5: Keterangan | R5: Sumber: Dinas Dukcapil | T5: PERHITUNGAN: Data yang Dipakai di FSVA
A6: =IF('0.1 Produksi Pangan & Penduduk'!A6="","",'0.1 Produksi Pangan & Penduduk'!A6) -> 1 | B6: =IF('0.1 Produksi Pangan & Penduduk'!B6="","",'0.1 Produksi Pangan & Penduduk'!B6) -> CIWANDAN | C6: =IF('0.1 Produksi Pangan & Penduduk'!C6="","",'0.1 Produksi Pangan & Penduduk'!C6) -> 3672010 | D6: =IF('0.1 Produksi Pangan & Penduduk'!D6="","",'0.1 Produksi Pangan & Penduduk'!D6) -> 36.72.04.1004 | E6: =IF('0.1 Produksi Pangan & Penduduk'!E6="","",'0.1 Produksi Pangan & Penduduk'!E6) -> 3672010001 | F6: =IF('0.1 Produksi Pangan & Penduduk'!F6="","",'0.1 Produksi Pangan & Penduduk'!F6) -> Gunung Sugih | G6: 1.8618629 | J6: 1.8618629 | O6: =IF(J6="","",IFERROR((J6+N6),0)) -> 1.8618629 | R6: =IF('0.1 Produksi Pangan & Penduduk'!AQ6="","",'0.1 Produksi Pangan & Penduduk'!AQ6) -> 6740 | T6: =IF(J6="","",IFERROR((O6*1000/R6),0)) -> 0.27624079
A7: =IF('0.1 Produksi Pangan & Penduduk'!A7="","",'0.1 Produksi Pangan & Penduduk'!A7) -> 2 | B7: =IF('0.1 Produksi Pangan & Penduduk'!B7="","",'0.1 Produksi Pangan & Penduduk'!B7) -> CIWANDAN | C7: =IF('0.1 Produksi Pangan & Penduduk'!C7="","",'0.1 Produksi Pangan & Penduduk'!C7) -> 3672010 | D7: =IF('0.1 Produksi Pangan & Penduduk'!D7="","",'0.1 Produksi Pangan & Penduduk'!D7) -> 36.72.04.1005 | E7: =IF('0.1 Produksi Pangan & Penduduk'!E7="","",'0.1 Produksi Pangan & Penduduk'!E7) -> 3672010002 | F7: =IF('0.1 Produksi Pangan & Penduduk'!F7="","",'0.1 Produksi Pangan & Penduduk'!F7) -> Kepuh | G7: 2.5762216 | J7: 2.5762216 | O7: =IF(J7="","",IFERROR((J7+N7),0)) -> 2.5762216 | R7: =IF('0.1 Produksi Pangan & Penduduk'!AQ7="","",'0.1 Produksi Pangan & Penduduk'!AQ7) -> 9326 | T7: =IF(J7="","",IFERROR((O7*1000/R7),0)) -> 0.27624079
A8: =IF('0.1 Produksi Pangan & Penduduk'!A8="","",'0.1 Produksi Pangan & Penduduk'!A8) -> 3 | B8: =IF('0.1 Produksi Pangan & Penduduk'!B8="","",'0.1 Produksi Pangan & Penduduk'!B8) -> CIWANDAN | C8: =IF('0.1 Produksi Pangan & Penduduk'!C8="","",'0.1 Produksi Pangan & Penduduk'!C8) -> 3672010 | D8: =IF('0.1 Produksi Pangan & Penduduk'!D8="","",'0.1 Produksi Pangan & Penduduk'!D8) -> 36.72.04.1006 | E8: =IF('0.1 Produksi Pangan & Penduduk'!E8="","",'0.1 Produksi Pangan & Penduduk'!E8) -> 3672010003 | F8: =IF('0.1 Produksi Pangan & Penduduk'!F8="","",'0.1 Produksi Pangan & Penduduk'!F8) -> Randakari | G8: 2.7195906 | J8: 2.7195906 | O8: =IF(J8="","",IFERROR((J8+N8),0)) -> 2.7195906 | R8: =IF('0.1 Produksi Pangan & Penduduk'!AQ8="","",'0.1 Produksi Pangan & Penduduk'!AQ8) -> 9845 | T8: =IF(J8="","",IFERROR((O8*1000/R8),0)) -> 0.27624079
A9: =IF('0.1 Produksi Pangan & Penduduk'!A9="","",'0.1 Produksi Pangan & Penduduk'!A9) -> 4 | B9: =IF('0.1 Produksi Pangan & Penduduk'!B9="","",'0.1 Produksi Pangan & Penduduk'!B9) -> CIWANDAN | C9: =IF('0.1 Produksi Pangan & Penduduk'!C9="","",'0.1 Produksi Pangan & Penduduk'!C9) -> 3672010 | D9: =IF('0.1 Produksi Pangan & Penduduk'!D9="","",'0.1 Produksi Pangan & Penduduk'!D9) -> 36.72.04.1007 | E9: =IF('0.1 Produksi Pangan & Penduduk'!E9="","",'0.1 Produksi Pangan & Penduduk'!E9) -> 3672010004 | F9: =IF('0.1 Produksi Pangan & Penduduk'!F9="","",'0.1 Produksi Pangan & Penduduk'!F9) -> Tegal Ratu | G9: 3.3112984 | J9: 3.3112984 | O9: =IF(J9="","",IFERROR((J9+N9),0)) -> 3.3112984 | R9: =IF('0.1 Produksi Pangan & Penduduk'!AQ9="","",'0.1 Produksi Pangan & Penduduk'!AQ9) -> 11987 | T9: =IF(J9="","",IFERROR((O9*1000/R9),0)) -> 0.27624079
A10: =IF('0.1 Produksi Pangan & Penduduk'!A10="","",'0.1 Produksi Pangan & Penduduk'!A10) -> 5 | B10: =IF('0.1 Produksi Pangan & Penduduk'!B10="","",'0.1 Produksi Pangan & Penduduk'!B10) -> CIWANDAN | C10: =IF('0.1 Produksi Pangan & Penduduk'!C10="","",'0.1 Produksi Pangan & Penduduk'!C10) -> 3672010 | D10: =IF('0.1 Produksi Pangan & Penduduk'!D10="","",'0.1 Produksi Pangan & Penduduk'!D10) -> 36.72.04.1001 | E10: =IF('0.1 Produksi Pangan & Penduduk'!E10="","",'0.1 Produksi Pangan & Penduduk'!E10) -> 3672010005 | F10: =IF('0.1 Produksi Pangan & Penduduk'!F10="","",'0.1 Produksi Pangan & Penduduk'!F10) -> Banjar Negara | G10: 2.3411407 | J10: 2.3411407 | O10: =IF(J10="","",IFERROR((J10+N10),0)) -> 2.3411407 | R10: =IF('0.1 Produksi Pangan & Penduduk'!AQ10="","",'0.1 Produksi Pangan & Penduduk'!AQ10) -> 8475 | T10: =IF(J10="","",IFERROR((O10*1000/R10),0)) -> 0.27624079
A11: =IF('0.1 Produksi Pangan & Penduduk'!A11="","",'0.1 Produksi Pangan & Penduduk'!A11) -> 6 | B11: =IF('0.1 Produksi Pangan & Penduduk'!B11="","",'0.1 Produksi Pangan & Penduduk'!B11) -> CIWANDAN | C11: =IF('0.1 Produksi Pangan & Penduduk'!C11="","",'0.1 Produksi Pangan & Penduduk'!C11) -> 3672010 | D11: =IF('0.1 Produksi Pangan & Penduduk'!D11="","",'0.1 Produksi Pangan & Penduduk'!D11) -> 36.72.04.1002 | E11: =IF('0.1 Produksi Pangan & Penduduk'!E11="","",'0.1 Produksi Pangan & Penduduk'!E11) -> 3672010013 | F11: =IF('0.1 Produksi Pangan & Penduduk'!F11="","",'0.1 Produksi Pangan & Penduduk'!F11) -> Kubangsari | G11: 2.2742905 | J11: 2.2742905 | O11: =IF(J11="","",IFERROR((J11+N11),0)) -> 2.2742905 | R11: =IF('0.1 Produksi Pangan & Penduduk'!AQ11="","",'0.1 Produksi Pangan & Penduduk'!AQ11) -> 8233 | T11: =IF(J11="","",IFERROR((O11*1000/R11),0)) -> 0.27624079
A12: =IF('0.1 Produksi Pangan & Penduduk'!A12="","",'0.1 Produksi Pangan & Penduduk'!A12) -> 7 | B12: =IF('0.1 Produksi Pangan & Penduduk'!B12="","",'0.1 Produksi Pangan & Penduduk'!B12) -> CITANGKIL | C12: =IF('0.1 Produksi Pangan & Penduduk'!C12="","",'0.1 Produksi Pangan & Penduduk'!C12) -> 3672011 | D12: =IF('0.1 Produksi Pangan & Penduduk'!D12="","",'0.1 Produksi Pangan & Penduduk'!D12) -> 36.72.08.1002 | E12: =IF('0.1 Produksi Pangan & Penduduk'!E12="","",'0.1 Produksi Pangan & Penduduk'!E12) -> 3672011006 | F12: =IF('0.1 Produksi Pangan & Penduduk'!F12="","",'0.1 Produksi Pangan & Penduduk'!F12) -> Deringo | G12: 2.8908599 | J12: 2.8908599 | O12: =IF(J12="","",IFERROR((J12+N12),0)) -> 2.8908599 | R12: =IF('0.1 Produksi Pangan & Penduduk'!AQ12="","",'0.1 Produksi Pangan & Penduduk'!AQ12) -> 10465 | T12: =IF(J12="","",IFERROR((O12*1000/R12),0)) -> 0.27624079
A13: =IF('0.1 Produksi Pangan & Penduduk'!A13="","",'0.1 Produksi Pangan & Penduduk'!A13) -> 8 | B13: =IF('0.1 Produksi Pangan & Penduduk'!B13="","",'0.1 Produksi Pangan & Penduduk'!B13) -> CITANGKIL | C13: =IF('0.1 Produksi Pangan & Penduduk'!C13="","",'0.1 Produksi Pangan & Penduduk'!C13) -> 3672011 | D13: =IF('0.1 Produksi Pangan & Penduduk'!D13="","",'0.1 Produksi Pangan & Penduduk'!D13) -> 36.72.08.1004 | E13: =IF('0.1 Produksi Pangan & Penduduk'!E13="","",'0.1 Produksi Pangan & Penduduk'!E13) -> 3672011007 | F13: =IF('0.1 Produksi Pangan & Penduduk'!F13="","",'0.1 Produksi Pangan & Penduduk'!F13) -> Lebak Denok | G13: 3.6800799 | J13: 3.6800799 | O13: =IF(J13="","",IFERROR((J13+N13),0)) -> 3.6800799 | R13: =IF('0.1 Produksi Pangan & Penduduk'!AQ13="","",'0.1 Produksi Pangan & Penduduk'!AQ13) -> 13322 | T13: =IF(J13="","",IFERROR((O13*1000/R13),0)) -> 0.27624079
A14: =IF('0.1 Produksi Pangan & Penduduk'!A14="","",'0.1 Produksi Pangan & Penduduk'!A14) -> 9 | B14: =IF('0.1 Produksi Pangan & Penduduk'!B14="","",'0.1 Produksi Pangan & Penduduk'!B14) -> CITANGKIL | C14: =IF('0.1 Produksi Pangan & Penduduk'!C14="","",'0.1 Produksi Pangan & Penduduk'!C14) -> 3672011 | D14: =IF('0.1 Produksi Pangan & Penduduk'!D14="","",'0.1 Produksi Pangan & Penduduk'!D14) -> 36.72.08.1003 | E14: =IF('0.1 Produksi Pangan & Penduduk'!E14="","",'0.1 Produksi Pangan & Penduduk'!E14) -> 3672011008 | F14: =IF('0.1 Produksi Pangan & Penduduk'!F14="","",'0.1 Produksi Pangan & Penduduk'!F14) -> Taman Baru | G14: 2.7430711 | J14: 2.7430711 | O14: =IF(J14="","",IFERROR((J14+N14),0)) -> 2.7430711 | R14: =IF('0.1 Produksi Pangan & Penduduk'!AQ14="","",'0.1 Produksi Pangan & Penduduk'!AQ14) -> 9930 | T14: =IF(J14="","",IFERROR((O14*1000/R14),0)) -> 0.27624079
A15: =IF('0.1 Produksi Pangan & Penduduk'!A15="","",'0.1 Produksi Pangan & Penduduk'!A15) -> 10 | B15: =IF('0.1 Produksi Pangan & Penduduk'!B15="","",'0.1 Produksi Pangan & Penduduk'!B15) -> CITANGKIL | C15: =IF('0.1 Produksi Pangan & Penduduk'!C15="","",'0.1 Produksi Pangan & Penduduk'!C15) -> 3672011 | D15: =IF('0.1 Produksi Pangan & Penduduk'!D15="","",'0.1 Produksi Pangan & Penduduk'!D15) -> 36.72.08.1001 | E15: =IF('0.1 Produksi Pangan & Penduduk'!E15="","",'0.1 Produksi Pangan & Penduduk'!E15) -> 3672011009 | F15: =IF('0.1 Produksi Pangan & Penduduk'!F15="","",'0.1 Produksi Pangan & Penduduk'!F15) -> Citangkil | G15: 4.6273095 | J15: 4.6273095 | O15: =IF(J15="","",IFERROR((J15+N15),0)) -> 4.6273095 | R15: =IF('0.1 Produksi Pangan & Penduduk'!AQ15="","",'0.1 Produksi Pangan & Penduduk'!AQ15) -> 16751 | T15: =IF(J15="","",IFERROR((O15*1000/R15),0)) -> 0.27624079
A16: =IF('0.1 Produksi Pangan & Penduduk'!A16="","",'0.1 Produksi Pangan & Penduduk'!A16) -> 11 | B16: =IF('0.1 Produksi Pangan & Penduduk'!B16="","",'0.1 Produksi Pangan & Penduduk'!B16) -> CITANGKIL | C16: =IF('0.1 Produksi Pangan & Penduduk'!C16="","",'0.1 Produksi Pangan & Penduduk'!C16) -> 3672011 | D16: =IF('0.1 Produksi Pangan & Penduduk'!D16="","",'0.1 Produksi Pangan & Penduduk'!D16) -> 36.72.08.1005 | E16: =IF('0.1 Produksi Pangan & Penduduk'!E16="","",'0.1 Produksi Pangan & Penduduk'!E16) -> 3672011010 | F16: =IF('0.1 Produksi Pangan & Penduduk'!F16="","",'0.1 Produksi Pangan & Penduduk'!F16) -> Kebonsari | G16: 3.37511 | J16: 3.37511 | O16: =IF(J16="","",IFERROR((J16+N16),0)) -> 3.37511 | R16: =IF('0.1 Produksi Pangan & Penduduk'!AQ16="","",'0.1 Produksi Pangan & Penduduk'!AQ16) -> 12218 | T16: =IF(J16="","",IFERROR((O16*1000/R16),0)) -> 0.27624079
A17: =IF('0.1 Produksi Pangan & Penduduk'!A17="","",'0.1 Produksi Pangan & Penduduk'!A17) -> 12 | B17: =IF('0.1 Produksi Pangan & Penduduk'!B17="","",'0.1 Produksi Pangan & Penduduk'!B17) -> CITANGKIL | C17: =IF('0.1 Produksi Pangan & Penduduk'!C17="","",'0.1 Produksi Pangan & Penduduk'!C17) -> 3672011 | D17: =IF('0.1 Produksi Pangan & Penduduk'!D17="","",'0.1 Produksi Pangan & Penduduk'!D17) -> 36.72.08.1007 | E17: =IF('0.1 Produksi Pangan & Penduduk'!E17="","",'0.1 Produksi Pangan & Penduduk'!E17) -> 3672011011 | F17: =IF('0.1 Produksi Pangan & Penduduk'!F17="","",'0.1 Produksi Pangan & Penduduk'!F17) -> Warnasari | G17: 4.006044 | J17: 4.006044 | O17: =IF(J17="","",IFERROR((J17+N17),0)) -> 4.006044 | R17: =IF('0.1 Produksi Pangan & Penduduk'!AQ17="","",'0.1 Produksi Pangan & Penduduk'!AQ17) -> 14502 | T17: =IF(J17="","",IFERROR((O17*1000/R17),0)) -> 0.27624079
... A48: =IF('0.1 Produksi Pangan & Penduduk'!A48="","",'0.1 Produksi Pangan & Penduduk'!A48) -> 43 | B48: =IF('0.1 Produksi Pangan & Penduduk'!B48="","",'0.1 Produksi Pangan & Penduduk'!B48) -> CIBEBER | C48: =IF('0.1 Produksi Pangan & Penduduk'!C48="","",'0.1 Produksi Pangan & Penduduk'!C48) -> 3672040 | D48: =IF('0.1 Produksi Pangan & Penduduk'!D48="","",'0.1 Produksi Pangan & Penduduk'!D48) -> 36.72.01.1002 | E48: =IF('0.1 Produksi Pangan & Penduduk'!E48="","",'0.1 Produksi Pangan & Penduduk'!E48) -> 3672040006 | F48: =IF('0.1 Produksi Pangan & Penduduk'!F48="","",'0.1 Produksi Pangan & Penduduk'!F48) -> Kedaleman | G48: 2.9546715 | J48: 2.9546715 | O48: =IF(J48="","",IFERROR((J48+N48),0)) -> 2.9546715 | R48: =IF('0.1 Produksi Pangan & Penduduk'!AQ48="","",'0.1 Produksi Pangan & Penduduk'!AQ48) -> 10696 | T48: =IF(J48="","",IFERROR((O48*1000/R48),0)) -> 0.27624079
A49: =IF('0.1 Produksi Pangan & Penduduk'!A49="","",'0.1 Produksi Pangan & Penduduk'!A49) | B49: =IF('0.1 Produksi Pangan & Penduduk'!B49="","",'0.1 Produksi Pangan & Penduduk'!B49) | C49: =IF('0.1 Produksi Pangan & Penduduk'!C49="","",'0.1 Produksi Pangan & Penduduk'!C49) | D49: =IF('0.1 Produksi Pangan & Penduduk'!D49="","",'0.1 Produksi Pangan & Penduduk'!D49) | E49: =IF('0.1 Produksi Pangan & Penduduk'!E49="","",'0.1 Produksi Pangan & Penduduk'!E49) | F49: =IF('0.1 Produksi Pangan & Penduduk'!F49="","",'0.1 Produksi Pangan & Penduduk'!F49) | O49: =IF(J49="","",IFERROR((J49+N49),0)) | R49: =IF('0.1 Produksi Pangan & Penduduk'!AQ49="","",'0.1 Produksi Pangan & Penduduk'!AQ49) | T49: =IF(J49="","",IFERROR((O49*1000/R49),0))
A50: =IF('0.1 Produksi Pangan & Penduduk'!A50="","",'0.1 Produksi Pangan & Penduduk'!A50) | B50: =IF('0.1 Produksi Pangan & Penduduk'!B50="","",'0.1 Produksi Pangan & Penduduk'!B50) | C50: =IF('0.1 Produksi Pangan & Penduduk'!C50="","",'0.1 Produksi Pangan & Penduduk'!C50) | D50: =IF('0.1 Produksi Pangan & Penduduk'!D50="","",'0.1 Produksi Pangan & Penduduk'!D50) | E50: =IF('0.1 Produksi Pangan & Penduduk'!E50="","",'0.1 Produksi Pangan & Penduduk'!E50) | F50: =IF('0.1 Produksi Pangan & Penduduk'!F50="","",'0.1 Produksi Pangan & Penduduk'!F50) | O50: =IF(J50="","",IFERROR((J50+N50),0)) | R50: =IF('0.1 Produksi Pangan & Penduduk'!AQ50="","",'0.1 Produksi Pangan & Penduduk'!AQ50) | T50: =IF(J50="","",IFERROR((O50*1000/R50),0))
A51: =IF('0.1 Produksi Pangan & Penduduk'!A51="","",'0.1 Produksi Pangan & Penduduk'!A51) | B51: =IF('0.1 Produksi Pangan & Penduduk'!B51="","",'0.1 Produksi Pangan & Penduduk'!B51) | C51: =IF('0.1 Produksi Pangan & Penduduk'!C51="","",'0.1 Produksi Pangan & Penduduk'!C51) | D51: =IF('0.1 Produksi Pangan & Penduduk'!D51="","",'0.1 Produksi Pangan & Penduduk'!D51) | E51: =IF('0.1 Produksi Pangan & Penduduk'!E51="","",'0.1 Produksi Pangan & Penduduk'!E51) | F51: =IF('0.1 Produksi Pangan & Penduduk'!F51="","",'0.1 Produksi Pangan & Penduduk'!F51) | O51: =IF(J51="","",IFERROR((J51+N51),0)) | R51: =IF('0.1 Produksi Pangan & Penduduk'!AQ51="","",'0.1 Produksi Pangan & Penduduk'!AQ51) | T51: =IF(J51="","",IFERROR((O51*1000/R51),0))
A52: =IF('0.1 Produksi Pangan & Penduduk'!A52="","",'0.1 Produksi Pangan & Penduduk'!A52) | B52: =IF('0.1 Produksi Pangan & Penduduk'!B52="","",'0.1 Produksi Pangan & Penduduk'!B52) | C52: =IF('0.1 Produksi Pangan & Penduduk'!C52="","",'0.1 Produksi Pangan & Penduduk'!C52) | D52: =IF('0.1 Produksi Pangan & Penduduk'!D52="","",'0.1 Produksi Pangan & Penduduk'!D52) | E52: =IF('0.1 Produksi Pangan & Penduduk'!E52="","",'0.1 Produksi Pangan & Penduduk'!E52) | F52: =IF('0.1 Produksi Pangan & Penduduk'!F52="","",'0.1 Produksi Pangan & Penduduk'!F52) | O52: =IF(J52="","",IFERROR((J52+N52),0)) | R52: =IF('0.1 Produksi Pangan & Penduduk'!AQ52="","",'0.1 Produksi Pangan & Penduduk'!AQ52) | T52: =IF(J52="","",IFERROR((O52*1000/R52),0))
A53: =IF('0.1 Produksi Pangan & Penduduk'!A53="","",'0.1 Produksi Pangan & Penduduk'!A53) | B53: =IF('0.1 Produksi Pangan & Penduduk'!B53="","",'0.1 Produksi Pangan & Penduduk'!B53) | C53: =IF('0.1 Produksi Pangan & Penduduk'!C53="","",'0.1 Produksi Pangan & Penduduk'!C53) | D53: =IF('0.1 Produksi Pangan & Penduduk'!D53="","",'0.1 Produksi Pangan & Penduduk'!D53) | E53: =IF('0.1 Produksi Pangan & Penduduk'!E53="","",'0.1 Produksi Pangan & Penduduk'!E53) | F53: =IF('0.1 Produksi Pangan & Penduduk'!F53="","",'0.1 Produksi Pangan & Penduduk'!F53) | O53: =IF(J53="","",IFERROR((J53+N53),0)) | R53: =IF('0.1 Produksi Pangan & Penduduk'!AQ53="","",'0.1 Produksi Pangan & Penduduk'!AQ53) | T53: =IF(J53="","",IFERROR((O53*1000/R53),0))
